Workbook
Name BOL: OFFSET('[1]DaysInWIP control'!$AA$2,1,0,COUNTA('[1]DaysInWIP control'!#REF!),1)
Name BOL: OFFSET(#REF!,1,0,COUNTA(#REF!),1)
Name date1: OFFSET('[1]DaysInWIP control'!$V$2,1,0,COUNTA('[1]DaysInWIP control'!#REF!),1)
Name date1: OFFSET(#REF!,1,0,COUNTA(#REF!),1)
Name EOL: OFFSET('[1]DaysInWIP control'!$AK$2,1,0,COUNTA('[1]DaysInWIP control'!$AL$11:$AL$25),1)
Name EOL: OFFSET(#REF!,1,0,COUNTA(#REF!),1)
Name FCT: '[2]Formation time data'!$A$1:$B$3173
Name MATA_WIP: [3]!Table_ExternalData_1[#All]
Name MOL: OFFSET('[1]DaysInWIP control'!$AD$2,1,0,COUNTA('[1]DaysInWIP control'!#REF!),1)
Name MOL: OFFSET(#REF!,1,0,COUNTA(#REF!),1)
Name SMT: OFFSET('[1]DaysInWIP control'!$AM$2,1,0,COUNTA('[1]DaysInWIP control'!$AN$4:$AN$28),1)
Name SMT: OFFSET(#REF!,1,0,COUNTA(#REF!),1)

Sheet Carouselwash
A1: PartType | B1: PowderType | C1: Cspec | D1: Cspec2 | E1: ParameterName | F1: Parttype combine | G1: PartType+PowderType | H1: ParameterValue | I1: CarouselwashTime
A2: 598B107/006 | B2: STA156KA | C2: E070 | D2: 0000 | E2: KMS_RouteECP | F2: 598B107/006STA156KAE070 | G2: =k[[#This Row],[PartType]]&k[[#This Row],[PowderType]] -> 598B107/006STA156KA | H2: S45103SXMU2P | I2: {=_xlfn.IFS(LEFT(k[[#This Row],[ParameterValue]],1)="S",3,LEFT(k[[#This Row],[ParameterValue]],1)="X",2, LEFT(k[[#This Row],[ParameterValue]],1)="D",4)} -> 3
A3: 521B106/016 | B3: FTW400 | C3: E090 | D3: 0000 | E3: KMS_RouteECP | F3: 521B106/016FTW400E090 | G3: =k[[#This Row],[PartType]]&k[[#This Row],[PowderType]] -> 521B106/016FTW400 | H3: S40102BP5 | I3: {=_xlfn.IFS(LEFT(k[[#This Row],[ParameterValue]],1)="S",3,LEFT(k[[#This Row],[ParameterValue]],1)="X",2, LEFT(k[[#This Row],[ParameterValue]],1)="D",4)} -> 3
A4: 521B106/016 | B4: FTW400 | C4: E100 | D4: 0000 | E4: KMS_RouteECP | F4: 521B106/016FTW400E100 | G4: =k[[#This Row],[PartType]]&k[[#This Row],[PowderType]] -> 521B106/016FTW400 | H4: S40102BP5 | I4: {=_xlfn.IFS(LEFT(k[[#This Row],[ParameterValue]],1)="S",3,LEFT(k[[#This Row],[ParameterValue]],1)="X",2, LEFT(k[[#This Row],[ParameterValue]],1)="D",4)} -> 3
A5: 521V156/050 | B5: C275 | C5: E070 | D5: 0000 | E5: KMS_RouteECP | F5: 521V156/050C275E070 | G5: =k[[#This Row],[PartType]]&k[[#This Row],[PowderType]] -> 521V156/050C275 | H5: X20103BP5 | I5: {=_xlfn.IFS(LEFT(k[[#This Row],[ParameterValue]],1)="S",3,LEFT(k[[#This Row],[ParameterValue]],1)="X",2, LEFT(k[[#This Row],[ParameterValue]],1)="D",4)} -> 2
A6: 521V116/050 | B6: C275 | C6: E070 | D6: 0000 | E6: KMS_RouteECP | F6: 521V116/050C275E070 | G6: =k[[#This Row],[PartType]]&k[[#This Row],[PowderType]] -> 521V116/050C275 | H6: X30103BP5 | I6: {=_xlfn.IFS(LEFT(k[[#This Row],[ParameterValue]],1)="S",3,LEFT(k[[#This Row],[ParameterValue]],1)="X",2, LEFT(k[[#This Row],[ParameterValue]],1)="D",4)} -> 2
A7: 521X226/050 | B7: C275 | C7: E080 | D7: 0000 | E7: KMS_RouteECP | F7: 521X226/050C275E080 | G7: =k[[#This Row],[PartType]]&k[[#This Row],[PowderType]] -> 521X226/050C275 | H7: X20103BEP5 | I7: {=_xlfn.IFS(LEFT(k[[#This Row],[ParameterValue]],1)="S",3,LEFT(k[[#This Row],[ParameterValue]],1)="X",2, LEFT(k[[#This Row],[ParameterValue]],1)="D",4)} -> 2
A8: 522V227/006 | B8: NT50 | C8: 4109 | D8: 0000 | E8: KMS_RouteECP | F8: 522V227/006NT504109 | G8: =k[[#This Row],[PartType]]&k[[#This Row],[PowderType]] -> 522V227/006NT50 | H8: S38103HKP | I8: {=_xlfn.IFS(LEFT(k[[#This Row],[ParameterValue]],1)="S",3,LEFT(k[[#This Row],[ParameterValue]],1)="X",2, LEFT(k[[#This Row],[ParameterValue]],1)="D",4)} -> 3
A9: 591V227/2R5 | B9: NT50 | C9: E009 | D9: 0000 | E9: KMS_RouteECP | F9: 591V227/2R5NT50E009 | G9: =k[[#This Row],[PartType]]&k[[#This Row],[PowderType]] -> 591V227/2R5NT50 | H9: S38102S | I9: {=_xlfn.IFS(LEFT(k[[#This Row],[ParameterValue]],1)="S",3,LEFT(k[[#This Row],[ParameterValue]],1)="X",2, LEFT(k[[#This Row],[ParameterValue]],1)="D",4)} -> 3
A10: 598D476/025 | B10: FTP200 | C10: E060 | D10: SUZH | E10: KMS_RouteECP | F10: 598D476/025FTP200E060 | G10: =k[[#This Row],[PartType]]&k[[#This Row],[PowderType]] -> 598D476/025FTP200 | H10: S20113V6BP7 | I10: {=_xlfn.IFS(LEFT(k[[#This Row],[ParameterValue]],1)="S",3,LEFT(k[[#This Row],[ParameterValue]],1)="X",2, LEFT(k[[#This Row],[ParameterValue]],1)="D",4)} -> 3
A11: 598D337/006 | B11: NT50 | C11: E025 | D11: SUZH | E11: KMS_RouteECP | F11: 598D337/006NT50E025 | G11: =k[[#This Row],[PartType]]&k[[#This Row],[PowderType]] -> 598D337/006NT50 | H11: S35113SP | I11: {=_xlfn.IFS(LEFT(k[[#This Row],[ParameterValue]],1)="S",3,LEFT(k[[#This Row],[ParameterValue]],1)="X",2, LEFT(k[[#This Row],[ParameterValue]],1)="D",4)} -> 3
A12: 598D227/010 | B12: NT50 | C12: E040 | D12: SUZH | E12: KMS_RouteECP | F12: 598D227/010NT50E040 | G12: =k[[#This Row],[PartType]]&k[[#This Row],[PowderType]] -> 598D227/010NT50 | H12: S35113SP | I12: {=_xlfn.IFS(LEFT(k[[#This Row],[ParameterValue]],1)="S",3,LEFT(k[[#This Row],[ParameterValue]],1)="X",2, LEFT(k[[#This Row],[ParameterValue]],1)="D",4)} -> 3
A13: 591V226/035 | B13: TTS40 | C13: E075 | D13: 0000 | E13: KMS_RouteECP | F13: 591V226/035TTS40E075 | G13: =k[[#This Row],[PartType]]&k[[#This Row],[PowderType]] -> 591V226/035TTS40 | H13: X30114BP6 | I13: {=_xlfn.IFS(LEFT(k[[#This Row],[ParameterValue]],1)="S",3,LEFT(k[[#This Row],[ParameterValue]],1)="X",2, LEFT(k[[#This Row],[ParameterValue]],1)="D",4)} -> 2
... A2674: 598D157/016 | B2674: TTS50 | C2674: W065 | D2674: 0000 | E2674: KMS_RouteECP | F2674: 598D157/016TTS50W065 | G2674: =k[[#This Row],[PartType]]&k[[#This Row],[PowderType]] -> 598D157/016TTS50 | H2674: S33133SU2P | I2674: {=_xlfn.IFS(LEFT(k[[#This Row],[ParameterValue]],1)="S",3,LEFT(k[[#This Row],[ParameterValue]],1)="X",2, LEFT(k[[#This Row],[ParameterValue]],1)="D",4)} -> 3

Sheet Form CT
A1: Column1 | B1: Column2 | C1: Column3 | D1: Column4 | E1: Column5 | F1: Column6 | G1: Column7 | H1: Column8 | I1: 8
A2: S.PN | B2: PowderPN | C2: Powder | D2: 1st | E2: 2nd | F2: 有效 | G2: Date | H2: Lots | I2: Combine
A3: T520B107M006ATE015 | B3: A520B107M006ASE015 | C3: S805 | D3: 295.07633 | E3: 151.34114 | F3: 1 | G3: 2026 | H3: 31 | I3: =A3&B3&C3 -> T520B107M006ATE015A520B107M006ASE015S805
A4: T520B107M006ATE018 | B4: A520B107M006ASE018 | C4: S805 | D4: 268.30655 | E4: 149.51505 | F4: 1 | G4: 2026 | H4: 4 | I4: =A4&B4&C4 -> T520B107M006ATE018A520B107M006ASE018S805
A5: T520B107M006ATE025 | B5: A520B157M006ASE025 | C5: STA156KA | D5: 725.04267 | E5: 202.01226 | F5: 1 | G5: 2026 | H5: 25 | I5: =A5&B5&C5 -> T520B107M006ATE025A520B157M006ASE025STA156KA
A6: T520B107M006ATE025 | B6: A520B107M006ASE025 | C6: KBP126 | D6: 420.20453 | E6: 148.95814 | F6: 1 | G6: 2026 | H6: 50 | I6: =A6&B6&C6 -> T520B107M006ATE025A520B107M006ASE025KBP126
A7: T520B107M006ATE025 | B7: A520B107M006ASE025 | C7: KBP126X | D7: 419.37188 | E7: 171.50881 | F7: 1 | G7: 2026 | H7: 5 | I7: =A7&B7&C7 -> T520B107M006ATE025A520B107M006ASE025KBP126X
A8: T520B107M006ATE035 | B8: A520B107M006ASMHSP | C8: KBP126 | D8: 424.59874 | E8: 163.52096 | F8: 1 | G8: 2026 | H8: 50 | I8: =A8&B8&C8 -> T520B107M006ATE035A520B107M006ASMHSPKBP126
A9: T520B107M006ATE040 | B9: A520B107M006ASMHSP | C9: KBP126 | D9: 429.2104 | E9: 146.62431 | F9: 1 | G9: 2026 | H9: 50 | I9: =A9&B9&C9 -> T520B107M006ATE040A520B107M006ASMHSPKBP126
A10: T520B107M006ATE040 | B10: A520B107M006AS9997 | C10: STA156KA | D10: 414.77512 | E10: 122.5935 | F10: 1 | G10: 2026 | H10: 1 | I10: =A10&B10&C10 -> T520B107M006ATE040A520B107M006AS9997STA156KA
A11: T520B107M006ATE045 | B11: A520B107M006ASMHSP | C11: KBP126 | D11: 433.32113 | E11: 165.39003 | F11: 1 | G11: 2026 | H11: 48 | I11: =A11&B11&C11 -> T520B107M006ATE045A520B107M006ASMHSPKBP126
A12: T520B157M006ATE018 | B12: A520B157M006AS9997 | C12: TTS150 | D12: 468.90198 | E12: 143.00102 | F12: 1 | G12: 2026 | H12: 5 | I12: =A12&B12&C12 -> T520B157M006ATE018A520B157M006AS9997TTS150
A13: T520B157M006ATE018 | B13: A520B157M006ASE025 | C13: STA156KA | D13: 572.88094 | E13: 200.92873 | F13: 1 | G13: 2026 | H13: 50 | I13: =A13&B13&C13 -> T520B157M006ATE018A520B157M006ASE025STA156KA
A14: T520B157M006ATE018 | B14: A520B157M006ASMHSB | C14: STA156KA | D14: 458.90724 | E14: 146.10952 | F14: 1 | G14: 2026 | H14: 50 | I14: =A14&B14&C14 -> T520B157M006ATE018A520B157M006ASMHSBSTA156KA
... A851: T520C227M006AHE025 | B851: A520C227M006ASMHSS | C851: KBP126 | D851: 337.73333 | E851: 135.13533 | F851: 1 | G851: 2026 | H851: 1 | I851: =A851&B851&C851 -> T520C227M006AHE025A520C227M006ASMHSSKBP126
A852: S.PN | B852: PowderPN | C852: Powder | D852: 1st | E852: 2nd | F852: 有效 | G852: Date | H852: Lots | I852: =A852&B852&C852 -> S.PNPowderPNPowder
A853: T520B107M006ATE015 | B853: A520B107M006ASE015 | C853: S805 | D853: 295.07633 | E853: 151.34114 | F853: 1 | G853: 2025 | H853: 31 | I853: =A853&B853&C853 -> T520B107M006ATE015A520B107M006ASE015S805
A854: T520B107M006ATE018 | B854: A520B107M006ASE018 | C854: S805 | D854: 268.30655 | E854: 149.51505 | F854: 1 | G854: 2025 | H854: 4 | I854: =A854&B854&C854 -> T520B107M006ATE018A520B107M006ASE018S805
A855: T520B107M006ATE025 | B855: A520B157M006ASE025 | C855: STA156KA | D855: 725.04267 | E855: 202.01226 | F855: 1 | G855: 2025 | H855: 25 | I855: =A855&B855&C855 -> T520B107M006ATE025A520B157M006ASE025STA156KA
A856: T520B107M006ATE025 | B856: A520B107M006ASE025 | C856: KBP126 | D856: 420.20453 | E856: 148.95814 | F856: 1 | G856: 2025 | H856: 50 | I856: =A856&B856&C856 -> T520B107M006ATE025A520B107M006ASE025KBP126
A857: T520B107M006ATE025 | B857: A520B107M006ASE025 | C857: KBP126X | D857: 419.37188 | E857: 171.50881 | F857: 1 | G857: 2025 | H857: 5 | I857: =A857&B857&C857 -> T520B107M006ATE025A520B107M006ASE025KBP126X
A858: T520B107M006ATE035 | B858: A520B107M006ASMHSP | C858: KBP126 | D858: 424.59874 | E858: 163.52096 | F858: 1 | G858: 2025 | H858: 50 | I858: =A858&B858&C858 -> T520B107M006ATE035A520B107M006ASMHSPKBP126
A859: T520B107M006ATE040 | B859: A520B107M006ASMHSP | C859: KBP126 | D859: 429.2104 | E859: 146.62431 | F859: 1 | G859: 2025 | H859: 50 | I859: =A859&B859&C859 -> T520B107M006ATE040A520B107M006ASMHSPKBP126
A860: T520B107M006ATE040 | B860: A520B107M006AS9997 | C860: STA156KA | D860: 414.77512 | E860: 122.5935 | F860: 1 | G860: 2025 | H860: 1 | I860: =A860&B860&C860 -> T520B107M006ATE040A520B107M006AS9997STA156KA
A861: T520B107M006ATE045 | B861: A520B107M006ASMHSP | C861: KBP126 | D861: 433.32113 | E861: 165.39003 | F861: 1 | G861: 2025 | H861: 48 | I861: =A861&B861&C861 -> T520B107M006ATE045A520B107M006ASMHSPKBP126
A862: T520B157M006ATE018 | B862: A520B157M006AS9997 | C862: TTS150 | D862: 468.90198 | E862: 143.00102 | F862: 1 | G862: 2025 | H862: 5 | I862: =A862&B862&C862 -> T520B157M006ATE018A520B157M006AS9997TTS150
A863: T520B157M006ATE018 | B863: A520B157M006ASE025 | C863: STA156KA | D863: 572.88094 | E863: 200.92873 | F863: 1 | G863: 2025 | H863: 50 | I863: =A863&B863&C863 -> T520B157M006ATE018A520B157M006ASE025STA156KA
A864: T520B157M006ATE018 | B864: A520B157M006ASMHSB | C864: STA156KA | D864: 458.90724 | E864: 146.10952 | F864: 1 | G864: 2025 | H864: 50 | I864: =A864&B864&C864 -> T520B157M006ATE018A520B157M006ASMHSBSTA156KA
... A1701: T520C227M006AHE025 | B1701: A520C227M006ASMHSS | C1701: KBP126 | D1701: 337.73333 | E1701: 135.13533 | F1701: 1 | G1701: 2025 | H1701: 1 | I1701: =A1701&B1701&C1701 -> T520C227M006AHE025A520C227M006ASMHSSKBP126
A1702: S.PN | B1702: PowderPN | C1702: Powder | D1702: 1st | E1702: 2nd | F1702: 有效 | G1702: Date | H1702: Lots | I1702: =A1702&B1702&C1702 -> S.PNPowderPNPowder
A1703: T520B107M006ATE015 | B1703: A520B107M006ASE015 | C1703: S805 | D1703: 330.10805 | E1703: 213.2414 | F1703: 1 | G1703: 2024 | H1703: 19 | I1703: =A1703&B1703&C1703 -> T520B107M006ATE015A520B107M006ASE015S805
A1704: T520B107M006ATE018 | B1704: A520B107M006ASE018 | C1704: S805 | D1704: 301.25067 | E1704: 201.37123 | F1704: 1 | G1704: 2024 | H1704: 1 | I1704: =A1704&B1704&C1704 -> T520B107M006ATE018A520B107M006ASE018S805
A1705: T520B107M006ATE018 | B1705: A520B107M006AS9997 | C1705: KBP74E | D1705: 393.81455 | E1705: 131.141 | F1705: 1 | G1705: 2024 | H1705: 1 | I1705: =A1705&B1705&C1705 -> T520B107M006ATE018A520B107M006AS9997KBP74E
A1706: T520B107M006ATE018 | B1706: A520B107M006AS9997 | C1706: KBP126X | D1706: 420.01512 | E1706: 130.37038 | F1706: 1 | G1706: 2024 | H1706: 1 | I1706: =A1706&B1706&C1706 -> T520B107M006ATE018A520B107M006AS9997KBP126X
A1707: T520B107M006ATE025 | B1707: A520B157M006ASE025 | C1707: STA156KA | D1707: 699.24466 | E1707: 232.23449 | F1707: 1 | G1707: 2024 | H1707: 22 | I1707: =A1707&B1707&C1707 -> T520B107M006ATE025A520B157M006ASE025STA156KA
A1708: T520B107M006ATE025 | B1708: A520B157M006ASE025 | C1708: SKIPR | D1708: 747.02145 | E1708: 134.37533 | F1708: 1 | G1708: 2024 | H1708: 1 | I1708: =A1708&B1708&C1708 -> T520B107M006ATE025A520B157M006ASE025SKIPR
A1709: T520B107M006ATE025 | B1709: A520B107M006AS9997 | C1709: KBP126X | D1709: 562.92383 | E1709: 123.9915 | F1709: 1 | G1709: 2024 | H1709: 1 | I1709: =A1709&B1709&C1709 -> T520B107M006ATE025A520B107M006AS9997KBP126X
A1710: T520B107M006ATE040 | B1710: A520B107M006ASMHSP | C1710: KBP126 | D1710: 447.13612 | E1710: 167.97344 | F1710: 1 | G1710: 2024 | H1710: 50 | I1710: =A1710&B1710&C1710 -> T520B107M006ATE040A520B107M006ASMHSPKBP126
A1711: T520B107M006ATE045 | B1711: A520B107M006ASMHSP | C1711: KBP126 | D1711: 472.42606 | E1711: 178.60598 | F1711: 1 | G1711: 2024 | H1711: 50 | I1711: =A1711&B1711&C1711 -> T520B107M006ATE045A520B107M006ASMHSPKBP126
A1712: T520B157M006ATE018 | B1712: A520B157M006AS9997 | C1712: PTSA | D1712: 514.21486 | E1712: 278.97183 | F1712: 1 | G1712: 2024 | H1712: 4 | I1712: =A1712&B1712&C1712 -> T520B157M006ATE018A520B157M006AS9997PTSA
...

Sheet KS2
A1: RouteChainName | B1: KS2 Cycles
A2: T520B227M004ATE0452478-A520B227M004ASE035-STA156KA | B2: 1
A3: T520B227M004ATE070-A520B227M004AS-STA156KA | B3: 1
A4: T520B227M006ATE035-A520B227M006AS9997-STA200KE | B4: 1
A5: T520B337M006ATE0407652-A520B337M006ASALT1-STA200KA | B5: 1
A6: T520B337M006ATE040-A520B337M006AS9997-STA200KA | B6: 1
A7: T520B337M006ATE040-A520B337M006ASALT1-STA200KA | B7: 1
A8: T520B337M006ATE040-A520B337M006ASE040-STA200KA | B8: 1
A9: T520B337M006ATE0707652-A520B337M006ASE040-STA200KA | B9: 1
A10: T520B337M006ATE070-A520B337M006ASALT1-STA200KA | B10: 1
A11: T520B337M006ATE070-A520B337M006ASE040-STA200KA | B11: 1
A12: T520M157M006ATE0707650-A520M157M006ASALT1-S15MB | B12: 1
A13: T520M157M006ATE0707650-A520M157M006ASE070-STA156KA | B13: 1
... A429: T523H107M035AP4407-A523H107M035ASSZ02-S706 | B429: 7

Sheet Details (2)
A1: anodeLotID | B1: partNumber | C1: component | D1: powderName | E1: planDate | F1: quantity | G1: startDate | H1: needDate | I1: category | J1: ecpCycle | K1: rCycle | L1: uano | M1: cv | N1: electrolyteType | O1: width | P1: length | Q1: thickness | R1: wiresize | S1: barsPerLid | T1: piecesPerBar | U1: lidRequest | V1: ecpRoute | W1: up | X1: formationCT | Y1: batchSize | Z1: subInventory | AA1: comments | AB1: notes | AC1: orderNumber | AD1: P | AE1: Y | AF1: NGZ | AG1: 停线3天 | AH1: KS2 | AI1: Carouselwash
A2: 2628IF67 | B2: T598D337M006AT41437280 | C2: A598D337M006AS | D2: KBP55 | E2: 2026-07-29 | F2: 20334 | G2: 2026-07-24 | H2: 2026-08-29 | I2: T59D 1 | J2: 8 | K2: 5 | L2: XLPJ61043191-023 | M2: 5896.7 | N2: NGZ | O2: 0.128 | P2: 0.185 | Q2: 0.062 | R2: 0.015 | S2: 50 | T2: 37 | U2: 18 | V2: S35113SP | W2: 32 | X2: 26125.24 | Y2: 33300 | Z2: ANODE-INSP | AA2: fixed,TopRunners,push out | AB2: pass due | AC2: 3882507304 | AD2: =IF(N2=$AD$1,_xlfn.XLOOKUP(LEFT(B2,18)&C2&D2,'Form CT'!I:I,'Form CT'!D:D,0)+_xlfn.XLOOKUP(LEFT(B2,18)&C2&D2,'Form CT'!I:I,'Form CT'!E:E,0),0) -> 0 | AE2: =IF(N2=$AE$1,_xlfn.XLOOKUP(LEFT(B2,18)&C2&D2,'Form CT'!I:I,'Form CT'!D:D,0)+_xlfn.XLOOKUP(LEFT(B2,18)&C2&D2,'Form CT'!I:I,'Form CT'!E:E,0),0) -> 0 | AF2: =IF(N2=$AF$1,_xlfn.XLOOKUP(LEFT(B2,18)&C2&D2,'Form CT'!I:I,'Form CT'!D:D,0)+_xlfn.XLOOKUP(LEFT(B2,18)&C2&D2,'Form CT'!I:I,'Form CT'!E:E,0),0) -> 442.91429 | AG2: =IF(OR( AND(MID(B2,2,2)="59", VALUE(MID(B2,11,2))>24), AND(LEFT(B2,4)="T521", VALUE(MID(B2,11,2))>62), LEFT(B2,4)="T523" ), "符合", "不符合") -> 不符合 | AH2: =_xlfn.XLOOKUP(TRIM(CLEAN(B2))&"-"&TRIM(CLEAN(C2))&"-"&TRIM(CLEAN(D2)),'KS2'!A:A,'KS2'!B:B,0) -> 0 | AI2: =IF(_xlfn.XLOOKUP(MID(B2,2,7)&"/"&MID(B2,10,3)&TRIM(D2)&MID(B2,15,4),Carouselwash!F:F,Carouselwash!I:I,0)=0,_xlfn.XLOOKUP((MID(C2,2,7)&"/"&MID(C2,10,3)&TRIM(D2)),Carouselwash!G:G,Carouselwash!I:I,0),_xlfn.XLOOKUP(MID(B2,2,7)&"/"&MID(B2,10,3)&TRIM(D2)&MID(B2,15,4),Carouselwash!F:F,Carouselwash!I:I,0)) -> 3
A3: 2628DJ67 | B3: T521D106M050ATE0907654 | C3: A521D106M050ASE060 | D3: FTP150 | E3: 2026-07-28 | F3: 16199 | G3: 2026-08-08 | H3: 2026-08-28 | I3: D | J3: 2 | K3: 0 | L3: WB4R16643191-014 | M3: 1676.4 | N3: Y | O3: 0.122 | P3: 0.18 | Q3: 0.056 | R3: 0.015 | S3: 35 | T3: 26 | U3: 18 | V3: X20104BP6 | W3: 32 | X3: 57063.87 | Y3: 16380 | Z3: Intransit | AA3: fixed,TopRunners,pull in | AC3: 3882464174 | AD3: =IF(N3=$AD$1,_xlfn.XLOOKUP(LEFT(B3,18)&C3&D3,'Form CT'!I:I,'Form CT'!D:D,0)+_xlfn.XLOOKUP(LEFT(B3,18)&C3&D3,'Form CT'!I:I,'Form CT'!E:E,0),0) -> 0 | AE3: =IF(N3=$AE$1,_xlfn.XLOOKUP(LEFT(B3,18)&C3&D3,'Form CT'!I:I,'Form CT'!D:D,0)+_xlfn.XLOOKUP(LEFT(B3,18)&C3&D3,'Form CT'!I:I,'Form CT'!E:E,0),0) -> 964.72306 | AF3: =IF(N3=$AF$1,_xlfn.XLOOKUP(LEFT(B3,18)&C3&D3,'Form CT'!I:I,'Form CT'!D:D,0)+_xlfn.XLOOKUP(LEFT(B3,18)&C3&D3,'Form CT'!I:I,'Form CT'!E:E,0),0) -> 0 | AG3: =IF(OR( AND(MID(B3,2,2)="59", VALUE(MID(B3,11,2))>24), AND(LEFT(B3,4)="T521", VALUE(MID(B3,11,2))>62), LEFT(B3,4)="T523" ), "符合", "不符合") -> 不符合 | AH3: =_xlfn.XLOOKUP(TRIM(CLEAN(B3))&"-"&TRIM(CLEAN(C3))&"-"&TRIM(CLEAN(D3)),'KS2'!A:A,'KS2'!B:B,0) -> 1 | AI3: =IF(_xlfn.XLOOKUP(MID(B3,2,7)&"/"&MID(B3,10,3)&TRIM(D3)&MID(B3,15,4),Carouselwash!F:F,Carouselwash!I:I,0)=0,_xlfn.XLOOKUP((MID(C3,2,7)&"/"&MID(C3,10,3)&TRIM(D3)),Carouselwash!G:G,Carouselwash!I:I,0),_xlfn.XLOOKUP(MID(B3,2,7)&"/"&MID(B3,10,3)&TRIM(D3)&MID(B3,15,4),Carouselwash!F:F,Carouselwash!I:I,0)) -> 2
A4: 2628X417 | B4: T598D476M016ATE070 | C4: A598D476M016AS | D4: TTS50 | E4: 2026-07-29 | F4: 29328 | G4: 2026-07-25 | H4: 2026-08-24 | I4: T59D 1 | J4: 7 | K4: 4 | L4: WI/M3014K187-006 | M4: 3057.8 | N4: P | O4: 0.128 | P4: 0.17 | Q4: 0.033 | R4: 0.015 | S4: 50 | T4: 37 | U4: 18 | V4: S34143XSU2P | W4: 32 | X4: 41472.99 | Y4: 33300 | Z4: ANODE-KO | AA4: fixed,pass due,push out | AB4: 3882577024-QTY:16836,pass due | AC4: 3882577023 | AD4: =IF(N4=$AD$1,_xlfn.XLOOKUP(LEFT(B4,18)&C4&D4,'Form CT'!I:I,'Form CT'!D:D,0)+_xlfn.XLOOKUP(LEFT(B4,18)&C4&D4,'Form CT'!I:I,'Form CT'!E:E,0),0) -> 678.41475 | AE4: =IF(N4=$AE$1,_xlfn.XLOOKUP(LEFT(B4,18)&C4&D4,'Form CT'!I:I,'Form CT'!D:D,0)+_xlfn.XLOOKUP(LEFT(B4,18)&C4&D4,'Form CT'!I:I,'Form CT'!E:E,0),0) -> 0 | AF4: =IF(N4=$AF$1,_xlfn.XLOOKUP(LEFT(B4,18)&C4&D4,'Form CT'!I:I,'Form CT'!D:D,0)+_xlfn.XLOOKUP(LEFT(B4,18)&C4&D4,'Form CT'!I:I,'Form CT'!E:E,0),0) -> 0 | AG4: =IF(OR( AND(MID(B4,2,2)="59", VALUE(MID(B4,11,2))>24), AND(LEFT(B4,4)="T521", VALUE(MID(B4,11,2))>62), LEFT(B4,4)="T523" ), "符合", "不符合") -> 不符合 | AH4: =_xlfn.XLOOKUP(TRIM(CLEAN(B4))&"-"&TRIM(CLEAN(C4))&"-"&TRIM(CLEAN(D4)),'KS2'!A:A,'KS2'!B:B,0) -> 1 | AI4: =IF(_xlfn.XLOOKUP(MID(B4,2,7)&"/"&MID(B4,10,3)&TRIM(D4)&MID(B4,15,4),Carouselwash!F:F,Carouselwash!I:I,0)=0,_xlfn.XLOOKUP((MID(C4,2,7)&"/"&MID(C4,10,3)&TRIM(D4)),Carouselwash!G:G,Carouselwash!I:I,0),_xlfn.XLOOKUP(MID(B4,2,7)&"/"&MID(B4,10,3)&TRIM(D4)&MID(B4,15,4),Carouselwash!F:F,Carouselwash!I:I,0)) -> 3
A5: 2628KN57 | B5: T520B157M006ATE0707028 | C5: A520B157M006ASMHSP | D5: S15MB | E5: 2026-07-28 | F5: 50694 | G5: 2026-08-03 | H5: 2026-08-22 | I5: B | J5: 9 | K5: 5 | L5: Q46R2254D191-001 | M5: 2150.3 | N5: P | O5: 0.089 | P5: 0.054 | Q5: 0.041 | R5: 0.0118 | S5: 60 | T5: 47 | U5: 18 | V5: S45103XNU2P | W5: 42 | X5: 45705.58 | Y5: 50760 | Z5: Intransit | AA5: ,pull in | AB5: 3882422094-QTY:15115 | AC5: 3882422093 | AD5: =IF(N5=$AD$1,_xlfn.XLOOKUP(LEFT(B5,18)&C5&D5,'Form CT'!I:I,'Form CT'!D:D,0)+_xlfn.XLOOKUP(LEFT(B5,18)&C5&D5,'Form CT'!I:I,'Form CT'!E:E,0),0) -> 775.01502 | AE5: =IF(N5=$AE$1,_xlfn.XLOOKUP(LEFT(B5,18)&C5&D5,'Form CT'!I:I,'Form CT'!D:D,0)+_xlfn.XLOOKUP(LEFT(B5,18)&C5&D5,'Form CT'!I:I,'Form CT'!E:E,0),0) -> 0 | AF5: =IF(N5=$AF$1,_xlfn.XLOOKUP(LEFT(B5,18)&C5&D5,'Form CT'!I:I,'Form CT'!D:D,0)+_xlfn.XLOOKUP(LEFT(B5,18)&C5&D5,'Form CT'!I:I,'Form CT'!E:E,0),0) -> 0 | AG5: =IF(OR( AND(MID(B5,2,2)="59", VALUE(MID(B5,11,2))>24), AND(LEFT(B5,4)="T521", VALUE(MID(B5,11,2))>62), LEFT(B5,4)="T523" ), "符合", "不符合") -> 不符合 | AH5: =_xlfn.XLOOKUP(TRIM(CLEAN(B5))&"-"&TRIM(CLEAN(C5))&"-"&TRIM(CLEAN(D5)),'KS2'!A:A,'KS2'!B:B,0) -> 0 | AI5: =IF(_xlfn.XLOOKUP(MID(B5,2,7)&"/"&MID(B5,10,3)&TRIM(D5)&MID(B5,15,4),Carouselwash!F:F,Carouselwash!I:I,0)=0,_xlfn.XLOOKUP((MID(C5,2,7)&"/"&MID(C5,10,3)&TRIM(D5)),Carouselwash!G:G,Carouselwash!I:I,0),_xlfn.XLOOKUP(MID(B5,2,7)&"/"&MID(B5,10,3)&TRIM(D5)&MID(B5,15,4),Carouselwash!F:F,Carouselwash!I:I,0)) -> 3
A6: 2628LS67 | B6: T598D337M006AT4143 | C6: A598D337M006AS | D6: KBP55 | E6: 2026-07-29 | F6: 20321 | G6: 2026-07-28 | H6: 2026-09-02 | I6: T59D 1 | J6: 8 | K6: 5 | L6: XLPJ61043191-034 | M6: 5883.9 | N6: NGZ | O6: 0.128 | P6: 0.185 | Q6: 0.062 | R6: 0.015 | S6: 50 | T6: 37 | U6: 18 | V6: S35113SP | W6: 32 | X6: 26236.47 | Y6: 33300 | Z6: ANODE-INSP | AA6: fixed,TopRunners | AB6: pass due | AC6: 3882577240 | AD6: =IF(N6=$AD$1,_xlfn.XLOOKUP(LEFT(B6,18)&C6&D6,'Form CT'!I:I,'Form CT'!D:D,0)+_xlfn.XLOOKUP(LEFT(B6,18)&C6&D6,'Form CT'!I:I,'Form CT'!E:E,0),0) -> 0 | AE6: =IF(N6=$AE$1,_xlfn.XLOOKUP(LEFT(B6,18)&C6&D6,'Form CT'!I:I,'Form CT'!D:D,0)+_xlfn.XLOOKUP(LEFT(B6,18)&C6&D6,'Form CT'!I:I,'Form CT'!E:E,0),0) -> 0 | AF6: =IF(N6=$AF$1,_xlfn.XLOOKUP(LEFT(B6,18)&C6&D6,'Form CT'!I:I,'Form CT'!D:D,0)+_xlfn.XLOOKUP(LEFT(B6,18)&C6&D6,'Form CT'!I:I,'Form CT'!E:E,0),0) -> 442.91429 | AG6: =IF(OR( AND(MID(B6,2,2)="59", VALUE(MID(B6,11,2))>24), AND(LEFT(B6,4)="T521", VALUE(MID(B6,11,2))>62), LEFT(B6,4)="T523" ), "符合", "不符合") -> 不符合 | AH6: =_xlfn.XLOOKUP(TRIM(CLEAN(B6))&"-"&TRIM(CLEAN(C6))&"-"&TRIM(CLEAN(D6)),'KS2'!A:A,'KS2'!B:B,0) -> 0 | AI6: =IF(_xlfn.XLOOKUP(MID(B6,2,7)&"/"&MID(B6,10,3)&TRIM(D6)&MID(B6,15,4),Carouselwash!F:F,Carouselwash!I:I,0)=0,_xlfn.XLOOKUP((MID(C6,2,7)&"/"&MID(C6,10,3)&TRIM(D6)),Carouselwash!G:G,Carouselwash!I:I,0),_xlfn.XLOOKUP(MID(B6,2,7)&"/"&MID(B6,10,3)&TRIM(D6)&MID(B6,15,4),Carouselwash!F:F,Carouselwash!I:I,0)) -> 3
A7: 2629KG47 | B7: T521D106M050ATE0907654 | C7: A521D106M050ASE060 | D7: FTP150 | E7: 2026-07-28 | F7: 16165 | G7: 2026-08-08 | H7: 2026-08-28 | I7: D | J7: 2 | K7: 0 | L7: WB4R16643197-005 | M7: 1745 | N7: Y | O7: 0.122 | P7: 0.18 | Q7: 0.056 | R7: 0.015 | S7: 35 | T7: 26 | U7: 18 | V7: X20104BP6 | W7: 32 | X7: 57063.87 | Y7: 16380 | Z7: Intransit | AA7: fixed,TopRunners,pull in | AC7: 3882464174 | AD7: =IF(N7=$AD$1,_xlfn.XLOOKUP(LEFT(B7,18)&C7&D7,'Form CT'!I:I,'Form CT'!D:D,0)+_xlfn.XLOOKUP(LEFT(B7,18)&C7&D7,'Form CT'!I:I,'Form CT'!E:E,0),0) -> 0 | AE7: =IF(N7=$AE$1,_xlfn.XLOOKUP(LEFT(B7,18)&C7&D7,'Form CT'!I:I,'Form CT'!D:D,0)+_xlfn.XLOOKUP(LEFT(B7,18)&C7&D7,'Form CT'!I:I,'Form CT'!E:E,0),0) -> 964.72306 | AF7: =IF(N7=$AF$1,_xlfn.XLOOKUP(LEFT(B7,18)&C7&D7,'Form CT'!I:I,'Form CT'!D:D,0)+_xlfn.XLOOKUP(LEFT(B7,18)&C7&D7,'Form CT'!I:I,'Form CT'!E:E,0),0) -> 0 | AG7: =IF(OR( AND(MID(B7,2,2)="59", VALUE(MID(B7,11,2))>24), AND(LEFT(B7,4)="T521", VALUE(MID(B7,11,2))>62), LEFT(B7,4)="T523" ), "符合", "不符合") -> 不符合 | AH7: =_xlfn.XLOOKUP(TRIM(CLEAN(B7))&"-"&TRIM(CLEAN(C7))&"-"&TRIM(CLEAN(D7)),'KS2'!A:A,'KS2'!B:B,0) -> 1 | AI7: =IF(_xlfn.XLOOKUP(MID(B7,2,7)&"/"&MID(B7,10,3)&TRIM(D7)&MID(B7,15,4),Carouselwash!F:F,Carouselwash!I:I,0)=0,_xlfn.XLOOKUP((MID(C7,2,7)&"/"&MID(C7,10,3)&TRIM(D7)),Carouselwash!G:G,Carouselwash!I:I,0),_xlfn.XLOOKUP(MID(B7,2,7)&"/"&MID(B7,10,3)&TRIM(D7)&MID(B7,15,4),Carouselwash!F:F,Carouselwash!I:I,0)) -> 2
A8: 2629JW57 | B8: T521T106M025ATE0607652 | C8: A521T106M025AS | D8: FTW700 | E8: 2026-07-28 | F8: 50760 | G8: 2026-08-09 | H8: 2026-08-29 | I8: T-G | J8: 5 | K8: 0 | L8: QPSO6083A198-002 | M8: 584.4 | N8: P | O8: 0.094 | P8: 0.07 | Q8: 0.019 | R8: 0.0098 | S8: 60 | T8: 47 | U8: 18 | V8: S50123BP6 | W8: 42 | X8: 42804.22 | Y8: 50760 | Z8: Intransit | AA8: ,pull in | AC8: 3882475903 | AD8: =IF(N8=$AD$1,_xlfn.XLOOKUP(LEFT(B8,18)&C8&D8,'Form CT'!I:I,'Form CT'!D:D,0)+_xlfn.XLOOKUP(LEFT(B8,18)&C8&D8,'Form CT'!I:I,'Form CT'!E:E,0),0) -> 734.16662 | AE8: =IF(N8=$AE$1,_xlfn.XLOOKUP(LEFT(B8,18)&C8&D8,'Form CT'!I:I,'Form CT'!D:D,0)+_xlfn.XLOOKUP(LEFT(B8,18)&C8&D8,'Form CT'!I:I,'Form CT'!E:E,0),0) -> 0 | AF8: =IF(N8=$AF$1,_xlfn.XLOOKUP(LEFT(B8,18)&C8&D8,'Form CT'!I:I,'Form CT'!D:D,0)+_xlfn.XLOOKUP(LEFT(B8,18)&C8&D8,'Form CT'!I:I,'Form CT'!E:E,0),0) -> 0 | AG8: =IF(OR( AND(MID(B8,2,2)="59", VALUE(MID(B8,11,2))>24), AND(LEFT(B8,4)="T521", VALUE(MID(B8,11,2))>62), LEFT(B8,4)="T523" ), "符合", "不符合") -> 不符合 | AH8: =_xlfn.XLOOKUP(TRIM(CLEAN(B8))&"-"&TRIM(CLEAN(C8))&"-"&TRIM(CLEAN(D8)),'KS2'!A:A,'KS2'!B:B,0) -> 4 | AI8: =IF(_xlfn.XLOOKUP(MID(B8,2,7)&"/"&MID(B8,10,3)&TRIM(D8)&MID(B8,15,4),Carouselwash!F:F,Carouselwash!I:I,0)=0,_xlfn.XLOOKUP((MID(C8,2,7)&"/"&MID(C8,10,3)&TRIM(D8)),Carouselwash!G:G,Carouselwash!I:I,0),_xlfn.XLOOKUP(MID(B8,2,7)&"/"&MID(B8,10,3)&TRIM(D8)&MID(B8,15,4),Carouselwash!F:F,Carouselwash!I:I,0)) -> 3
A9: 2628LN67 | B9: T598D227M2R5ATE009 | C9: A598D227M004AS | D9: KBP55 | E9: 2026-07-29 | F9: 32703 | G9: 2026-07-26 | H9: 2026-08-25 | I9: T59D 1 | J9: 13 | K9: 8 | L9: NC5B34549191-001 | M9: 3425.4 | N9: NGZ | O9: 0.14 | P9: 0.19 | Q9: 0.036 | R9: 0.0193 | S9: 50 | T9: 37 | U9: 18 | V9: S58112SJ | W9: 32 | X9: 22819.76 | Y9: 33300 | Z9: ANODE-KO | AA9: fixed,pass due,push out | AB9: 3882430210-QTY:11609,pass due | AC9: 3882430209 | AD9: =IF(N9=$AD$1,_xlfn.XLOOKUP(LEFT(B9,18)&C9&D9,'Form CT'!I:I,'Form CT'!D:D,0)+_xlfn.XLOOKUP(LEFT(B9,18)&C9&D9,'Form CT'!I:I,'Form CT'!E:E,0),0) -> 0 | AE9: =IF(N9=$AE$1,_xlfn.XLOOKUP(LEFT(B9,18)&C9&D9,'Form CT'!I:I,'Form CT'!D:D,0)+_xlfn.XLOOKUP(LEFT(B9,18)&C9&D9,'Form CT'!I:I,'Form CT'!E:E,0),0) -> 0 | AF9: =IF(N9=$AF$1,_xlfn.XLOOKUP(LEFT(B9,18)&C9&D9,'Form CT'!I:I,'Form CT'!D:D,0)+_xlfn.XLOOKUP(LEFT(B9,18)&C9&D9,'Form CT'!I:I,'Form CT'!E:E,0),0) -> 380.90338 | AG9: =IF(OR( AND(MID(B9,2,2)="59", VALUE(MID(B9,11,2))>24), AND(LEFT(B9,4)="T521", VALUE(MID(B9,11,2))>62), LEFT(B9,4)="T523" ), "符合", "不符合") -> #VALUE! | AH9: =_xlfn.XLOOKUP(TRIM(CLEAN(B9))&"-"&TRIM(CLEAN(C9))&"-"&TRIM(CLEAN(D9)),'KS2'!A:A,'KS2'!B:B,0) -> 0 | AI9: =IF(_xlfn.XLOOKUP(MID(B9,2,7)&"/"&MID(B9,10,3)&TRIM(D9)&MID(B9,15,4),Carouselwash!F:F,Carouselwash!I:I,0)=0,_xlfn.XLOOKUP((MID(C9,2,7)&"/"&MID(C9,10,3)&TRIM(D9)),Carouselwash!G:G,Carouselwash!I:I,0),_xlfn.XLOOKUP(MID(B9,2,7)&"/"&MID(B9,10,3)&TRIM(D9)&MID(B9,15,4),Carouselwash!F:F,Carouselwash!I:I,0)) -> 3
A10: 2629JR27 | B10: T521X336M050ATE075 | C10: A521V156M050AS | D10: FTP200 | E10: 2026-07-28 | F10: 15976 | G10: 2026-08-10 | H10: 2026-09-05 | I10: T521X | J10: 2 | K10: 0 | L10: WB.D24243195-002 | M10: 2422.7 | N10: Y | O10: 0.122 | P10: 0.18 | Q10: 0.056 | R10: 0.015 | S10: 35 | T10: 26 | U10: 18 | V10: X20113V3EP5 | W10: 32 | X10: 53648.24 | Y10: 16380 | Z10: Intransit | AA10: ,pull in | AB10: 3882483890-QTY:5655 | AC10: 3882483889 | AD10: =IF(N10=$AD$1,_xlfn.XLOOKUP(LEFT(B10,18)&C10&D10,'Form CT'!I:I,'Form CT'!D:D,0)+_xlfn.XLOOKUP(LEFT(B10,18)&C10&D10,'Form CT'!I:I,'Form CT'!E:E,0),0) -> 0 | AE10: =IF(N10=$AE$1,_xlfn.XLOOKUP(LEFT(B10,18)&C10&D10,'Form CT'!I:I,'Form CT'!D:D,0)+_xlfn.XLOOKUP(LEFT(B10,18)&C10&D10,'Form CT'!I:I,'Form CT'!E:E,0),0) -> 853.81156 | AF10: =IF(N10=$AF$1,_xlfn.XLOOKUP(LEFT(B10,18)&C10&D10,'Form CT'!I:I,'Form CT'!D:D,0)+_xlfn.XLOOKUP(LEFT(B10,18)&C10&D10,'Form CT'!I:I,'Form CT'!E:E,0),0) -> 0 | AG10: =IF(OR( AND(MID(B10,2,2)="59", VALUE(MID(B10,11,2))>24), AND(LEFT(B10,4)="T521", VALUE(MID(B10,11,2))>62), LEFT(B10,4)="T523" ), "符合", "不符合") -> 不符合 | AH10: =_xlfn.XLOOKUP(TRIM(CLEAN(B10))&"-"&TRIM(CLEAN(C10))&"-"&TRIM(CLEAN(D10)),'KS2'!A:A,'KS2'!B:B,0) -> 0 | AI10: =IF(_xlfn.XLOOKUP(MID(B10,2,7)&"/"&MID(B10,10,3)&TRIM(D10)&MID(B10,15,4),Carouselwash!F:F,Carouselwash!I:I,0)=0,_xlfn.XLOOKUP((MID(C10,2,7)&"/"&MID(C10,10,3)&TRIM(D10)),Carouselwash!G:G,Carouselwash!I:I,0),_xlfn.XLOOKUP(MID(B10,2,7)&"/"&MID(B10,10,3)&TRIM(D10)&MID(B10,15,4),Carouselwash!F:F,Carouselwash!I:I,0)) -> 2
A11: 2628QC37 | B11: T598D477M2R5ATE006 | C11: A598V247M004AS | D11: TTS80 | E11: 2026-07-28 | F11: 40428 | G11: 2026-08-01 | H11: 2026-09-06 | I11: T59D 2 | J11: 14 | K11: 9 | L11: R8TE28649189-015 | M11: 2821.6 | N11: NGZ | O11: 0.065 | P11: 0.17 | Q11: 0.04 | R11: 0.0193 | S11: 50 | T11: 47 | U11: 18 | V11: S59112SJ4 | W11: 32 | X11: 20932.16 | Y11: 42300 | Z11: ANODE-KO | AA11: ,pull in | AC11: 3882573994 | AD11: =IF(N11=$AD$1,_xlfn.XLOOKUP(LEFT(B11,18)&C11&D11,'Form CT'!I:I,'Form CT'!D:D,0)+_xlfn.XLOOKUP(LEFT(B11,18)&C11&D11,'Form CT'!I:I,'Form CT'!E:E,0),0) -> 0 | AE11: =IF(N11=$AE$1,_xlfn.XLOOKUP(LEFT(B11,18)&C11&D11,'Form CT'!I:I,'Form CT'!D:D,0)+_xlfn.XLOOKUP(LEFT(B11,18)&C11&D11,'Form CT'!I:I,'Form CT'!E:E,0),0) -> 0 | AF11: =IF(N11=$AF$1,_xlfn.XLOOKUP(LEFT(B11,18)&C11&D11,'Form CT'!I:I,'Form CT'!D:D,0)+_xlfn.XLOOKUP(LEFT(B11,18)&C11&D11,'Form CT'!I:I,'Form CT'!E:E,0),0) -> 349.29693 | AG11: =IF(OR( AND(MID(B11,2,2)="59", VALUE(MID(B11,11,2))>24), AND(LEFT(B11,4)="T521", VALUE(MID(B11,11,2))>62), LEFT(B11,4)="T523" ), "符合", "不符合") -> #VALUE! | AH11: =_xlfn.XLOOKUP(TRIM(CLEAN(B11))&"-"&TRIM(CLEAN(C11))&"-"&TRIM(CLEAN(D11)),'KS2'!A:A,'KS2'!B:B,0) -> 0 | AI11: =IF(_xlfn.XLOOKUP(MID(B11,2,7)&"/"&MID(B11,10,3)&TRIM(D11)&MID(B11,15,4),Carouselwash!F:F,Carouselwash!I:I,0)=0,_xlfn.XLOOKUP((MID(C11,2,7)&"/"&MID(C11,10,3)&TRIM(D11)),Carouselwash!G:G,Carouselwash!I:I,0),_xlfn.XLOOKUP(MID(B11,2,7)&"/"&MID(B11,10,3)&TRIM(D11)&MID(B11,15,4),Carouselwash!F:F,Carouselwash!I:I,0)) -> 3
A12: 2627SV67 | B12: T598D687M2R5ATE006 | C12: A598V347M2R5AS | D12: KBP86 | E12: 2026-07-28 | F12: 42300 | G12: 2026-07-31 | H12: 2026-09-08 | I12: T59D 2 | J12: 14 | K12: 9 | L12: R8KZ34849184-001 | M12: 3588.8 | N12: NGZ | O12: 0.065 | P12: 0.17 | Q12: 0.046 | R12: 0.0193 | S12: 50 | T12: 47 | U12: 18 | V12: S59112SJ4 | W12: 32 | X12: 33606.44 | Y12: 42300 | Z12: ANODE-KO | AA12: fixed,TopRunners,pull in | AC12: 3882411404 | AD12: =IF(N12=$AD$1,_xlfn.XLOOKUP(LEFT(B12,18)&C12&D12,'Form CT'!I:I,'Form CT'!D:D,0)+_xlfn.XLOOKUP(LEFT(B12,18)&C12&D12,'Form CT'!I:I,'Form CT'!E:E,0),0) -> 0 | AE12: =IF(N12=$AE$1,_xlfn.XLOOKUP(LEFT(B12,18)&C12&D12,'Form CT'!I:I,'Form CT'!D:D,0)+_xlfn.XLOOKUP(LEFT(B12,18)&C12&D12,'Form CT'!I:I,'Form CT'!E:E,0),0) -> 0 | AF12: =IF(N12=$AF$1,_xlfn.XLOOKUP(LEFT(B12,18)&C12&D12,'Form CT'!I:I,'Form CT'!D:D,0)+_xlfn.XLOOKUP(LEFT(B12,18)&C12&D12,'Form CT'!I:I,'Form CT'!E:E,0),0) -> 551.8743 | AG12: =IF(OR( AND(MID(B12,2,2)="59", VALUE(MID(B12,11,2))>24), AND(LEFT(B12,4)="T521", VALUE(MID(B12,11,2))>62), LEFT(B12,4)="T523" ), "符合", "不符合") -> #VALUE! | AH12: =_xlfn.XLOOKUP(TRIM(CLEAN(B12))&"-"&TRIM(CLEAN(C12))&"-"&TRIM(CLEAN(D12)),'KS2'!A:A,'KS2'!B:B,0) -> 0 | AI12: =IF(_xlfn.XLOOKUP(MID(B12,2,7)&"/"&MID(B12,10,3)&TRIM(D12)&MID(B12,15,4),Carouselwash!F:F,Carouselwash!I:I,0)=0,_xlfn.XLOOKUP((MID(C12,2,7)&"/"&MID(C12,10,3)&TRIM(D12)),Carouselwash!G:G,Carouselwash!I:I,0),_xlfn.XLOOKUP(MID(B12,2,7)&"/"&MID(B12,10,3)&TRIM(D12)&MID(B12,15,4),Carouselwash!F:F,Carouselwash!I:I,0)) -> 3
A13: 2628PW17 | B13: T521D107M025ATE040 | C13: A521D107M025ASMHSP | D13: TTS50 | E13: 2026-07-28 | F13: 28832 | G13: 2026-07-30 | H13: 2026-08-19 | I13: D | J13: 6 | K13: 4 | L13: WIV$55043187-046 | M13: 5729.8 | N13: P | O13: 0.128 | P13: 0.17 | Q13: 0.064 | R13: 0.015 | S13: 50 | T13: 32 | U13: 18 | V13: S24143SXU3P | W13: 32 | X13: 34325.82 | Y13: 28800 | Z13: ANODE-KO | AA13: fixed,TopRunners,pull in | AC13: 3882472840 | AD13: =IF(N13=$AD$1,_xlfn.XLOOKUP(LEFT(B13,18)&C13&D13,'Form CT'!I:I,'Form CT'!D:D,0)+_xlfn.XLOOKUP(LEFT(B13,18)&C13&D13,'Form CT'!I:I,'Form CT'!E:E,0),0) -> 582.15053 | AE13: =IF(N13=$AE$1,_xlfn.XLOOKUP(LEFT(B13,18)&C13&D13,'Form CT'!I:I,'Form CT'!D:D,0)+_xlfn.XLOOKUP(LEFT(B13,18)&C13&D13,'Form CT'!I:I,'Form CT'!E:E,0),0) -> 0 | AF13: =IF(N13=$AF$1,_xlfn.XLOOKUP(LEFT(B13,18)&C13&D13,'Form CT'!I:I,'Form CT'!D:D,0)+_xlfn.XLOOKUP(LEFT(B13,18)&C13&D13,'Form CT'!I:I,'Form CT'!E:E,0),0) -> 0 | AG13: =IF(OR( AND(MID(B13,2,2)="59", VALUE(MID(B13,11,2))>24), AND(LEFT(B13,4)="T521", VALUE(MID(B13,11,2))>62), LEFT(B13,4)="T523" ), "符合", "不符合") -> 不符合 | AH13: =_xlfn.XLOOKUP(TRIM(CLEAN(B13))&"-"&TRIM(CLEAN(C13))&"-"&TRIM(CLEAN(D13)),'KS2'!A:A,'KS2'!B:B,0) -> 0 | AI13: =IF(_xlfn.XLOOKUP(MID(B13,2,7)&"/"&MID(B13,10,3)&TRIM(D13)&MID(B13,15,4),Carouselwash!F:F,Carouselwash!I:I,0)=0,_xlfn.XLOOKUP((MID(C13,2,7)&"/"&MID(C13,10,3)&TRIM(D13)),Carouselwash!G:G,Carouselwash!I:I,0),_xlfn.XLOOKUP(MID(B13,2,7)&"/"&MID(B13,10,3)&TRIM(D13)&MID(B13,15,4),Carouselwash!F:F,Carouselwash!I:I,0)) -> 3
A14: 2625BL67 | B14: T521V107M020ATE055 | C14: A521V107M020ASMH01 | D14: KBP86 | E14: 2026-07-28 | F14: 33284 | G14: 2026-07-25 | H14: 2026-08-19 | I14: T59V | J14: 7 | K14: 4 | L14: XLKZ5344D170-038 | M14: 5605.8 | N14: P | O14: 0.128 | P14: 0.185 | Q14: 0.033 | R14: 0.0118 | S14: 50 | T14: 37 | U14: 18 | V14: S34153SXU2P | W14: 32 | X14: 35070.43 | Y14: 33300 | Z14: ANODE-KO | AA14: fixed,pass due,push out | AB14: 3882477144-QTY:19345,pass due | AC14: 3882477143 | AD14: =IF(N14=$AD$1,_xlfn.XLOOKUP(LEFT(B14,18)&C14&D14,'Form CT'!I:I,'Form CT'!D:D,0)+_xlfn.XLOOKUP(LEFT(B14,18)&C14&D14,'Form CT'!I:I,'Form CT'!E:E,0),0) -> 581.43039 | AE14: =IF(N14=$AE$1,_xlfn.XLOOKUP(LEFT(B14,18)&C14&D14,'Form CT'!I:I,'Form CT'!D:D,0)+_xlfn.XLOOKUP(LEFT(B14,18)&C14&D14,'Form CT'!I:I,'Form CT'!E:E,0),0) -> 0 | AF14: =IF(N14=$AF$1,_xlfn.XLOOKUP(LEFT(B14,18)&C14&D14,'Form CT'!I:I,'Form CT'!D:D,0)+_xlfn.XLOOKUP(LEFT(B14,18)&C14&D14,'Form CT'!I:I,'Form CT'!E:E,0),0) -> 0 | AG14: =IF(OR( AND(MID(B14,2,2)="59", VALUE(MID(B14,11,2))>24), AND(LEFT(B14,4)="T521", VALUE(MID(B14,11,2))>62), LEFT(B14,4)="T523" ), "符合", "不符合") -> 不符合 | AH14: =_xlfn.XLOOKUP(TRIM(CLEAN(B14))&"-"&TRIM(CLEAN(C14))&"-"&TRIM(CLEAN(D14)),'KS2'!A:A,'KS2'!B:B,0) -> 0 | AI14: =IF(_xlfn.XLOOKUP(MID(B14,2,7)&"/"&MID(B14,10,3)&TRIM(D14)&MID(B14,15,4),Carouselwash!F:F,Carouselwash!I:I,0)=0,_xlfn.XLOOKUP((MID(C14,2,7)&"/"&MID(C14,10,3)&TRIM(D14)),Carouselwash!G:G,Carouselwash!I:I,0),_xlfn.XLOOKUP(MID(B14,2,7)&"/"&MID(B14,10,3)&TRIM(D14)&MID(B14,15,4),Carouselwash!F:F,Carouselwash!I:I,0)) -> 3
A15: 2628G767 | B15: T523W476M035APE100 | C15: A523W476M035ASE100 | D15: S706 | E15: 2026-07-28 | F15: 23390 | G15: 2026-08-03 | H15: 2026-09-02 | I15: T523W | J15: 3 | K15: 0 | L15: WCU245343191-009 | M15: 4476.8 | N15: Y | O15: 0.14 | P15: 0.21 | Q15: 0.032 | R15: 0.015 | S15: 50 | T15: 26 | U15: 18 | V15: D30123BP7 | W15: 32 | X15: 68186.45 | Y15: 23400 | Z15: ANODE-KO | AA15: ,pull in | AB15: 3882488094-QTY:17381 | AC15: 3882488093 | AD15: =IF(N15=$AD$1,_xlfn.XLOOKUP(LEFT(B15,18)&C15&D15,'Form CT'!I:I,'Form CT'!D:D,0)+_xlfn.XLOOKUP(LEFT(B15,18)&C15&D15,'Form CT'!I:I,'Form CT'!E:E,0),0) -> 0 | AE15: =IF(N15=$AE$1,_xlfn.XLOOKUP(LEFT(B15,18)&C15&D15,'Form CT'!I:I,'Form CT'!D:D,0)+_xlfn.XLOOKUP(LEFT(B15,18)&C15&D15,'Form CT'!I:I,'Form CT'!E:E,0),0) -> 1148.7496 | AF15: =IF(N15=$AF$1,_xlfn.XLOOKUP(LEFT(B15,18)&C15&D15,'Form CT'!I:I,'Form CT'!D:D,0)+_xlfn.XLOOKUP(LEFT(B15,18)&C15&D15,'Form CT'!I:I,'Form CT'!E:E,0),0) -> 0 | AG15: =IF(OR( AND(MID(B15,2,2)="59", VALUE(MID(B15,11,2))>24), AND(LEFT(B15,4)="T521", VALUE(MID(B15,11,2))>62), LEFT(B15,4)="T523" ), "符合", "不符合") -> 符合 | AH15: =_xlfn.XLOOKUP(TRIM(CLEAN(B15))&"-"&TRIM(CLEAN(C15))&"-"&TRIM(CLEAN(D15)),'KS2'!A:A,'KS2'!B:B,0) -> 5 | AI15: =IF(_xlfn.XLOOKUP(MID(B15,2,7)&"/"&MID(B15,10,3)&TRIM(D15)&MID(B15,15,4),Carouselwash!F:F,Carouselwash!I:I,0)=0,_xlfn.XLOOKUP((MID(C15,2,7)&"/"&MID(C15,10,3)&TRIM(D15)),Carouselwash!G:G,Carouselwash!I:I,0),_xlfn.XLOOKUP(MID(B15,2,7)&"/"&MID(B15,10,3)&TRIM(D15)&MID(B15,15,4),Carouselwash!F:F,Carouselwash!I:I,0)) -> 4
A16: 2627GS67 | B16: T521T336M018APE0557659 | C16: A521T336M018ASTR01 | D16: FTW121KE | E16: 2026-07-28 | F16: 50605 | G16: 2026-07-28 | H16: 2026-08-19 | I16: T-A42 | J16: 10 | K16: 5 | L16: QOGQ1454A184-071 | M16: 1409.2 | N16: P | O16: 0.094 | P16: 0.076 | Q16: 0.0203 | R16: 0.0098 | S16: 60 | T16: 47 | U16: 18 | V16: S55152IXU2P | W16: 42 | X16: 66066.73 | Y16: 50760 | Z16: ANODE-KO | AA16: fixed,pull in | AC16: 3882421911 | AD16: =IF(N16=$AD$1,_xlfn.XLOOKUP(LEFT(B16,18)&C16&D16,'Form CT'!I:I,'Form CT'!D:D,0)+_xlfn.XLOOKUP(LEFT(B16,18)&C16&D16,'Form CT'!I:I,'Form CT'!E:E,0),0) -> 770.01657 | AE16: =IF(N16=$AE$1,_xlfn.XLOOKUP(LEFT(B16,18)&C16&D16,'Form CT'!I:I,'Form CT'!D:D,0)+_xlfn.XLOOKUP(LEFT(B16,18)&C16&D16,'Form CT'!I:I,'Form CT'!E:E,0),0) -> 0 | AF16: =IF(N16=$AF$1,_xlfn.XLOOKUP(LEFT(B16,18)&C16&D16,'Form CT'!I:I,'Form CT'!D:D,0)+_xlfn.XLOOKUP(LEFT(B16,18)&C16&D16,'Form CT'!I:I,'Form CT'!E:E,0),0) -> 0 | AG16: =IF(OR( AND(MID(B16,2,2)="59", VALUE(MID(B16,11,2))>24), AND(LEFT(B16,4)="T521", VALUE(MID(B16,11,2))>62), LEFT(B16,4)="T523" ), "符合", "不符合") -> 不符合 | AH16: =_xlfn.XLOOKUP(TRIM(CLEAN(B16))&"-"&TRIM(CLEAN(C16))&"-"&TRIM(CLEAN(D16)),'KS2'!A:A,'KS2'!B:B,0) -> 0 | AI16: =IF(_xlfn.XLOOKUP(MID(B16,2,7)&"/"&MID(B16,10,3)&TRIM(D16)&MID(B16,15,4),Carouselwash!F:F,Carouselwash!I:I,0)=0,_xlfn.XLOOKUP((MID(C16,2,7)&"/"&MID(C16,10,3)&TRIM(D16)),Carouselwash!G:G,Carouselwash!I:I,0),_xlfn.XLOOKUP(MID(B16,2,7)&"/"&MID(B16,10,3)&TRIM(D16)&MID(B16,15,4),Carouselwash!F:F,Carouselwash!I:I,0)) -> 3
A17: 2624DG67 | B17: T521V107M020ATE055 | C17: A521V107M020ASMH01 | D17: KBP86 | E17: 2026-07-28 | F17: 33300 | G17: 2026-07-25 | H17: 2026-08-19 | I17: T59V | J17: 7 | K17: 4 | L17: XLKZ5344D163-030 | M17: 5458.7 | N17: P | O17: 0.128 | P17: 0.185 | Q17: 0.033 | R17: 0.0118 | S17: 50 | T17: 37 | U17: 18 | V17: S34153SXU2P | W17: 32 | X17: 35070.43 | Y17: 33300 | Z17: ANODE-KO | AA17: fixed,pass due,push out | AB17: 3882477140,3882477141-QTY:13061,pass due | AC17: 3882477139 | AD17: =IF(N17=$AD$1,_xlfn.XLOOKUP(LEFT(B17,18)&C17&D17,'Form CT'!I:I,'Form CT'!D:D,0)+_xlfn.XLOOKUP(LEFT(B17,18)&C17&D17,'Form CT'!I:I,'Form CT'!E:E,0),0) -> 581.43039 | AE17: =IF(N17=$AE$1,_xlfn.XLOOKUP(LEFT(B17,18)&C17&D17,'Form CT'!I:I,'Form CT'!D:D,0)+_xlfn.XLOOKUP(LEFT(B17,18)&C17&D17,'Form CT'!I:I,'Form CT'!E:E,0),0) -> 0 | AF17: =IF(N17=$AF$1,_xlfn.XLOOKUP(LEFT(B17,18)&C17&D17,'Form CT'!I:I,'Form CT'!D:D,0)+_xlfn.XLOOKUP(LEFT(B17,18)&C17&D17,'Form CT'!I:I,'Form CT'!E:E,0),0) -> 0 | AG17: =IF(OR( AND(MID(B17,2,2)="59", VALUE(MID(B17,11,2))>24), AND(LEFT(B17,4)="T521", VALUE(MID(B17,11,2))>62), LEFT(B17,4)="T523" ), "符合", "不符合") -> 不符合 | AH17: =_xlfn.XLOOKUP(TRIM(CLEAN(B17))&"-"&TRIM(CLEAN(C17))&"-"&TRIM(CLEAN(D17)),'KS2'!A:A,'KS2'!B:B,0) -> 0 | AI17: =IF(_xlfn.XLOOKUP(MID(B17,2,7)&"/"&MID(B17,10,3)&TRIM(D17)&MID(B17,15,4),Carouselwash!F:F,Carouselwash!I:I,0)=0,_xlfn.XLOOKUP((MID(C17,2,7)&"/"&MID(C17,10,3)&TRIM(D17)),Carouselwash!G:G,Carouselwash!I:I,0),_xlfn.XLOOKUP(MID(B17,2,7)&"/"&MID(B17,10,3)&TRIM(D17)&MID(B17,15,4),Carouselwash!F:F,Carouselwash!I:I,0)) -> 3
A18: 2626KW47 | B18: T521T336M018APE0557659 | C18: A521T336M018ASTR01 | D18: FTW121KE | E18: 2026-07-28 | F18: 50474 | G18: 2026-07-28 | H18: 2026-08-19 | I18: T-A42 | J18: 10 | K18: 5 | L18: QOGQ1454A176-009 | M18: 1426.7 | N18: P | O18: 0.094 | P18: 0.076 | Q18: 0.0203 | R18: 0.0098 | S18: 60 | T18: 47 | U18: 18 | V18: S55152IXU2P | W18: 42 | X18: 66066.73 | Y18: 50760 | Z18: ANODE-KO | AA18: fixed,pull in | AC18: 3882421911 | AD18: =IF(N18=$AD$1,_xlfn.XLOOKUP(LEFT(B18,18)&C18&D18,'Form CT'!I:I,'Form CT'!D:D,0)+_xlfn.XLOOKUP(LEFT(B18,18)&C18&D18,'Form CT'!I:I,'Form CT'!E:E,0),0) -> 770.01657 | AE18: =IF(N18=$AE$1,_xlfn.XLOOKUP(LEFT(B18,18)&C18&D18,'Form CT'!I:I,'Form CT'!D:D,0)+_xlfn.XLOOKUP(LEFT(B18,18)&C18&D18,'Form CT'!I:I,'Form CT'!E:E,0),0) -> 0 | AF18: =IF(N18=$AF$1,_xlfn.XLOOKUP(LEFT(B18,18)&C18&D18,'Form CT'!I:I,'Form CT'!D:D,0)+_xlfn.XLOOKUP(LEFT(B18,18)&C18&D18,'Form CT'!I:I,'Form CT'!E:E,0),0) -> 0 | AG18: =IF(OR( AND(MID(B18,2,2)="59", VALUE(MID(B18,11,2))>24), AND(LEFT(B18,4)="T521", VALUE(MID(B18,11,2))>62), LEFT(B18,4)="T523" ), "符合", "不符合") -> 不符合 | AH18: =_xlfn.XLOOKUP(TRIM(CLEAN(B18))&"-"&TRIM(CLEAN(C18))&"-"&TRIM(CLEAN(D18)),'KS2'!A:A,'KS2'!B:B,0) -> 0 | AI18: =IF(_xlfn.XLOOKUP(MID(B18,2,7)&"/"&MID(B18,10,3)&TRIM(D18)&MID(B18,15,4),Carouselwash!F:F,Carouselwash!I:I,0)=0,_xlfn.XLOOKUP((MID(C18,2,7)&"/"&MID(C18,10,3)&TRIM(D18)),Carouselwash!G:G,Carouselwash!I:I,0),_xlfn.XLOOKUP(MID(B18,2,7)&"/"&MID(B18,10,3)&TRIM(D18)&MID(B18,15,4),Carouselwash!F:F,Carouselwash!I:I,0)) -> 3
A19: 2628PM17 | B19: T521D107M025ATE040 | C19: A521D107M025ASMHSP | D19: TTS50 | E19: 2026-07-28 | F19: 28812 | G19: 2026-07-30 | H19: 2026-08-19 | I19: D | J19: 6 | K19: 4 | L19: WIV$55043187-036 | M19: 5758.6 | N19: P | O19: 0.128 | P19: 0.17 | Q19: 0.064 | R19: 0.015 | S19: 50 | T19: 32 | U19: 18 | V19: S24143SXU3P | W19: 32 | X19: 34325.82 | Y19: 28800 | Z19: ANODE-KO | AA19: fixed,TopRunners,pull in | AC19: 3882472838 | AD19: =IF(N19=$AD$1,_xlfn.XLOOKUP(LEFT(B19,18)&C19&D19,'Form CT'!I:I,'Form CT'!D:D,0)+_xlfn.XLOOKUP(LEFT(B19,18)&C19&D19,'Form CT'!I:I,'Form CT'!E:E,0),0) -> 582.15053 | AE19: =IF(N19=$AE$1,_xlfn.XLOOKUP(LEFT(B19,18)&C19&D19,'Form CT'!I:I,'Form CT'!D:D,0)+_xlfn.XLOOKUP(LEFT(B19,18)&C19&D19,'Form CT'!I:I,'Form CT'!E:E,0),0) -> 0 | AF19: =IF(N19=$AF$1,_xlfn.XLOOKUP(LEFT(B19,18)&C19&D19,'Form CT'!I:I,'Form CT'!D:D,0)+_xlfn.XLOOKUP(LEFT(B19,18)&C19&D19,'Form CT'!I:I,'Form CT'!E:E,0),0) -> 0 | AG19: =IF(OR( AND(MID(B19,2,2)="59", VALUE(MID(B19,11,2))>24), AND(LEFT(B19,4)="T521", VALUE(MID(B19,11,2))>62), LEFT(B19,4)="T523" ), "符合", "不符合") -> 不符合 | AH19: =_xlfn.XLOOKUP(TRIM(CLEAN(B19))&"-"&TRIM(CLEAN(C19))&"-"&TRIM(CLEAN(D19)),'KS2'!A:A,'KS2'!B:B,0) -> 0 | AI19: =IF(_xlfn.XLOOKUP(MID(B19,2,7)&"/"&MID(B19,10,3)&TRIM(D19)&MID(B19,15,4),Carouselwash!F:F,Carouselwash!I:I,0)=0,_xlfn.XLOOKUP((MID(C19,2,7)&"/"&MID(C19,10,3)&TRIM(D19)),Carouselwash!G:G,Carouselwash!I:I,0),_xlfn.XLOOKUP(MID(B19,2,7)&"/"&MID(B19,10,3)&TRIM(D19)&MID(B19,15,4),Carouselwash!F:F,Carouselwash!I:I,0)) -> 3
A20: 2626SE57 | B20: T521D107M025ATE0407280 | C20: A521D107M025ASALT2 | D20: FTW503 | E20: 2026-07-28 | F20: 28900 | G20: 2026-07-25 | H20: 2026-08-17 | I20: D | J20: 6 | K20: 4 | L20: WIJ+55043177-033 | M20: 5661.2 | N20: P | O20: 0.128 | P20: 0.17 | Q20: 0.064 | R20: 0.015 | S20: 50 | T20: 32 | U20: 18 | V20: S24143SXU3P | W20: 32 | X20: 34184.05 | Y20: 28800 | Z20: ANODE-KO | AA20: fixed,TopRunners,push out | AB20: pass due | AC20: 3882468231 | AD20: =IF(N20=$AD$1,_xlfn.XLOOKUP(LEFT(B20,18)&C20&D20,'Form CT'!I:I,'Form CT'!D:D,0)+_xlfn.XLOOKUP(LEFT(B20,18)&C20&D20,'Form CT'!I:I,'Form CT'!E:E,0),0) -> 582.32677 | AE20: =IF(N20=$AE$1,_xlfn.XLOOKUP(LEFT(B20,18)&C20&D20,'Form CT'!I:I,'Form CT'!D:D,0)+_xlfn.XLOOKUP(LEFT(B20,18)&C20&D20,'Form CT'!I:I,'Form CT'!E:E,0),0) -> 0 | AF20: =IF(N20=$AF$1,_xlfn.XLOOKUP(LEFT(B20,18)&C20&D20,'Form CT'!I:I,'Form CT'!D:D,0)+_xlfn.XLOOKUP(LEFT(B20,18)&C20&D20,'Form CT'!I:I,'Form CT'!E:E,0),0) -> 0 | AG20: =IF(OR( AND(MID(B20,2,2)="59", VALUE(MID(B20,11,2))>24), AND(LEFT(B20,4)="T521", VALUE(MID(B20,11,2))>62), LEFT(B20,4)="T523" ), "符合", "不符合") -> 不符合 | AH20: =_xlfn.XLOOKUP(TRIM(CLEAN(B20))&"-"&TRIM(CLEAN(C20))&"-"&TRIM(CLEAN(D20)),'KS2'!A:A,'KS2'!B:B,0) -> 0 | AI20: =IF(_xlfn.XLOOKUP(MID(B20,2,7)&"/"&MID(B20,10,3)&TRIM(D20)&MID(B20,15,4),Carouselwash!F:F,Carouselwash!I:I,0)=0,_xlfn.XLOOKUP((MID(C20,2,7)&"/"&MID(C20,10,3)&TRIM(D20)),Carouselwash!G:G,Carouselwash!I:I,0),_xlfn.XLOOKUP(MID(B20,2,7)&"/"&MID(B20,10,3)&TRIM(D20)&MID(B20,15,4),Carouselwash!F:F,Carouselwash!I:I,0)) -> 3
A21: 2627WJ27 | B21: T598D687M2R5ATE006 | C21: A598V347M2R5AS | D21: KBP86 | E21: 2026-07-28 | F21: 42300 | G21: 2026-07-31 | H21: 2026-09-08 | I21: T59D 2 | J21: 14 | K21: 9 | L21: R8KZ34849181-005 | M21: 3615.9 | N21: NGZ | O21: 0.065 | P21: 0.17 | Q21: 0.046 | R21: 0.0193 | S21: 50 | T21: 47 | U21: 18 | V21: S59112SJ4 | W21: 32 | X21: 33606.44 | Y21: 42300 | Z21: ANODE-KO | AA21: fixed,TopRunners,pull in | AC21: 3882411404 | AD21: =IF(N21=$AD$1,_xlfn.XLOOKUP(LEFT(B21,18)&C21&D21,'Form CT'!I:I,'Form CT'!D:D,0)+_xlfn.XLOOKUP(LEFT(B21,18)&C21&D21,'Form CT'!I:I,'Form CT'!E:E,0),0) -> 0 | AE21: =IF(N21=$AE$1,_xlfn.XLOOKUP(LEFT(B21,18)&C21&D21,'Form CT'!I:I,'Form CT'!D:D,0)+_xlfn.XLOOKUP(LEFT(B21,18)&C21&D21,'Form CT'!I:I,'Form CT'!E:E,0),0) -> 0 | AF21: =IF(N21=$AF$1,_xlfn.XLOOKUP(LEFT(B21,18)&C21&D21,'Form CT'!I:I,'Form CT'!D:D,0)+_xlfn.XLOOKUP(LEFT(B21,18)&C21&D21,'Form CT'!I:I,'Form CT'!E:E,0),0) -> 551.8743 | AG21: =IF(OR( AND(MID(B21,2,2)="59", VALUE(MID(B21,11,2))>24), AND(LEFT(B21,4)="T521", VALUE(MID(B21,11,2))>62), LEFT(B21,4)="T523" ), "符合", "不符合") -> #VALUE! | AH21: =_xlfn.XLOOKUP(TRIM(CLEAN(B21))&"-"&TRIM(CLEAN(C21))&"-"&TRIM(CLEAN(D21)),'KS2'!A:A,'KS2'!B:B,0) -> 0 | AI21: =IF(_xlfn.XLOOKUP(MID(B21,2,7)&"/"&MID(B21,10,3)&TRIM(D21)&MID(B21,15,4),Carouselwash!F:F,Carouselwash!I:I,0)=0,_xlfn.XLOOKUP((MID(C21,2,7)&"/"&MID(C21,10,3)&TRIM(D21)),Carouselwash!G:G,Carouselwash!I:I,0),_xlfn.XLOOKUP(MID(B21,2,7)&"/"&MID(B21,10,3)&TRIM(D21)&MID(B21,15,4),Carouselwash!F:F,Carouselwash!I:I,0)) -> 3
A22: 2628JF67 | B22: T598D477M2R5ATE006 | C22: A598V247M004AS | D22: TTS80 | E22: 2026-07-28 | F22: 42300 | G22: 2026-08-01 | H22: 2026-09-06 | I22: T59D 2 | J22: 14 | K22: 9 | L22: R8TE28649191-021 | M22: 2672.7 | N22: NGZ | O22: 0.065 | P22: 0.17 | Q22: 0.04 | R22: 0.0193 | S22: 50 | T22: 47 | U22: 18 | V22: S59112SJ4 | W22: 32 | X22: 20932.16 | Y22: 42300 | Z22: ANODE-KO | AA22: ,pull in | AB22: 3882573997-QTY:27396 | AC22: 3882573996 | AD22: =IF(N22=$AD$1,_xlfn.XLOOKUP(LEFT(B22,18)&C22&D22,'Form CT'!I:I,'Form CT'!D:D,0)+_xlfn.XLOOKUP(LEFT(B22,18)&C22&D22,'Form CT'!I:I,'Form CT'!E:E,0),0) -> 0 | AE22: =IF(N22=$AE$1,_xlfn.XLOOKUP(LEFT(B22,18)&C22&D22,'Form CT'!I:I,'Form CT'!D:D,0)+_xlfn.XLOOKUP(LEFT(B22,18)&C22&D22,'Form CT'!I:I,'Form CT'!E:E,0),0) -> 0 | AF22: =IF(N22=$AF$1,_xlfn.XLOOKUP(LEFT(B22,18)&C22&D22,'Form CT'!I:I,'Form CT'!D:D,0)+_xlfn.XLOOKUP(LEFT(B22,18)&C22&D22,'Form CT'!I:I,'Form CT'!E:E,0),0) -> 349.29693 | AG22: =IF(OR( AND(MID(B22,2,2)="59", VALUE(MID(B22,11,2))>24), AND(LEFT(B22,4)="T521", VALUE(MID(B22,11,2))>62), LEFT(B22,4)="T523" ), "符合", "不符合") -> #VALUE! | AH22: =_xlfn.XLOOKUP(TRIM(CLEAN(B22))&"-"&TRIM(CLEAN(C22))&"-"&TRIM(CLEAN(D22)),'KS2'!A:A,'KS2'!B:B,0) -> 0 | AI22: =IF(_xlfn.XLOOKUP(MID(B22,2,7)&"/"&MID(B22,10,3)&TRIM(D22)&MID(B22,15,4),Carouselwash!F:F,Carouselwash!I:I,0)=0,_xlfn.XLOOKUP((MID(C22,2,7)&"/"&MID(C22,10,3)&TRIM(D22)),Carouselwash!G:G,Carouselwash!I:I,0),_xlfn.XLOOKUP(MID(B22,2,7)&"/"&MID(B22,10,3)&TRIM(D22)&MID(B22,15,4),Carouselwash!F:F,Carouselwash!I:I,0)) -> 3
A23: 2627KE47 | B23: T523W476M035APE1007723 | C23: A523W476M035ASE100 | D23: S706 | E23: 2026-07-28 | F23: 23400 | G23: 2026-07-27 | H23: 2026-08-26 | I23: T523W | J23: 3 | K23: 0 | L23: WCU245343183-026 | M23: 4520.3 | N23: Y | O23: 0.14 | P23: 0.21 | Q23: 0.032 | R23: 0.015 | S23: 50 | T23: 26 | U23: 18 | V23: D30123BP7 | W23: 32 | X23: 69156.48 | Y23: 23400 | Z23: ANODE-KO | AA23: fixed,pass due | AB23: 3882487204-QTY:16389,pass due | AC23: 3882487203 | AD23: =IF(N23=$AD$1,_xlfn.XLOOKUP(LEFT(B23,18)&C23&D23,'Form CT'!I:I,'Form CT'!D:D,0)+_xlfn.XLOOKUP(LEFT(B23,18)&C23&D23,'Form CT'!I:I,'Form CT'!E:E,0),0) -> 0 | AE23: =IF(N23=$AE$1,_xlfn.XLOOKUP(LEFT(B23,18)&C23&D23,'Form CT'!I:I,'Form CT'!D:D,0)+_xlfn.XLOOKUP(LEFT(B23,18)&C23&D23,'Form CT'!I:I,'Form CT'!E:E,0),0) -> 1148.7496 | AF23: =IF(N23=$AF$1,_xlfn.XLOOKUP(LEFT(B23,18)&C23&D23,'Form CT'!I:I,'Form CT'!D:D,0)+_xlfn.XLOOKUP(LEFT(B23,18)&C23&D23,'Form CT'!I:I,'Form CT'!E:E,0),0) -> 0 | AG23: =IF(OR( AND(MID(B23,2,2)="59", VALUE(MID(B23,11,2))>24), AND(LEFT(B23,4)="T521", VALUE(MID(B23,11,2))>62), LEFT(B23,4)="T523" ), "符合", "不符合") -> 符合 | AH23: =_xlfn.XLOOKUP(TRIM(CLEAN(B23))&"-"&TRIM(CLEAN(C23))&"-"&TRIM(CLEAN(D23)),'KS2'!A:A,'KS2'!B:B,0) -> 5 | AI23: =IF(_xlfn.XLOOKUP(MID(B23,2,7)&"/"&MID(B23,10,3)&TRIM(D23)&MID(B23,15,4),Carouselwash!F:F,Carouselwash!I:I,0)=0,_xlfn.XLOOKUP((MID(C23,2,7)&"/"&MID(C23,10,3)&TRIM(D23)),Carouselwash!G:G,Carouselwash!I:I,0),_xlfn.XLOOKUP(MID(B23,2,7)&"/"&MID(B23,10,3)&TRIM(D23)&MID(B23,15,4),Carouselwash!F:F,Carouselwash!I:I,0)) -> 4
A24: 2629K227 | B24: T523W476M035APE100 | C24: A523W476M035ASE100 | D24: S706 | E24: 2026-07-28 | F24: 23400 | G24: 2026-08-01 | H24: 2026-08-31 | I24: T523W | J24: 3 | K24: 0 | L24: WCU245343195-003 | M24: 4464.7 | N24: Y | O24: 0.14 | P24: 0.21 | Q24: 0.032 | R24: 0.015 | S24: 50 | T24: 26 | U24: 18 | V24: D30123BP7 | W24: 32 | X24: 68186.45 | Y24: 23400 | Z24: ANODE-KO | AA24: ,pull in | AB24: 3882488091-QTY:3561 | AC24: 3882488090 | AD24: =IF(N24=$AD$1,_xlfn.XLOOKUP(LEFT(B24,18)&C24&D24,'Form CT'!I:I,'Form CT'!D:D,0)+_xlfn.XLOOKUP(LEFT(B24,18)&C24&D24,'Form CT'!I:I,'Form CT'!E:E,0),0) -> 0 | AE24: =IF(N24=$AE$1,_xlfn.XLOOKUP(LEFT(B24,18)&C24&D24,'Form CT'!I:I,'Form CT'!D:D,0)+_xlfn.XLOOKUP(LEFT(B24,18)&C24&D24,'Form CT'!I:I,'Form CT'!E:E,0),0) -> 1148.7496 | AF24: =IF(N24=$AF$1,_xlfn.XLOOKUP(LEFT(B24,18)&C24&D24,'Form CT'!I:I,'Form CT'!D:D,0)+_xlfn.XLOOKUP(LEFT(B24,18)&C24&D24,'Form CT'!I:I,'Form CT'!E:E,0),0) -> 0 | AG24: =IF(OR( AND(MID(B24,2,2)="59", VALUE(MID(B24,11,2))>24), AND(LEFT(B24,4)="T521", VALUE(MID(B24,11,2))>62), LEFT(B24,4)="T523" ), "符合", "不符合") -> 符合 | AH24: =_xlfn.XLOOKUP(TRIM(CLEAN(B24))&"-"&TRIM(CLEAN(C24))&"-"&TRIM(CLEAN(D24)),'KS2'!A:A,'KS2'!B:B,0) -> 5 | AI24: =IF(_xlfn.XLOOKUP(MID(B24,2,7)&"/"&MID(B24,10,3)&TRIM(D24)&MID(B24,15,4),Carouselwash!F:F,Carouselwash!I:I,0)=0,_xlfn.XLOOKUP((MID(C24,2,7)&"/"&MID(C24,10,3)&TRIM(D24)),Carouselwash!G:G,Carouselwash!I:I,0),_xlfn.XLOOKUP(MID(B24,2,7)&"/"&MID(B24,10,3)&TRIM(D24)&MID(B24,15,4),Carouselwash!F:F,Carouselwash!I:I,0)) -> 4
A25: 2629DL27 | B25: T521D106M050ATE0907654 | C25: A521D106M050ASE060 | D25: FTP150 | E25: 2026-07-28 | F25: 16322 | G25: 2026-08-08 | H25: 2026-08-28 | I25: D | J25: 2 | K25: 0 | L25: WB4R16643195-005 | M25: 1697.8 | N25: Y | O25: 0.122 | P25: 0.18 | Q25: 0.056 | R25: 0.015 | S25: 35 | T25: 26 | U25: 18 | V25: X20104BP6 | W25: 32 | X25: 57063.87 | Y25: 16380 | Z25: Intransit | AA25: fixed,TopRunners,pull in | AC25: 3882464173 | AD25: =IF(N25=$AD$1,_xlfn.XLOOKUP(LEFT(B25,18)&C25&D25,'Form CT'!I:I,'Form CT'!D:D,0)+_xlfn.XLOOKUP(LEFT(B25,18)&C25&D25,'Form CT'!I:I,'Form CT'!E:E,0),0) -> 0 | AE25: =IF(N25=$AE$1,_xlfn.XLOOKUP(LEFT(B25,18)&C25&D25,'Form CT'!I:I,'Form CT'!D:D,0)+_xlfn.XLOOKUP(LEFT(B25,18)&C25&D25,'Form CT'!I:I,'Form CT'!E:E,0),0) -> 964.72306 | AF25: =IF(N25=$AF$1,_xlfn.XLOOKUP(LEFT(B25,18)&C25&D25,'Form CT'!I:I,'Form CT'!D:D,0)+_xlfn.XLOOKUP(LEFT(B25,18)&C25&D25,'Form CT'!I:I,'Form CT'!E:E,0),0) -> 0 | AG25: =IF(OR( AND(MID(B25,2,2)="59", VALUE(MID(B25,11,2))>24), AND(LEFT(B25,4)="T521", VALUE(MID(B25,11,2))>62), LEFT(B25,4)="T523" ), "符合", "不符合") -> 不符合 | AH25: =_xlfn.XLOOKUP(TRIM(CLEAN(B25))&"-"&TRIM(CLEAN(C25))&"-"&TRIM(CLEAN(D25)),'KS2'!A:A,'KS2'!B:B,0) -> 1 | AI25: =IF(_xlfn.XLOOKUP(MID(B25,2,7)&"/"&MID(B25,10,3)&TRIM(D25)&MID(B25,15,4),Carouselwash!F:F,Carouselwash!I:I,0)=0,_xlfn.XLOOKUP((MID(C25,2,7)&"/"&MID(C25,10,3)&TRIM(D25)),Carouselwash!G:G,Carouselwash!I:I,0),_xlfn.XLOOKUP(MID(B25,2,7)&"/"&MID(B25,10,3)&TRIM(D25)&MID(B25,15,4),Carouselwash!F:F,Carouselwash!I:I,0)) -> 2
A26: 2628PL37 | B26: T530D337M006ATE006 | C26: A530V117M006ASE006 | D26: KBP76 | E26: 2026-07-28 | F26: 42266 | G26: 2026-07-30 | H26: 2026-08-26 | I26: T530D 3 | J26: 14 | K26: 9 | L26: VK/S21943189-006 | M26: 2158.2 | N26: NGZ | O26: 0.07 | P26: 0.19 | Q26: 0.031 | R26: 0.015 | S26: 50 | T26: 47 | U26: 18 | V26: S59113 | W26: 32 | X26: 22695.61 | Y26: 42300 | Z26: ANODE-KO | AA26: ,pull in | AB26: 3882499346-QTY:17623 | AC26: 3882499345 | AD26: =IF(N26=$AD$1,_xlfn.XLOOKUP(LEFT(B26,18)&C26&D26,'Form CT'!I:I,'Form CT'!D:D,0)+_xlfn.XLOOKUP(LEFT(B26,18)&C26&D26,'Form CT'!I:I,'Form CT'!E:E,0),0) -> 0 | AE26: =IF(N26=$AE$1,_xlfn.XLOOKUP(LEFT(B26,18)&C26&D26,'Form CT'!I:I,'Form CT'!D:D,0)+_xlfn.XLOOKUP(LEFT(B26,18)&C26&D26,'Form CT'!I:I,'Form CT'!E:E,0),0) -> 0 | AF26: =IF(N26=$AF$1,_xlfn.XLOOKUP(LEFT(B26,18)&C26&D26,'Form CT'!I:I,'Form CT'!D:D,0)+_xlfn.XLOOKUP(LEFT(B26,18)&C26&D26,'Form CT'!I:I,'Form CT'!E:E,0),0) -> 360.52159 | AG26: =IF(OR( AND(MID(B26,2,2)="59", VALUE(MID(B26,11,2))>24), AND(LEFT(B26,4)="T521", VALUE(MID(B26,11,2))>62), LEFT(B26,4)="T523" ), "符合", "不符合") -> 不符合 | AH26: =_xlfn.XLOOKUP(TRIM(CLEAN(B26))&"-"&TRIM(CLEAN(C26))&"-"&TRIM(CLEAN(D26)),'KS2'!A:A,'KS2'!B:B,0) -> 0 | AI26: =IF(_xlfn.XLOOKUP(MID(B26,2,7)&"/"&MID(B26,10,3)&TRIM(D26)&MID(B26,15,4),Carouselwash!F:F,Carouselwash!I:I,0)=0,_xlfn.XLOOKUP((MID(C26,2,7)&"/"&MID(C26,10,3)&TRIM(D26)),Carouselwash!G:G,Carouselwash!I:I,0),_xlfn.XLOOKUP(MID(B26,2,7)&"/"&MID(B26,10,3)&TRIM(D26)&MID(B26,15,4),Carouselwash!F:F,Carouselwash!I:I,0)) -> 3
A27: 2625BT67 | B27: T521V107M020ATE055 | C27: A521V107M020ASMH01 | D27: KBP86 | E27: 2026-07-28 | F27: 33150 | G27: 2026-07-25 | H27: 2026-08-19 | I27: T59V | J27: 7 | K27: 4 | L27: XLKZ5344D170-046 | M27: 5530.2 | N27: P | O27: 0.128 | P27: 0.185 | Q27: 0.033 | R27: 0.0118 | S27: 50 | T27: 37 | U27: 18 | V27: S34153SXU2P | W27: 32 | X27: 35070.43 | Y27: 33300 | Z27: ANODE-KO | AA27: fixed,pass due,push out | AB27: 3882477147,3882477148-QTY:5346,pass due | AC27: 3882477146 | AD27: =IF(N27=$AD$1,_xlfn.XLOOKUP(LEFT(B27,18)&C27&D27,'Form CT'!I:I,'Form CT'!D:D,0)+_xlfn.XLOOKUP(LEFT(B27,18)&C27&D27,'Form CT'!I:I,'Form CT'!E:E,0),0) -> 581.43039 | AE27: =IF(N27=$AE$1,_xlfn.XLOOKUP(LEFT(B27,18)&C27&D27,'Form CT'!I:I,'Form CT'!D:D,0)+_xlfn.XLOOKUP(LEFT(B27,18)&C27&D27,'Form CT'!I:I,'Form CT'!E:E,0),0) -> 0 | AF27: =IF(N27=$AF$1,_xlfn.XLOOKUP(LEFT(B27,18)&C27&D27,'Form CT'!I:I,'Form CT'!D:D,0)+_xlfn.XLOOKUP(LEFT(B27,18)&C27&D27,'Form CT'!I:I,'Form CT'!E:E,0),0) -> 0 | AG27: =IF(OR( AND(MID(B27,2,2)="59", VALUE(MID(B27,11,2))>24), AND(LEFT(B27,4)="T521", VALUE(MID(B27,11,2))>62), LEFT(B27,4)="T523" ), "符合", "不符合") -> 不符合 | AH27: =_xlfn.XLOOKUP(TRIM(CLEAN(B27))&"-"&TRIM(CLEAN(C27))&"-"&TRIM(CLEAN(D27)),'KS2'!A:A,'KS2'!B:B,0) -> 0 | AI27: =IF(_xlfn.XLOOKUP(MID(B27,2,7)&"/"&MID(B27,10,3)&TRIM(D27)&MID(B27,15,4),Carouselwash!F:F,Carouselwash!I:I,0)=0,_xlfn.XLOOKUP((MID(C27,2,7)&"/"&MID(C27,10,3)&TRIM(D27)),Carouselwash!G:G,Carouselwash!I:I,0),_xlfn.XLOOKUP(MID(B27,2,7)&"/"&MID(B27,10,3)&TRIM(D27)&MID(B27,15,4),Carouselwash!F:F,Carouselwash!I:I,0)) -> 3
A28: 2628GZ37 | B28: T520Y477M006ATE010 | C28: A520V227M006ASMHSM | D28: KBP86 | E28: 2026-07-28 | F28: 43000 | G28: 2026-07-30 | H28: 2026-08-22 | I28: T530Y | J28: 8 | K28: 5 | L28: SWWN35843189-001 | M28: 3549.6 | N28: NGZ | O28: 0.098 | P28: 0.163 | Q28: 0.033 | R28: 0.015 | S28: 60 | T28: 42 | U28: 18 | V28: S35103SXU2P | W28: 32 | X28: 25484.15 | Y28: 45360 | Z28: ANODE-KO | AA28: ,pull in | AB28: 3882459479-QTY:27827 | AC28: 3882459478 | AD28: =IF(N28=$AD$1,_xlfn.XLOOKUP(LEFT(B28,18)&C28&D28,'Form CT'!I:I,'Form CT'!D:D,0)+_xlfn.XLOOKUP(LEFT(B28,18)&C28&D28,'Form CT'!I:I,'Form CT'!E:E,0),0) -> 0 | AE28: =IF(N28=$AE$1,_xlfn.XLOOKUP(LEFT(B28,18)&C28&D28,'Form CT'!I:I,'Form CT'!D:D,0)+_xlfn.XLOOKUP(LEFT(B28,18)&C28&D28,'Form CT'!I:I,'Form CT'!E:E,0),0) -> 0 | AF28: =IF(N28=$AF$1,_xlfn.XLOOKUP(LEFT(B28,18)&C28&D28,'Form CT'!I:I,'Form CT'!D:D,0)+_xlfn.XLOOKUP(LEFT(B28,18)&C28&D28,'Form CT'!I:I,'Form CT'!E:E,0),0) -> 452.42727 | AG28: =IF(OR( AND(MID(B28,2,2)="59", VALUE(MID(B28,11,2))>24), AND(LEFT(B28,4)="T521", VALUE(MID(B28,11,2))>62), LEFT(B28,4)="T523" ), "符合", "不符合") -> 不符合 | AH28: =_xlfn.XLOOKUP(TRIM(CLEAN(B28))&"-"&TRIM(CLEAN(C28))&"-"&TRIM(CLEAN(D28)),'KS2'!A:A,'KS2'!B:B,0) -> 0 | AI28: =IF(_xlfn.XLOOKUP(MID(B28,2,7)&"/"&MID(B28,10,3)&TRIM(D28)&MID(B28,15,4),Carouselwash!F:F,Carouselwash!I:I,0)=0,_xlfn.XLOOKUP((MID(C28,2,7)&"/"&MID(C28,10,3)&TRIM(D28)),Carouselwash!G:G,Carouselwash!I:I,0),_xlfn.XLOOKUP(MID(B28,2,7)&"/"&MID(B28,10,3)&TRIM(D28)&MID(B28,15,4),Carouselwash!F:F,Carouselwash!I:I,0)) -> 3
A29: 2628OW37 | B29: T523W476M035APE100 | C29: A523W476M035ASE100 | D29: S706 | E29: 2026-07-28 | F29: 23400 | G29: 2026-08-01 | H29: 2026-08-31 | I29: T523W | J29: 3 | K29: 0 | L29: WCU245343189-002 | M29: 4485.2 | N29: Y | O29: 0.14 | P29: 0.21 | Q29: 0.032 | R29: 0.015 | S29: 50 | T29: 26 | U29: 18 | V29: D30123BP7 | W29: 32 | X29: 68186.45 | Y29: 23400 | Z29: ANODE-KO | AA29: ,pull in | AB29: 3882488092-QTY:16595 | AC29: 3882488091 | AD29: =IF(N29=$AD$1,_xlfn.XLOOKUP(LEFT(B29,18)&C29&D29,'Form CT'!I:I,'Form CT'!D:D,0)+_xlfn.XLOOKUP(LEFT(B29,18)&C29&D29,'Form CT'!I:I,'Form CT'!E:E,0),0) -> 0 | AE29: =IF(N29=$AE$1,_xlfn.XLOOKUP(LEFT(B29,18)&C29&D29,'Form CT'!I:I,'Form CT'!D:D,0)+_xlfn.XLOOKUP(LEFT(B29,18)&C29&D29,'Form CT'!I:I,'Form CT'!E:E,0),0) -> 1148.7496 | AF29: =IF(N29=$AF$1,_xlfn.XLOOKUP(LEFT(B29,18)&C29&D29,'Form CT'!I:I,'Form CT'!D:D,0)+_xlfn.XLOOKUP(LEFT(B29,18)&C29&D29,'Form CT'!I:I,'Form CT'!E:E,0),0) -> 0 | AG29: =IF(OR( AND(MID(B29,2,2)="59", VALUE(MID(B29,11,2))>24), AND(LEFT(B29,4)="T521", VALUE(MID(B29,11,2))>62), LEFT(B29,4)="T523" ), "符合", "不符合") -> 符合 | AH29: =_xlfn.XLOOKUP(TRIM(CLEAN(B29))&"-"&TRIM(CLEAN(C29))&"-"&TRIM(CLEAN(D29)),'KS2'!A:A,'KS2'!B:B,0) -> 5 | AI29: =IF(_xlfn.XLOOKUP(MID(B29,2,7)&"/"&MID(B29,10,3)&TRIM(D29)&MID(B29,15,4),Carouselwash!F:F,Carouselwash!I:I,0)=0,_xlfn.XLOOKUP((MID(C29,2,7)&"/"&MID(C29,10,3)&TRIM(D29)),Carouselwash!G:G,Carouselwash!I:I,0),_xlfn.XLOOKUP(MID(B29,2,7)&"/"&MID(B29,10,3)&TRIM(D29)&MID(B29,15,4),Carouselwash!F:F,Carouselwash!I:I,0)) -> 4
A30: 2628BI27 | B30: T520B227M006ATE025 | C30: A520B227M006ASMHSP | D30: STA156KA | E30: 2026-07-28 | F30: 48679 | G30: 2026-08-04 | H30: 2026-08-23 | I30: B | J30: 10 | K30: 5 | L30: QMND2934D188-001 | M30: 2585 | N30: P | O30: 0.089 | P30: 0.064 | Q30: 0.041 | R30: 0.0118 | S30: 60 | T30: 47 | U30: 18 | V30: S55103XNU2P | W30: 42 | X30: 42929.6 | Y30: 50760 | Z30: ANODE-INSP | AA30: ,pull in | AB30: 3882425829-QTY:7385 | AC30: 3882425828 | AD30: =IF(N30=$AD$1,_xlfn.XLOOKUP(LEFT(B30,18)&C30&D30,'Form CT'!I:I,'Form CT'!D:D,0)+_xlfn.XLOOKUP(LEFT(B30,18)&C30&D30,'Form CT'!I:I,'Form CT'!E:E,0),0) -> 734.35044 | AE30: =IF(N30=$AE$1,_xlfn.XLOOKUP(LEFT(B30,18)&C30&D30,'Form CT'!I:I,'Form CT'!D:D,0)+_xlfn.XLOOKUP(LEFT(B30,18)&C30&D30,'Form CT'!I:I,'Form CT'!E:E,0),0) -> 0 | AF30: =IF(N30=$AF$1,_xlfn.XLOOKUP(LEFT(B30,18)&C30&D30,'Form CT'!I:I,'Form CT'!D:D,0)+_xlfn.XLOOKUP(LEFT(B30,18)&C30&D30,'Form CT'!I:I,'Form CT'!E:E,0),0) -> 0 | AG30: =IF(OR( AND(MID(B30,2,2)="59", VALUE(MID(B30,11,2))>24), AND(LEFT(B30,4)="T521", VALUE(MID(B30,11,2))>62), LEFT(B30,4)="T523" ), "符合", "不符合") -> 不符合 | AH30: =_xlfn.XLOOKUP(TRIM(CLEAN(B30))&"-"&TRIM(CLEAN(C30))&"-"&TRIM(CLEAN(D30)),'KS2'!A:A,'KS2'!B:B,0) -> 0 | AI30: =IF(_xlfn.XLOOKUP(MID(B30,2,7)&"/"&MID(B30,10,3)&TRIM(D30)&MID(B30,15,4),Carouselwash!F:F,Carouselwash!I:I,0)=0,_xlfn.XLOOKUP((MID(C30,2,7)&"/"&MID(C30,10,3)&TRIM(D30)),Carouselwash!G:G,Carouselwash!I:I,0),_xlfn.XLOOKUP(MID(B30,2,7)&"/"&MID(B30,10,3)&TRIM(D30)&MID(B30,15,4),Carouselwash!F:F,Carouselwash!I:I,0)) -> 3
