Workbook

Sheet Summary
B1: SIP | C1: Category | D1: 46200 | E1: =D1+1 -> 46201 | F1: =E1+1 -> 46202 | G1: =F1+1 -> 46203 | H1: =G1+1 -> 46204 | I1: =H1+1 -> 46205 | J1: =I1+1 -> 46206 | L1: =D1 -> 46200 | M1: =L1+1 -> 46201 | N1: =M1+1 -> 46202 | O1: =N1+1 -> 46203 | P1: =O1+1 -> 46204 | Q1: =P1+1 -> 46205 | R1: =Q1+1 -> 46206
A2: =B2*7 -> 4900 | B2: 700 | C2: B | D2: 700 | E2: 700 | F2: 700 | G2: 700 | H2: 700 | I2: 700 | J2: 700 | K2: =SUM(D2:J2) -> 4900 | L2: =IFERROR(_xlfn.XLOOKUP($C2,'[8]Key point'!$A:$A,'[8]Key point'!C:C,0),0) -> 708.687 | M2: =IFERROR(_xlfn.XLOOKUP($C2,'[8]Key point'!$A:$A,'[8]Key point'!D:D,0),0) -> 659.32 | N2: =IFERROR(_xlfn.XLOOKUP($C2,'[8]Key point'!$A:$A,'[8]Key point'!E:E,0),0) -> 759.895 | O2: =IFERROR(_xlfn.XLOOKUP($C2,'[8]Key point'!$A:$A,'[8]Key point'!F:F,0),0) -> 762.7 | P2: =IFERROR(_xlfn.XLOOKUP($C2,'[8]Key point'!$A:$A,'[8]Key point'!G:G,0),0) -> 662.946 | Q2: =IFERROR(_xlfn.XLOOKUP($C2,[9]Sheet1!$A:$A,[9]Sheet1!B:B,0)/1000,0) -> 709.71 | R2: =IFERROR(_xlfn.XLOOKUP($C2,[9]Sheet1!$A:$A,[9]Sheet1!C:C,0)/1000,0) -> 706.828 | S2: =SUM(L2:R2) -> 4970.086
A3: =B3*7 -> 2100 | B3: 300 | C3: T59B | D3: =_xlfn.XLOOKUP(C3,'[1]Weekly SIP'!$A:$A,'[1]Weekly SIP'!$N:$N,0) -> 300 | E3: 300 | F3: 300 | G3: 300 | H3: 300 | I3: 300 | J3: 300 | K3: =SUM(D3:J3) -> 2100 | L3: =IFERROR(_xlfn.XLOOKUP($C3,'[8]Key point'!$A:$A,'[8]Key point'!C:C,0),0) -> 300.845 | M3: =IFERROR(_xlfn.XLOOKUP($C3,'[8]Key point'!$A:$A,'[8]Key point'!D:D,0),0) -> 254.8 | N3: =IFERROR(_xlfn.XLOOKUP($C3,'[8]Key point'!$A:$A,'[8]Key point'!E:E,0),0) -> 356.721 | O3: =IFERROR(_xlfn.XLOOKUP($C3,'[8]Key point'!$A:$A,'[8]Key point'!F:F,0),0) -> 243.657 | P3: =IFERROR(_xlfn.XLOOKUP($C3,'[8]Key point'!$A:$A,'[8]Key point'!G:G,0),0) -> 354.468 | Q3: =IFERROR(_xlfn.XLOOKUP($C3,[9]Sheet1!$A:$A,[9]Sheet1!B:B,0)/1000,0) -> 304.818 | R3: =IFERROR(_xlfn.XLOOKUP($C3,[9]Sheet1!$A:$A,[9]Sheet1!C:C,0)/1000,0) -> 305.554 | S3: =SUM(L3:R3) -> 2120.863
A4: =B4*7 -> 0 | B4: 0 | C4: T528B | D4: =_xlfn.XLOOKUP(C4,'[1]Weekly SIP'!$A:$A,'[1]Weekly SIP'!$N:$N,0) -> 0 | E4: 0 | F4: 0 | G4: 0 | H4: 0 | I4: 0 | J4: 0 | K4: =SUM(D4:J4) -> 0 | L4: =IFERROR(_xlfn.XLOOKUP($C4,'[8]Key point'!$A:$A,'[8]Key point'!C:C,0),0) -> 0 | M4: =IFERROR(_xlfn.XLOOKUP($C4,'[8]Key point'!$A:$A,'[8]Key point'!D:D,0),0) -> 0 | N4: =IFERROR(_xlfn.XLOOKUP($C4,'[8]Key point'!$A:$A,'[8]Key point'!E:E,0),0) -> 0 | O4: =IFERROR(_xlfn.XLOOKUP($C4,'[8]Key point'!$A:$A,'[8]Key point'!F:F,0),0) -> 0 | P4: =IFERROR(_xlfn.XLOOKUP($C4,'[8]Key point'!$A:$A,'[8]Key point'!G:G,0),0) -> 0 | Q4: =IFERROR(_xlfn.XLOOKUP($C4,[9]Sheet1!$A:$A,[9]Sheet1!B:B,0)/1000,0) -> 0 | R4: =IFERROR(_xlfn.XLOOKUP($C4,[9]Sheet1!$A:$A,[9]Sheet1!C:C,0)/1000,0) -> 0 | S4: =SUM(L4:R4) -> 0
A5: =B5*7 -> 2800 | B5: 400 | C5: T | D5: 500 | E5: 500 | F5: 500 | G5: 350 | H5: 300 | I5: 300 | J5: 300 | K5: =SUM(D5:J5) -> 2750 | L5: =IFERROR(_xlfn.XLOOKUP($C5,'[8]Key point'!$A:$A,'[8]Key point'!C:C,0),0) -> 536.212 | M5: =IFERROR(_xlfn.XLOOKUP($C5,'[8]Key point'!$A:$A,'[8]Key point'!D:D,0),0) -> 473.028 | N5: =IFERROR(_xlfn.XLOOKUP($C5,'[8]Key point'!$A:$A,'[8]Key point'!E:E,0),0) -> 485.328 | O5: =IFERROR(_xlfn.XLOOKUP($C5,'[8]Key point'!$A:$A,'[8]Key point'!F:F,0),0) -> 355.572 | P5: =IFERROR(_xlfn.XLOOKUP($C5,'[8]Key point'!$A:$A,'[8]Key point'!G:G,0),0) -> 260.303 | Q5: =IFERROR(_xlfn.XLOOKUP($C5,[9]Sheet1!$A:$A,[9]Sheet1!B:B,0)/1000,0) -> 323.201 | R5: =IFERROR(_xlfn.XLOOKUP($C5,[9]Sheet1!$A:$A,[9]Sheet1!C:C,0)/1000,0) -> 269.885 | S5: =SUM(L5:R5) -> 2703.529
A6: =B6*7 -> 0 | B6: 0 | C6: Flat T | K6: =SUM(D6:J6) -> 0 | L6: =IFERROR(_xlfn.XLOOKUP($C6,'[8]Key point'!$A:$A,'[8]Key point'!C:C,0),0) -> 0 | M6: =IFERROR(_xlfn.XLOOKUP($C6,'[8]Key point'!$A:$A,'[8]Key point'!D:D,0),0) -> 0 | N6: =IFERROR(_xlfn.XLOOKUP($C6,'[8]Key point'!$A:$A,'[8]Key point'!E:E,0),0) -> 0 | O6: =IFERROR(_xlfn.XLOOKUP($C6,'[8]Key point'!$A:$A,'[8]Key point'!F:F,0),0) -> 0 | P6: =IFERROR(_xlfn.XLOOKUP($C6,'[8]Key point'!$A:$A,'[8]Key point'!G:G,0),0) -> 0 | Q6: =IFERROR(_xlfn.XLOOKUP($C6,[9]Sheet1!$A:$A,[9]Sheet1!B:B,0)/1000,0) -> 0 | R6: =IFERROR(_xlfn.XLOOKUP($C6,[9]Sheet1!$A:$A,[9]Sheet1!C:C,0)/1000,0) -> 0 | S6: =SUM(L6:R6) -> 0
A7: =B7*7 -> 7000 | B7: 1000 | C7: T-A42 | D7: 1000 | E7: 1000 | F7: 1000 | G7: 1000 | H7: 1000 | I7: 1000 | J7: 1000 | K7: =SUM(D7:J7) -> 7000 | L7: =IFERROR(_xlfn.XLOOKUP($C7,'[8]Key point'!$A:$A,'[8]Key point'!C:C,0),0) -> 1011.928 | M7: =IFERROR(_xlfn.XLOOKUP($C7,'[8]Key point'!$A:$A,'[8]Key point'!D:D,0),0) -> 1013.203 | N7: =IFERROR(_xlfn.XLOOKUP($C7,'[8]Key point'!$A:$A,'[8]Key point'!E:E,0),0) -> 1012.022 | O7: =IFERROR(_xlfn.XLOOKUP($C7,'[8]Key point'!$A:$A,'[8]Key point'!F:F,0),0) -> 1005.943 | P7: =IFERROR(_xlfn.XLOOKUP($C7,'[8]Key point'!$A:$A,'[8]Key point'!G:G,0),0) -> 1014.644 | Q7: =IFERROR(_xlfn.XLOOKUP($C7,[9]Sheet1!$A:$A,[9]Sheet1!B:B,0)/1000,0) -> 1014.154 | R7: =IFERROR(_xlfn.XLOOKUP($C7,[9]Sheet1!$A:$A,[9]Sheet1!C:C,0)/1000,0) -> 1014.102 | S7: =SUM(L7:R7) -> 7085.996
A8: =B8*7 -> 1050 | B8: 150 | C8: T-G | D8: =_xlfn.XLOOKUP(C8,'[1]Weekly SIP'!$A:$A,'[1]Weekly SIP'!$N:$N,0) -> 150 | E8: 150 | F8: 150 | G8: 150 | H8: 150 | I8: 150 | J8: 150 | K8: =SUM(D8:J8) -> 1050 | L8: =IFERROR(_xlfn.XLOOKUP($C8,'[8]Key point'!$A:$A,'[8]Key point'!C:C,0),0) -> 152.248 | M8: =IFERROR(_xlfn.XLOOKUP($C8,'[8]Key point'!$A:$A,'[8]Key point'!D:D,0),0) -> 152.164 | N8: =IFERROR(_xlfn.XLOOKUP($C8,'[8]Key point'!$A:$A,'[8]Key point'!E:E,0),0) -> 155.1 | O8: =IFERROR(_xlfn.XLOOKUP($C8,'[8]Key point'!$A:$A,'[8]Key point'!F:F,0),0) -> 157.92 | P8: =IFERROR(_xlfn.XLOOKUP($C8,'[8]Key point'!$A:$A,'[8]Key point'!G:G,0),0) -> 152.255 | Q8: =IFERROR(_xlfn.XLOOKUP($C8,[9]Sheet1!$A:$A,[9]Sheet1!B:B,0)/1000,0) -> 152.275 | R8: =IFERROR(_xlfn.XLOOKUP($C8,[9]Sheet1!$A:$A,[9]Sheet1!C:C,0)/1000,0) -> 152.056 | S8: =SUM(L8:R8) -> 1074.018
A9: =B9*7 -> 0 | B9: 0 | C9: T523T | D9: =_xlfn.XLOOKUP(C9,'[1]Weekly SIP'!$A:$A,'[1]Weekly SIP'!$N:$N,0) -> 0 | E9: 0 | F9: 0 | G9: 0 | H9: =_xlfn.XLOOKUP(C9,'[2]Weekly SIP'!$A:$A,'[2]Weekly SIP'!$N:$N,0) -> 0 | I9: 0 | J9: 0 | K9: =SUM(D9:J9) -> 0 | L9: =IFERROR(_xlfn.XLOOKUP($C9,'[8]Key point'!$A:$A,'[8]Key point'!C:C,0),0) -> 0 | M9: =IFERROR(_xlfn.XLOOKUP($C9,'[8]Key point'!$A:$A,'[8]Key point'!D:D,0),0) -> 0 | N9: =IFERROR(_xlfn.XLOOKUP($C9,'[8]Key point'!$A:$A,'[8]Key point'!E:E,0),0) -> 0 | O9: =IFERROR(_xlfn.XLOOKUP($C9,'[8]Key point'!$A:$A,'[8]Key point'!F:F,0),0) -> 0 | P9: =IFERROR(_xlfn.XLOOKUP($C9,'[8]Key point'!$A:$A,'[8]Key point'!G:G,0),0) -> 0 | Q9: =IFERROR(_xlfn.XLOOKUP($C9,[9]Sheet1!$A:$A,[9]Sheet1!B:B,0)/1000,0) -> 0 | R9: =IFERROR(_xlfn.XLOOKUP($C9,[9]Sheet1!$A:$A,[9]Sheet1!C:C,0)/1000,0) -> 0 | S9: =SUM(L9:R9) -> 0
A10: =B10*7 -> 0 | B10: 0 | C10: C | K10: =SUM(D10:J10) -> 0 | L10: =IFERROR(_xlfn.XLOOKUP($C10,'[8]Key point'!$A:$A,'[8]Key point'!C:C,0),0) -> 0 | M10: =IFERROR(_xlfn.XLOOKUP($C10,'[8]Key point'!$A:$A,'[8]Key point'!D:D,0),0) -> 0 | N10: =IFERROR(_xlfn.XLOOKUP($C10,'[8]Key point'!$A:$A,'[8]Key point'!E:E,0),0) -> 0 | O10: =IFERROR(_xlfn.XLOOKUP($C10,'[8]Key point'!$A:$A,'[8]Key point'!F:F,0),0) -> 0 | P10: =IFERROR(_xlfn.XLOOKUP($C10,'[8]Key point'!$A:$A,'[8]Key point'!G:G,0),0) -> 0 | Q10: =IFERROR(_xlfn.XLOOKUP($C10,[9]Sheet1!$A:$A,[9]Sheet1!B:B,0)/1000,0) -> 0 | R10: =IFERROR(_xlfn.XLOOKUP($C10,[9]Sheet1!$A:$A,[9]Sheet1!C:C,0)/1000,0) -> 0
A11: =B11*7 -> 6790 | B11: 970 | C11: D | D11: 860 | E11: 860 | F11: 860 | G11: 1010 | H11: 1060 | I11: 1060 | J11: 1060 | K11: =SUM(D11:J11) -> 6770 | L11: =IFERROR(_xlfn.XLOOKUP($C11,'[8]Key point'!$A:$A,'[8]Key point'!C:C,0),0) -> 888.988 | M11: =IFERROR(_xlfn.XLOOKUP($C11,'[8]Key point'!$A:$A,'[8]Key point'!D:D,0),0) -> 880.106 | N11: =IFERROR(_xlfn.XLOOKUP($C11,'[8]Key point'!$A:$A,'[8]Key point'!E:E,0),0) -> 819.414 | O11: =IFERROR(_xlfn.XLOOKUP($C11,'[8]Key point'!$A:$A,'[8]Key point'!F:F,0),0) -> 1033.196 | P11: =IFERROR(_xlfn.XLOOKUP($C11,'[8]Key point'!$A:$A,'[8]Key point'!G:G,0),0) -> 1005.693 | Q11: =IFERROR(_xlfn.XLOOKUP($C11,[9]Sheet1!$A:$A,[9]Sheet1!B:B,0)/1000,0) -> 1071.441 | R11: =IFERROR(_xlfn.XLOOKUP($C11,[9]Sheet1!$A:$A,[9]Sheet1!C:C,0)/1000,0) -> 1109.545 | S11: =SUM(L11:R11) -> 6808.383
A12: =B12*7 -> 560 | B12: 80 | C12: 1.9V | D12: =_xlfn.XLOOKUP(C12,'[3]Weekly SIP'!$A:$A,'[3]Weekly SIP'!$K:$K,0) -> 80 | E12: 80 | F12: 80 | G12: 80 | H12: 80 | I12: 80 | J12: 80 | K12: =SUM(D12:J12) -> 560 | L12: =IFERROR(_xlfn.XLOOKUP($C12,'[8]Key point'!$A:$A,'[8]Key point'!C:C,0),0) -> 33.6 | M12: =IFERROR(_xlfn.XLOOKUP($C12,'[8]Key point'!$A:$A,'[8]Key point'!D:D,0),0) -> 66.599 | N12: =IFERROR(_xlfn.XLOOKUP($C12,'[8]Key point'!$A:$A,'[8]Key point'!E:E,0),0) -> 99.332 | O12: =IFERROR(_xlfn.XLOOKUP($C12,'[8]Key point'!$A:$A,'[8]Key point'!F:F,0),0) -> 66.543 | P12: =IFERROR(_xlfn.XLOOKUP($C12,'[8]Key point'!$A:$A,'[8]Key point'!G:G,0),0) -> 98.919 | Q12: =IFERROR(_xlfn.XLOOKUP($C12,[9]Sheet1!$A:$A,[9]Sheet1!B:B,0)/1000,0) -> 65.875 | R12: =IFERROR(_xlfn.XLOOKUP($C12,[9]Sheet1!$A:$A,[9]Sheet1!C:C,0)/1000,0) -> 99.194 | S12: =SUM(L12:R12) -> 530.062
A13: =B13*7 -> 1050 | B13: 150 | C13: 2.0V | D13: =_xlfn.XLOOKUP(C13,'[3]Weekly SIP'!$A:$A,'[3]Weekly SIP'!$K:$K,0) -> 150 | E13: 150 | F13: 150 | G13: 150 | H13: 150 | I13: 150 | J13: 150 | K13: =SUM(D13:J13) -> 1050 | L13: =IFERROR(_xlfn.XLOOKUP($C13,'[8]Key point'!$A:$A,'[8]Key point'!C:C,0),0) -> 136.165 | M13: =IFERROR(_xlfn.XLOOKUP($C13,'[8]Key point'!$A:$A,'[8]Key point'!D:D,0),0) -> 135.748 | N13: =IFERROR(_xlfn.XLOOKUP($C13,'[8]Key point'!$A:$A,'[8]Key point'!E:E,0),0) -> 159.846 | O13: =IFERROR(_xlfn.XLOOKUP($C13,'[8]Key point'!$A:$A,'[8]Key point'!F:F,0),0) -> 136.3 | P13: =IFERROR(_xlfn.XLOOKUP($C13,'[8]Key point'!$A:$A,'[8]Key point'!G:G,0),0) -> 169.468 | Q13: =IFERROR(_xlfn.XLOOKUP($C13,[9]Sheet1!$A:$A,[9]Sheet1!B:B,0)/1000,0) -> 136.233 | R13: =IFERROR(_xlfn.XLOOKUP($C13,[9]Sheet1!$A:$A,[9]Sheet1!C:C,0)/1000,0) -> 181.128 | S13: =SUM(L13:R13) -> 1054.888
A14: =B14*7 -> 420 | B14: 60 | C14: W | D14: =_xlfn.XLOOKUP(C14,'[3]Weekly SIP'!$A:$A,'[3]Weekly SIP'!$K:$K,0) -> 60 | E14: 60 | F14: 60 | G14: 60 | H14: 60 | I14: 60 | J14: 60 | K14: =SUM(D14:J14) -> 420 | L14: =IFERROR(_xlfn.XLOOKUP($C14,'[8]Key point'!$A:$A,'[8]Key point'!C:C,0),0) -> 46.98 | M14: =IFERROR(_xlfn.XLOOKUP($C14,'[8]Key point'!$A:$A,'[8]Key point'!D:D,0),0) -> 70.833 | N14: =IFERROR(_xlfn.XLOOKUP($C14,'[8]Key point'!$A:$A,'[8]Key point'!E:E,0),0) -> 47.222 | O14: =IFERROR(_xlfn.XLOOKUP($C14,'[8]Key point'!$A:$A,'[8]Key point'!F:F,0),0) -> 70.829 | P14: =IFERROR(_xlfn.XLOOKUP($C14,'[8]Key point'!$A:$A,'[8]Key point'!G:G,0),0) -> 47.222 | Q14: =IFERROR(_xlfn.XLOOKUP($C14,[9]Sheet1!$A:$A,[9]Sheet1!B:B,0)/1000,0) -> 70.599 | R14: =IFERROR(_xlfn.XLOOKUP($C14,[9]Sheet1!$A:$A,[9]Sheet1!C:C,0)/1000,0) -> 44.011 | S14: =SUM(L14:R14) -> 397.696
A15: =B15*7 -> 210 | B15: 30 | C15: X | D15: =_xlfn.XLOOKUP(C15,'[3]Weekly SIP'!$A:$A,'[3]Weekly SIP'!$K:$K,0) -> 30 | E15: 30 | F15: 30 | G15: 30 | H15: 30 | I15: 30 | J15: 30 | K15: =SUM(D15:J15) -> 210 | L15: =IFERROR(_xlfn.XLOOKUP($C15,'[8]Key point'!$A:$A,'[8]Key point'!C:C,0),0) -> 33.6 | M15: =IFERROR(_xlfn.XLOOKUP($C15,'[8]Key point'!$A:$A,'[8]Key point'!D:D,0),0) -> 33.585 | N15: =IFERROR(_xlfn.XLOOKUP($C15,'[8]Key point'!$A:$A,'[8]Key point'!E:E,0),0) -> 33.6 | O15: =IFERROR(_xlfn.XLOOKUP($C15,'[8]Key point'!$A:$A,'[8]Key point'!F:F,0),0) -> 20.099 | P15: =IFERROR(_xlfn.XLOOKUP($C15,'[8]Key point'!$A:$A,'[8]Key point'!G:G,0),0) -> 100.779 | Q15: =IFERROR(_xlfn.XLOOKUP($C15,[9]Sheet1!$A:$A,[9]Sheet1!B:B,0)/1000,0) -> 0 | R15: =IFERROR(_xlfn.XLOOKUP($C15,[9]Sheet1!$A:$A,[9]Sheet1!C:C,0)/1000,0) -> 0 | S15: =SUM(L15:R15) -> 221.663
A16: =B16*7 -> 70 | B16: 10 | C16: Y | D16: =_xlfn.XLOOKUP(C16,'[3]Weekly SIP'!$A:$A,'[3]Weekly SIP'!$K:$K,0) -> 10 | E16: 10 | F16: 10 | G16: 30 | H16: 10 | I16: 10 | J16: 10 | K16: =SUM(D16:J16) -> 90 | L16: =IFERROR(_xlfn.XLOOKUP($C16,'[8]Key point'!$A:$A,'[8]Key point'!C:C,0),0) -> 33.6 | M16: =IFERROR(_xlfn.XLOOKUP($C16,'[8]Key point'!$A:$A,'[8]Key point'!D:D,0),0) -> 0 | N16: =IFERROR(_xlfn.XLOOKUP($C16,'[8]Key point'!$A:$A,'[8]Key point'!E:E,0),0) -> 0 | O16: =IFERROR(_xlfn.XLOOKUP($C16,'[8]Key point'!$A:$A,'[8]Key point'!F:F,0),0) -> 22.666 | P16: =IFERROR(_xlfn.XLOOKUP($C16,'[8]Key point'!$A:$A,'[8]Key point'!G:G,0),0) -> 0 | Q16: =IFERROR(_xlfn.XLOOKUP($C16,[9]Sheet1!$A:$A,[9]Sheet1!B:B,0)/1000,0) -> 0 | R16: =IFERROR(_xlfn.XLOOKUP($C16,[9]Sheet1!$A:$A,[9]Sheet1!C:C,0)/1000,0) -> 0 | S16: =SUM(L16:R16) -> 56.266
A17: =B17*7 -> 0 | B17: 0 | C17: T530D 2 | D17: =_xlfn.XLOOKUP(C17,'[3]Weekly SIP'!$A:$A,'[3]Weekly SIP'!$K:$K,0) -> 0 | E17: 0 | F17: 0 | G17: 0 | H17: 0 | I17: 0 | J17: 0 | K17: =SUM(D17:J17) -> 0 | L17: =IFERROR(_xlfn.XLOOKUP($C17,'[8]Key point'!$A:$A,'[8]Key point'!C:C,0),0) -> 0 | M17: =IFERROR(_xlfn.XLOOKUP($C17,'[8]Key point'!$A:$A,'[8]Key point'!D:D,0),0) -> 0 | N17: =IFERROR(_xlfn.XLOOKUP($C17,'[8]Key point'!$A:$A,'[8]Key point'!E:E,0),0) -> 0 | O17: =IFERROR(_xlfn.XLOOKUP($C17,'[8]Key point'!$A:$A,'[8]Key point'!F:F,0),0) -> 0 | P17: =IFERROR(_xlfn.XLOOKUP($C17,'[8]Key point'!$A:$A,'[8]Key point'!G:G,0),0) -> 0 | Q17: =IFERROR(_xlfn.XLOOKUP($C17,[9]Sheet1!$A:$A,[9]Sheet1!B:B,0)/1000,0) -> 0 | R17: =IFERROR(_xlfn.XLOOKUP($C17,[9]Sheet1!$A:$A,[9]Sheet1!C:C,0)/1000,0) -> 0 | S17: =SUM(L17:R17) -> 0
A18: =B18*7 -> 882 | B18: 126 | C18: T530D 3 | D18: =84*2 -> 168 | E18: =84*2 -> 168 | F18: =84*2 -> 168 | G18: 126 | H18: 84 | I18: 84 | J18: 84 | K18: =SUM(D18:J18) -> 882 | L18: =IFERROR(_xlfn.XLOOKUP($C18,'[8]Key point'!$A:$A,'[8]Key point'!C:C,0),0) -> 168.859 | M18: =IFERROR(_xlfn.XLOOKUP($C18,'[8]Key point'!$A:$A,'[8]Key point'!D:D,0),0) -> 169.332 | N18: =IFERROR(_xlfn.XLOOKUP($C18,'[8]Key point'!$A:$A,'[8]Key point'!E:E,0),0) -> 169.592 | O18: =IFERROR(_xlfn.XLOOKUP($C18,'[8]Key point'!$A:$A,'[8]Key point'!F:F,0),0) -> 126.855 | P18: =IFERROR(_xlfn.XLOOKUP($C18,'[8]Key point'!$A:$A,'[8]Key point'!G:G,0),0) -> 84.952 | Q18: =IFERROR(_xlfn.XLOOKUP($C18,[9]Sheet1!$A:$A,[9]Sheet1!B:B,0)/1000,0) -> 85.297 | R18: =IFERROR(_xlfn.XLOOKUP($C18,[9]Sheet1!$A:$A,[9]Sheet1!C:C,0)/1000,0) -> 85.262 | S18: =SUM(L18:R18) -> 890.149
A19: =B19*7 -> 2030 | B19: 290 | C19: T530X | D19: 290 | E19: 290 | F19: 290 | G19: 290 | H19: 290 | I19: 290 | J19: 290 | K19: =SUM(D19:J19) -> 2030 | L19: =IFERROR(_xlfn.XLOOKUP($C19,'[8]Key point'!$A:$A,'[8]Key point'!C:C,0),0) -> 266.223 | M19: =IFERROR(_xlfn.XLOOKUP($C19,'[8]Key point'!$A:$A,'[8]Key point'!D:D,0),0) -> 266.105 | N19: =IFERROR(_xlfn.XLOOKUP($C19,'[8]Key point'!$A:$A,'[8]Key point'!E:E,0),0) -> 266.173 | O19: =IFERROR(_xlfn.XLOOKUP($C19,'[8]Key point'!$A:$A,'[8]Key point'!F:F,0),0) -> 288.908 | P19: =IFERROR(_xlfn.XLOOKUP($C19,'[8]Key point'!$A:$A,'[8]Key point'!G:G,0),0) -> 266.933 | Q19: =IFERROR(_xlfn.XLOOKUP($C19,[9]Sheet1!$A:$A,[9]Sheet1!B:B,0)/1000,0) -> 233.258 | R19: =IFERROR(_xlfn.XLOOKUP($C19,[9]Sheet1!$A:$A,[9]Sheet1!C:C,0)/1000,0) -> 266.078 | S19: =SUM(L19:R19) -> 1853.678
A20: =B20*7 -> 350 | B20: 50 | C20: T521X | D20: =_xlfn.XLOOKUP(C20,'[3]Weekly SIP'!$A:$A,'[3]Weekly SIP'!$K:$K,0) -> 50 | E20: 50 | F20: 50 | G20: 50 | H20: 50 | I20: 50 | J20: 50 | K20: =SUM(D20:J20) -> 350 | L20: =IFERROR(_xlfn.XLOOKUP($C20,'[8]Key point'!$A:$A,'[8]Key point'!C:C,0),0) -> 60.619 | M20: =IFERROR(_xlfn.XLOOKUP($C20,'[8]Key point'!$A:$A,'[8]Key point'!D:D,0),0) -> 60.985 | N20: =IFERROR(_xlfn.XLOOKUP($C20,'[8]Key point'!$A:$A,'[8]Key point'!E:E,0),0) -> 61.014 | O20: =IFERROR(_xlfn.XLOOKUP($C20,'[8]Key point'!$A:$A,'[8]Key point'!F:F,0),0) -> 60.916 | P20: =IFERROR(_xlfn.XLOOKUP($C20,'[8]Key point'!$A:$A,'[8]Key point'!G:G,0),0) -> 53.641 | Q20: =IFERROR(_xlfn.XLOOKUP($C20,[9]Sheet1!$A:$A,[9]Sheet1!B:B,0)/1000,0) -> 106.178 | R20: =IFERROR(_xlfn.XLOOKUP($C20,[9]Sheet1!$A:$A,[9]Sheet1!C:C,0)/1000,0) -> 76.423 | S20: =SUM(L20:R20) -> 479.776
A21: =B21*7 -> 1330 | B21: 190 | C21: T530Y | D21: =_xlfn.XLOOKUP(C21,'[3]Weekly SIP'!$A:$A,'[3]Weekly SIP'!$K:$K,0) -> 190 | E21: 190 | F21: 190 | G21: 190 | H21: 190 | I21: 190 | J21: 190 | K21: =SUM(D21:J21) -> 1330 | L21: =IFERROR(_xlfn.XLOOKUP($C21,'[8]Key point'!$A:$A,'[8]Key point'!C:C,0),0) -> 199.553 | M21: =IFERROR(_xlfn.XLOOKUP($C21,'[8]Key point'!$A:$A,'[8]Key point'!D:D,0),0) -> 209.472 | N21: =IFERROR(_xlfn.XLOOKUP($C21,'[8]Key point'!$A:$A,'[8]Key point'!E:E,0),0) -> 204.703 | O21: =IFERROR(_xlfn.XLOOKUP($C21,'[8]Key point'!$A:$A,'[8]Key point'!F:F,0),0) -> 199.277 | P21: =IFERROR(_xlfn.XLOOKUP($C21,'[8]Key point'!$A:$A,'[8]Key point'!G:G,0),0) -> 193.044 | Q21: =IFERROR(_xlfn.XLOOKUP($C21,[9]Sheet1!$A:$A,[9]Sheet1!B:B,0)/1000,0) -> 199.011 | R21: =IFERROR(_xlfn.XLOOKUP($C21,[9]Sheet1!$A:$A,[9]Sheet1!C:C,0)/1000,0) -> 198.979 | S21: =SUM(L21:R21) -> 1404.039
A22: =B22*7 -> 4410 | B22: 630 | C22: T59D 2 | D22: 588 | E22: 588 | F22: 588 | G22: =588+42 -> 630 | H22: =84*8 -> 672 | I22: =84*8 -> 672 | J22: =84*8 -> 672 | K22: =SUM(D22:J22) -> 4410 | L22: =IFERROR(_xlfn.XLOOKUP($C22,'[8]Key point'!$A:$A,'[8]Key point'!C:C,0),0) -> 591.058 | M22: =IFERROR(_xlfn.XLOOKUP($C22,'[8]Key point'!$A:$A,'[8]Key point'!D:D,0),0) -> 591.354 | N22: =IFERROR(_xlfn.XLOOKUP($C22,'[8]Key point'!$A:$A,'[8]Key point'!E:E,0),0) -> 590.633 | O22: =IFERROR(_xlfn.XLOOKUP($C22,'[8]Key point'!$A:$A,'[8]Key point'!F:F,0),0) -> 631.413 | P22: =IFERROR(_xlfn.XLOOKUP($C22,'[8]Key point'!$A:$A,'[8]Key point'!G:G,0),0) -> 689.302 | Q22: =IFERROR(_xlfn.XLOOKUP($C22,[9]Sheet1!$A:$A,[9]Sheet1!B:B,0)/1000,0) -> 671.495 | R22: =IFERROR(_xlfn.XLOOKUP($C22,[9]Sheet1!$A:$A,[9]Sheet1!C:C,0)/1000,0) -> 671.942 | S22: =SUM(L22:R22) -> 4437.197
A23: =B23*7 -> 1400 | B23: 200 | C23: T59D 1 | D23: =_xlfn.XLOOKUP(C23,'[3]Weekly SIP'!$A:$A,'[3]Weekly SIP'!$K:$K,0) -> 200 | E23: 200 | F23: 200 | G23: 200 | H23: 200 | I23: 200 | J23: 200 | K23: =SUM(D23:J23) -> 1400 | L23: =IFERROR(_xlfn.XLOOKUP($C23,'[8]Key point'!$A:$A,'[8]Key point'!C:C,0),0) -> 204.092 | M23: =IFERROR(_xlfn.XLOOKUP($C23,'[8]Key point'!$A:$A,'[8]Key point'!D:D,0),0) -> 197.589 | N23: =IFERROR(_xlfn.XLOOKUP($C23,'[8]Key point'!$A:$A,'[8]Key point'!E:E,0),0) -> 194.321 | O23: =IFERROR(_xlfn.XLOOKUP($C23,'[8]Key point'!$A:$A,'[8]Key point'!F:F,0),0) -> 164.863 | P23: =IFERROR(_xlfn.XLOOKUP($C23,'[8]Key point'!$A:$A,'[8]Key point'!G:G,0),0) -> 191.98 | Q23: 100 | R23: =IFERROR(_xlfn.XLOOKUP($C23,[9]Sheet1!$A:$A,[9]Sheet1!C:C,0)/1000,0) -> 101.481 | S23: =SUM(L23:R23) -> 1154.326
A24: =B24*7 -> 3150 | B24: 450 | C24: T59V | D24: =_xlfn.XLOOKUP(C24,'[3]Weekly SIP'!$A:$A,'[3]Weekly SIP'!$K:$K,0) -> 450 | E24: 450 | F24: 450 | G24: 450 | H24: 450 | I24: 450 | J24: 450 | K24: =SUM(D24:J24) -> 3150 | L24: =IFERROR(_xlfn.XLOOKUP($C24,'[8]Key point'!$A:$A,'[8]Key point'!C:C,0),0) -> 432.97 | M24: =IFERROR(_xlfn.XLOOKUP($C24,'[8]Key point'!$A:$A,'[8]Key point'!D:D,0),0) -> 432.282 | N24: =IFERROR(_xlfn.XLOOKUP($C24,'[8]Key point'!$A:$A,'[8]Key point'!E:E,0),0) -> 432.198 | O24: =IFERROR(_xlfn.XLOOKUP($C24,'[8]Key point'!$A:$A,'[8]Key point'!F:F,0),0) -> 400.952 | P24: =IFERROR(_xlfn.XLOOKUP($C24,'[8]Key point'!$A:$A,'[8]Key point'!G:G,0),0) -> 432.178 | Q24: =IFERROR(_xlfn.XLOOKUP($C24,[9]Sheet1!$A:$A,[9]Sheet1!B:B,0)/1000,0) -> 439.327 | R24: =IFERROR(_xlfn.XLOOKUP($C24,[9]Sheet1!$A:$A,[9]Sheet1!C:C,0)/1000,0) -> 458.369 | S24: =SUM(L24:R24) -> 3028.276
A25: =B25*7 -> 0 | B25: 0 | C25: T528Z 1 | D25: =_xlfn.XLOOKUP(C25,'[3]Weekly SIP'!$A:$A,'[3]Weekly SIP'!$K:$K,0) -> 0 | E25: 0 | F25: 0 | G25: 0 | H25: 0 | I25: 0 | J25: 0 | K25: =SUM(D25:J25) -> 0 | L25: =IFERROR(_xlfn.XLOOKUP($C25,'[8]Key point'!$A:$A,'[8]Key point'!C:C,0),0) -> 0 | M25: =IFERROR(_xlfn.XLOOKUP($C25,'[8]Key point'!$A:$A,'[8]Key point'!D:D,0),0) -> 0 | N25: =IFERROR(_xlfn.XLOOKUP($C25,'[8]Key point'!$A:$A,'[8]Key point'!E:E,0),0) -> 0 | O25: =IFERROR(_xlfn.XLOOKUP($C25,'[8]Key point'!$A:$A,'[8]Key point'!F:F,0),0) -> 0 | P25: =IFERROR(_xlfn.XLOOKUP($C25,'[8]Key point'!$A:$A,'[8]Key point'!G:G,0),0) -> 0 | Q25: =IFERROR(_xlfn.XLOOKUP($C25,[9]Sheet1!$A:$A,[9]Sheet1!B:B,0)/1000,0) -> 0 | R25: =IFERROR(_xlfn.XLOOKUP($C25,[9]Sheet1!$A:$A,[9]Sheet1!C:C,0)/1000,0) -> 0
A26: =B26*7 -> 2254 | B26: 322 | C26: T523W | D26: =_xlfn.XLOOKUP(C26,'[3]Weekly SIP'!$A:$A,'[3]Weekly SIP'!$K:$K,0) -> 322 | E26: 322 | F26: 322 | G26: 322 | H26: 322 | I26: 322 | J26: 322 | K26: =SUM(D26:J26) -> 2254 | L26: =IFERROR(_xlfn.XLOOKUP($C26,'[8]Key point'!$A:$A,'[8]Key point'!C:C,0),0) -> 326.641 | M26: =IFERROR(_xlfn.XLOOKUP($C26,'[8]Key point'!$A:$A,'[8]Key point'!D:D,0),0) -> 327.053 | N26: =IFERROR(_xlfn.XLOOKUP($C26,'[8]Key point'!$A:$A,'[8]Key point'!E:E,0),0) -> 326.897 | O26: =IFERROR(_xlfn.XLOOKUP($C26,'[8]Key point'!$A:$A,'[8]Key point'!F:F,0),0) -> 325.352 | P26: =IFERROR(_xlfn.XLOOKUP($C26,'[8]Key point'!$A:$A,'[8]Key point'!G:G,0),0) -> 327.186 | Q26: =IFERROR(_xlfn.XLOOKUP($C26,[9]Sheet1!$A:$A,[9]Sheet1!B:B,0)/1000,0) -> 327.521 | R26: =IFERROR(_xlfn.XLOOKUP($C26,[9]Sheet1!$A:$A,[9]Sheet1!C:C,0)/1000,0) -> 327.264 | S26: =SUM(L26:R26) -> 2287.914
A27: =B27*7 -> 0 | B27: 0 | C27: T528Z 2 | D27: =_xlfn.XLOOKUP(C27,'[3]Weekly SIP'!$A:$A,'[3]Weekly SIP'!$K:$K,0) -> 0 | E27: 0 | F27: 0 | G27: 0 | H27: 0 | I27: 0 | J27: 0 | K27: =SUM(D27:J27) -> 0 | L27: =IFERROR(_xlfn.XLOOKUP($C27,'[8]Key point'!$A:$A,'[8]Key point'!C:C,0),0) -> 0 | M27: =IFERROR(_xlfn.XLOOKUP($C27,'[8]Key point'!$A:$A,'[8]Key point'!D:D,0),0) -> 0 | N27: =IFERROR(_xlfn.XLOOKUP($C27,'[8]Key point'!$A:$A,'[8]Key point'!E:E,0),0) -> 0 | O27: =IFERROR(_xlfn.XLOOKUP($C27,'[8]Key point'!$A:$A,'[8]Key point'!F:F,0),0) -> 0 | P27: =IFERROR(_xlfn.XLOOKUP($C27,'[8]Key point'!$A:$A,'[8]Key point'!G:G,0),0) -> 0 | Q27: =IFERROR(_xlfn.XLOOKUP($C27,[9]Sheet1!$A:$A,[9]Sheet1!B:B,0)/1000,0) -> 0 | R27: =IFERROR(_xlfn.XLOOKUP($C27,[9]Sheet1!$A:$A,[9]Sheet1!C:C,0)/1000,0) -> 0
A28: =B28*7 -> 560 | B28: 80 | C28: T523H | D28: =_xlfn.XLOOKUP(C28,'[3]Weekly SIP'!$A:$A,'[3]Weekly SIP'!$K:$K,0) -> 80 | E28: 80 | F28: 80 | G28: 80 | H28: 80 | I28: 80 | J28: 80 | K28: =SUM(D28:J28) -> 560 | L28: =IFERROR(_xlfn.XLOOKUP($C28,'[8]Key point'!$A:$A,'[8]Key point'!C:C,0),0) -> 98.821 | M28: =IFERROR(_xlfn.XLOOKUP($C28,'[8]Key point'!$A:$A,'[8]Key point'!D:D,0),0) -> 105.936 | N28: =IFERROR(_xlfn.XLOOKUP($C28,'[8]Key point'!$A:$A,'[8]Key point'!E:E,0),0) -> 84.019 | O28: =IFERROR(_xlfn.XLOOKUP($C28,'[8]Key point'!$A:$A,'[8]Key point'!F:F,0),0) -> 79.657 | P28: =IFERROR(_xlfn.XLOOKUP($C28,'[8]Key point'!$A:$A,'[8]Key point'!G:G,0),0) -> 80.021 | Q28: =IFERROR(_xlfn.XLOOKUP($C28,[9]Sheet1!$A:$A,[9]Sheet1!B:B,0)/1000,0) -> 62.75 | R28: =IFERROR(_xlfn.XLOOKUP($C28,[9]Sheet1!$A:$A,[9]Sheet1!C:C,0)/1000,0) -> 45.979 | S28: =SUM(L28:R28) -> 557.183
A29: 42UP | B29: =SUM(B2:B9) -> 2550 | C29: =SUM(C2:C8) -> 0 | D29: =SUM(D2:D10) -> 2650 | E29: =SUM(E2:E10) -> 2650 | F29: =SUM(F2:F10) -> 2650 | G29: =SUM(G2:G10) -> 2500 | H29: =SUM(H2:H10) -> 2450 | I29: =SUM(I2:I10) -> 2450 | J29: =SUM(J2:J10) -> 2450 | K29: =SUM(K2:K9) -> 17800 | L29: =SUM(L2:L10) -> 2709.92 | M29: =SUM(M2:M10) -> 2552.515 | N29: =SUM(N2:N10) -> 2769.066 | O29: =SUM(O2:O10) -> 2525.792 | P29: =SUM(P2:P10) -> 2444.616 | Q29: =SUM(Q2:Q10) -> 2504.158 | R29: =SUM(R2:R9) -> 2448.425 | S29: =SUM(L29:R29) -> 17954.492
A30: 32UP | B30: =SUM(B11:B28) -> 3638 | C30: =SUM(C11:C28) -> 0 | D30: =SUM(D11:D28) -> 3528 | E30: =SUM(E11:E28) -> 3528 | F30: =SUM(F11:F28) -> 3528 | G30: =SUM(G11:G28) -> 3698 | H30: =SUM(H11:H28) -> 3728 | I30: =SUM(I11:I28) -> 3728 | ... R30: =SUM(R11:R28) -> 3665.655 | S30: =SUM(L30:R30) -> 25161.496
A31: MTAS | B31: =SUM(B17:B22) -> 1286 | C31: =SUM(C17:C22) -> 0 | D31: =SUM(D17:D22) -> 1286 | E31: =SUM(E17:E22) -> 1286 | F31: =SUM(F17:F22) -> 1286 | G31: =SUM(G17:G22) -> 1286 | H31: =SUM(H17:H22) -> 1286 | I31: =SUM(I17:I22) -> 1286 | ... R31: =SUM(R17:R22) -> 1298.684 | S31: =SUM(L31:R31) -> 9064.839
A32: TOTAL | B32: =SUM(B30:B30) -> 3638 | C32: =SUM(C30:C30) -> 0 | D32: =SUM(D29:D30) -> 6178 | E32: =SUM(E29:E30) -> 6178 | F32: =SUM(F29:F30) -> 6178 | G32: =SUM(G29:G30) -> 6198 | H32: =SUM(H29:H30) -> 6178 | I32: =SUM(I29:I30) -> 6178 | J32: =SUM(J29:J30) -> 6178 | K32: =SUM(K29:K30) -> 43266 | ... R32: =SUM(R29:R30) -> 6114.08 | S32: =SUM(L32:R32) -> 43115.988
K33: 42UP GAP | L33: =L29-D29 -> 59.92 | M33: =M29-E29 -> -97.485 | N33: =N29-F29 -> 119.066 | O33: =O29-G29 -> 25.792 | P33: =P29-H29 -> -5.384 | Q33: =Q29-I29 -> 54.158 | R33: =R29-J29 -> -1.575 | S33: =AVERAGE(L33:R33) -> 22.070286
K34: 32UP GAP | L34: =L30-D30 -> -6.231 | M34: =M30-E30 -> 18.979 | N34: =N30-F30 -> -39.036 | O34: =O30-G30 -> -70.174 | P34: =P30-H30 -> 13.318 | Q34: =Q30-I30 -> -159.015 | R34: =R30-J30 -> -62.345 | S34: =AVERAGE(L34:R34) -> -43.500571
A35: Coif | B35: =19*90 -> 1710 | C35: D-Sigma | D35: 640 | E35: 640 | F35: 640 | G35: 640 | H35: 640 | I35: 640 | J35: 640
A36: SIGMA | B36: =B30-B35 -> 1928 | D36: =SUM(D35,D24,420,180)-40 -> 1650 | E36: =SUM(E35,E24,420,180)-40 -> 1650 | F36: =SUM(F35,F24,420,180)-40 -> 1650 | G36: =SUM(G35,G24,420,180)-40 -> 1650 | H36: =SUM(H35,H24,420,180)-40 -> 1650 | I36: =SUM(I35,I24,420,180)-40 -> 1650 | J36: =SUM(J35,J24,420,180)-40 -> 1650
A37: 32-Sigma (Actual) | B37: =3*210+2*200+100+2*210+100 -> 1650 | C37: # Coif | D37: =(D30-D36)/90 -> 20.866667 | E37: =(E30-E36)/90 -> 20.866667 | F37: =(F30-F36)/90 -> 20.866667 | G37: =(G30-G36)/90 -> 22.755556 | H37: =(H30-H36)/90 -> 23.088889 | I37: =(I30-I36)/90 -> 23.088889 | J37: =(J30-J36)/90 -> 23.088889
A38: Rest-Coif | B38: =B30-B37 -> 1988 | C38: T | D38: =SUM(D5:D9,100)/240 -> 7.2916667 | E38: =SUM(E5:E9)/240 -> 6.875 | F38: =SUM(F5:F9)/240 -> 6.875 | G38: =SUM(G5:G9)/240 -> 6.25 | H38: =SUM(H5:H9)/240 -> 6.0416667 | I38: =SUM(I5:I9)/240 -> 6.0416667 | J38: =SUM(J5:J9)/240 -> 6.0416667
B39: =(B30-B37)/19 -> 104.63158 | C39: B | D39: =SUM(D2:D3)/250 -> 4 | E39: =SUM(E2:E3)/250 -> 4 | F39: =SUM(F2:F3)/250 -> 4 | G39: =SUM(G2:G3)/250 -> 4 | H39: =SUM(H2:H3)/250 -> 4 | I39: =SUM(I2:I3)/250 -> 4 | J39: =SUM(J2:J3)/250 -> 4
C40: D | D40: =D35/210 -> 3.047619 | E40: =E35/210 -> 3.047619 | F40: =F35/210 -> 3.047619 | G40: =G35/210 -> 3.047619 | H40: =H35/210 -> 3.047619 | I40: =I35/210 -> 3.047619 | J40: =J35/210 -> 3.047619
...

Sheet 687
A1: 59D2 | B1: D | C1: 45975 | D1: 45976 | E1: 45977 | F1: 45978 | G1: 45979 | H1: 45980 | I1: 45981 | J1: 45982 | K1: 45983 | L1: 45984 | M1: 45985 | N1: 45986 | O1: 45987 | P1: 45988 | Q1: 45989 | R1: 45990 | S1: 45991 | T1: 45992 | U1: 45993 | V1: 45994 | W1: 45995 | X1: 45996 | Y1: 45997 | Z1: 45998 | AA1: 45999 | AB1: 46000 | AC1: 46001 | AD1: 46002 | AE1: 46003 | AF1: Status | AG1: 46018 | AH1: 46019 | AI1: 46020 | AJ1: 46021 | AK1: 46022 | AL1: 46023 | AM1: 46024 | AN1: 46025 | AO1: 46026 | AP1: 46027 | AQ1: 46028 | AR1: 46029 | AS1: 46030 | AT1: 46031 | AU1: 46032 | AV1: 46033 | AW1: 46034 | AX1: 46035 | AY1: 46036 | AZ1: 46037 | BA1: 46038 | BB1: 46039 | BC1: 46040 | BD1: 46041 | BE1: 46042 | BF1: 46043 | BG1: 46044 | BH1: 46045 | BI1: 46046 | BJ1: 46047 | BK1: 46048 | BL1: 46049 | BM1: 46050 | BN1: 46051 | BO1: 46052 | BP1: 46053 | BQ1: 46054 | BR1: 46055 | BS1: 46056 | BT1: 46057 | BU1: 46058 | BV1: 46059 | BW1: 46060 | BX1: 46061 | BY1: 46062 | BZ1: 46063 | CA1: 46064 | CB1: 46065 | CC1: 46066 | CD1: 46067 | CE1: 46068 | CF1: 46069 | CG1: 46070 | CH1: 46071 | CI1: 46072 | CJ1: 46073 | CK1: 46074 | CL1: 46075 | CM1: 46076 | CN1: 46077 | CO1: 46078 | CP1: 46079 | CQ1: 46080 | CR1: 46081 | CS1: 46082 | CT1: 46083 | CU1: 46084 | CV1: 46085 | CW1: 46086 | CX1: 46087 | CY1: 46088 | CZ1: 46089 | DA1: 46090 | DB1: 46091 | DC1: 46092 | DD1: 46093 | DE1: 46094 | DF1: 46095 | DG1: 46096 | DH1: 46097 | DI1: 46098 | DJ1: 46099 | DK1: 46100 | DL1: 46101 | DM1: 46102 | DN1: 46103 | DO1: 46104 | DP1: 46105 | DQ1: 46106 | DR1: 46107 | DS1: 46108 | DT1: 46109 | DU1: 46110 | DV1: 46111 | DW1: 46112 | DX1: 46113 | DY1: 46114 | DZ1: 46115 | EA1: 46116 | EB1: 46117 | EC1: 46118 | ED1: 46119 | EE1: 46120 | EF1: 46121 | EG1: 46122 | EH1: 46123 | EI1: 46124 | EJ1: 46125 | EK1: 46126 | EL1: 46127 | EM1: 46128 | EN1: 46129 | EO1: 46130 | EP1: 46131 | EQ1: 46132 | ER1: 46133 | ES1: 46134 | ET1: 46135 | EU1: 46136 | EV1: 46137 | EW1: 46138 | EX1: 46139 | EY1: 46140 | EZ1: 46141 | FA1: 46142 | FB1: 46143 | FC1: 46144 | FD1: 46145 | FE1: 46146 | FF1: 46147 | FG1: 46148 | FH1: 46149 | FI1: 46150 | FJ1: 46151 | FK1: 46152 | FL1: 46153 | FM1: 46154 | FN1: 46155 | FO1: 46156 | FP1: 46157 | FQ1: 46203 | FR1: 46204 | FS1: 46205 | FT1: 46206 | FU1: 46207 | FV1: 46208 | FW1: 46209 | FX1: 46210 | FY1: 46211 | FZ1: 46212 | GA1: 46213 | GB1: 46214 | GC1: 46215 | GD1: 46200 | GE1: 46201 | GF1: 46202 | GG1: 46203 | GH1: 46204 | GI1: 46205 | GJ1: 46206 | GK1: 46207 | GL1: 46208 | GM1: 46209 | GN1: 46210 | GO1: 46211 | GP1: 46212 | GQ1: 46213 | GR1: 46214
A2: T598D687M2R5ATE006 | F2: 2 | G2: 2 | H2: 2 | I2: 2 | J2: 2 | K2: 2 | L2: 2 | M2: 2 | N2: 2 | O2: 2 | P2: 2 | Q2: 2 | R2: 2 | S2: 2 | T2: 2 | U2: 2 | V2: 2 | W2: 2 | X2: 2 | Y2: 1 | AP2: 2 | AR2: 1 | AS2: 2 | AT2: 2 | AU2: 2 | AV2: 2 | AW2: 2 | AX2: 2 | AY2: 2 | AZ2: 2 | BA2: 2 | BP2: 2 | BQ2: 2 | BR2: 2 | BS2: 2 | BT2: 2 | BY2: 1 | BZ2: 2 | CA2: 2 | CB2: 1 | CX2: 2 | CY2: 4 | CZ2: 2 | DA2: 2 | DB2: 2 | DC2: 2 | DD2: 2 | DE2: 2 | DF2: 2 | DG2: 2 | DH2: 2 | DI2: 2 | DJ2: 2 | DK2: 2 | DL2: 2 | DM2: 4 | DN2: 4 | DO2: 2 | DP2: 2 | DQ2: 2 | DR2: 4 | DS2: 4 | DT2: 4 | DU2: 4 | DV2: 4 | DW2: 4 | DX2: 4 | DY2: 4 | DZ2: 4 | ED2: 10 | EE2: 10 | EF2: 10 | EG2: 10 | EH2: 6 | EI2: 6 | EJ2: 6 | EO2: 2 | EP2: 2 | EQ2: 2 | FJ2: 4 | FK2: 4 | FL2: 4 | FM2: 4 | FN2: 4 | FO2: 4 | FP2: 4 | FQ2: 4 | FR2: 4 | FS2: 4 | FT2: 4 | FU2: 4 | FV2: 4 | FW2: 4 | FX2: 4 | FY2: 4 | FZ2: 4 | GA2: 4 | GB2: 4 | GC2: 4 | GK2: 2 | GL2: 2 | GM2: 2 | GN2: 2 | GO2: 2 | GP2: 2
A3: QTY | K3: 60 批 12/27 orders 12days | BS3: =BS2*42 -> 84 | BT3: =BT2*42 -> 84 | BU3: =BU2*42 -> 0 | BV3: =BV2*42 -> 0 | BW3: =BW2*42 -> 0 | BX3: =BX2*42 -> 0 | BY3: =BY2*42 -> 42 | BZ3: =BZ2*42 -> 84 | ... CE3: =CE2*42 -> 0 | CU3: =CU2*42 -> 0 | CV3: =CV2*42 -> 0 | CW3: =CW2*42 -> 0 | CX3: =CX2*42 -> 84 | CY3: =CY2*42 -> 168 | CZ3: =CZ2*42 -> 84 | DA3: =DA2*42 -> 84 | DB3: =DB2*42 -> 84 | ... DS3: =DS2*42 -> 168 | DY3: =DY2*42 -> 168 | DZ3: =DZ2*42 -> 168 | EA3: =EA2*42 -> 0 | EB3: =EB2*42 -> 0 | EC3: =EC2*42 -> 0 | ED3: =ED2*42 -> 420 | EE3: =EE2*42 -> 420 | EF3: =EF2*42 -> 420 | ... EU3: =EU2*42 -> 0 | FJ3: =FJ2*42 -> 168 | FK3: =FK2*42 -> 168 | FL3: =FL2*42 -> 168 | FM3: =FM2*42 -> 168 | FN3: =FN2*42 -> 168 | FO3: =FO2*42 -> 168 | FP3: =FP2*42 -> 168 | FQ3: =FQ2*42 -> 168 | ... GR3: =GR2*42 -> 0
A4: Non-687 | G4: 6 | H4: 8 | I4: 8 | J4: 8 | K4: 8 | L4: 8 | M4: 8 | N4: 6 | O4: 6 | P4: 6 | Q4: 6
A5: T598D687M2R5ATE006 | G5: =G2*42 -> 84 | H5: =H2*42 -> 84 | I5: =I2*42 -> 84 | J5: =J2*42 -> 84 | K5: =K2*42 -> 84 | L5: =L2*42 -> 84 | M5: =M2*42 -> 84 | N5: =N2*42 -> 84 | ... Q5: =Q2*42 -> 84 | AS5: =AS2*42 -> 84 | AT5: =AT2*42 -> 84 | AU5: =AU2*42 -> 84 | AV5: =AV2*42 -> 84 | AW5: =AW2*42 -> 84 | AX5: =AX2*42 -> 84 | AY5: =AY2*42 -> 84 | AZ5: =AZ2*42 -> 84 | ... BL5: =BL2*42 -> 0
A6: Non-687 | G6: =G4*42 -> 252 | H6: =H4*42 -> 336 | I6: =I4*42 -> 336 | J6: =J4*42 -> 336 | K6: =K4*42 -> 336 | L6: =L4*42 -> 336 | M6: =M4*42 -> 336 | N6: =N4*42 -> 252 | ... Q6: =Q4*42 -> 252
A7: Total | G7: =SUM(G5:G6) -> 336 | H7: =SUM(H5:H6) -> 420 | I7: =SUM(I5:I6) -> 420 | J7: =SUM(J5:J6) -> 420 | K7: =SUM(K5:K6) -> 420 | L7: =SUM(L5:L6) -> 420 | M7: =SUM(M5:M6) -> 420 | N7: =SUM(N5:N6) -> 336 | ... Q7: =SUM(Q5:Q6) -> 336
A10: T530D687M2R5AHE006 | ER10: 1
C11: 45975 | D11: 45976 | E11: 45977 | F11: 45978 | G11: 45979 | H11: 45980 | I11: 45981 | J11: 45982 | K11: 45983 | L11: 45984 | M11: 45985 | N11: 45986 | O11: 45987 | P11: 45988 | Q11: 45989 | R11: 45990 | S11: 45991 | T11: 45992 | U11: 45993 | V11: 45994 | W11: 45995 | X11: 45996 | Y11: 45997 | Z11: 45998 | AA11: 45999 | AB11: 46000 | AC11: 46001 | AD11: 46002 | AE11: 46003 | AG11: 46018 | AH11: 46019 | AI11: 46020 | AJ11: 46021 | AK11: 46022 | AL11: 46023 | AM11: 46024 | AN11: 46025 | AO11: 46026 | AP11: 46027 | AQ11: 46028 | AR11: 46029 | AS11: 46030 | AT11: 46031 | AU11: 46032 | AV11: 46033 | AW11: 46034 | AX11: 46035 | AY11: 46036 | AZ11: 46037 | BA11: 46038 | BB11: 46039 | BC11: 46040 | BD11: 46041 | BE11: 46042 | BF11: 46043 | BG11: 46044 | BH11: 46045 | BI11: 46046 | BJ11: 46047 | BK11: 46048 | BL11: 46049 | BM11: 46050 | BN11: 46051 | BO11: 46052 | BP11: 46053 | BQ11: 46054 | BR11: 46055 | BS11: 46056 | BT11: 46057 | BU11: 46058 | BV11: 46059 | BW11: 46060 | BX11: 46061 | BY11: 46062 | BZ11: 46063 | CA11: 46064 | CB11: 46065 | CC11: 46066 | CD11: 46067 | CE11: 46068 | CF11: 46069 | CG11: 46070 | CH11: 46071 | CI11: 46072 | CJ11: 46073 | CK11: 46074 | CL11: 46075 | CM11: 46076 | CN11: 46077 | CO11: 46078 | CP11: 46079 | CQ11: 46080 | CR11: 46081 | CS11: 46082 | CT11: 46083 | CU11: 46084 | CV11: 46085 | CW11: 46086 | CX11: 46087 | CY11: 46088 | CZ11: 46089 | DA11: 46090 | DB11: 46091 | DC11: 46092 | DD11: 46093 | DE11: 46094 | DF11: 46095 | DG11: 46096 | DH11: 46097 | DI11: 46098 | DJ11: 46099 | DK11: 46100 | DL11: 46101 | DM11: 46102 | DN11: 46103 | DO11: 46104 | DP11: 46105 | DQ11: 46106 | DR11: 46107 | DS11: 46108 | DT11: 46109 | DU11: 46110 | DV11: 46111 | DW11: 46112 | DX11: 46113 | DY11: 46114 | DZ11: 46115 | EA11: 46116 | EB11: 46117 | EC11: 46118 | ED11: 46119 | EE11: 46120 | EF11: 46121 | EG11: 46122 | EH11: 46123 | EI11: 46124 | EJ11: 46125 | EK11: 46126 | EL11: 46127 | EM11: 46128 | EN11: 46129 | EO11: 46130 | EP11: 46131 | EQ11: 46132 | ER11: 46133 | ES11: 46134 | ET11: 46135 | EU11: 46136 | EV11: 46137 | EW11: 46138 | EX11: 46139 | EY11: 46140 | EZ11: 46141 | FA11: 46142 | FB11: 46143 | FC11: 46144 | FD11: 46145 | FE11: 46146 | FF11: 46147 | FG11: 46148 | FH11: 46149 | FI11: 46150 | FJ11: 46151 | FK11: 46152 | FL11: 46153 | FM11: 46154 | FN11: 46155 | FO11: 46156 | FP11: 46157 | FQ11: 46203 | FR11: 46204 | FS11: 46205 | FT11: 46206 | FU11: 46207 | FV11: 46208 | FW11: 46209 | FX11: 46210 | FY11: 46211 | FZ11: 46212 | GA11: 46213 | GB11: 46214 | GC11: 46215 | GD11: 46200 | GE11: 46201 | GF11: 46202 | GG11: 46203 | GH11: 46204 | GI11: 46205 | GJ11: 46206 | GK11: 46207 | GL11: 46208 | GM11: 46209 | GN11: 46210 | GO11: 46211 | GP11: 46212 | GQ11: 46213 | GR11: 46214
A12: 530D 2 | J12: 687 /21号之前需要39 12/15 orders | R12: K | W12: 12/4 9 12/28 orders
A13: T530D687M2R5ATE006 | B13: 6 | C13: 5 | G13: 8 | H13: 5 | I13: 6 | J13: 4 | K13: 4 | L13: 4 | M13: 4 | N13: 4 | O13: 4 | P13: 4 | Q13: 4 | R13: 1 | S13: 1 | T13: 1 | U13: 1 | V13: 1 | W13: 1 | X13: 1 | Y13: 1 | Z13: 2 | AA13: 2 | AB13: 3 | AC13: 3 | AD13: 4 | AE13: 4 | AN13: 1 | AO13: 2 | AQ13: 2 | AR13: 1 | AW13: 4 | AX13: 2 | AY13: 2 | AZ13: 2 | BA13: 2 | BB13: 4 | BC13: 4 | BD13: 4 | BE13: 4 | BF13: 3 | BG13: 2 | BH13: 2 | BI13: 2 | BJ13: 2 | BK13: 2 | BL13: 2 | BM13: 2 | BO13: 2 | BP13: 2 | BQ13: 2 | BR13: 2 | BS13: 2 | BT13: 2 | BU13: 2 | BV13: 2 | BW13: 2 | BX13: 2 | BY13: 1 | CB13: 1 | CD13: 2 | CE13: 2 | CF13: 2 | CG13: 2 | CH13: 2 | CI13: 2 | CP13: 2 | CQ13: 2 | CR13: 4 | CS13: 4 | CT13: 4 | CU13: 4 | CV13: 4 | CW13: 4 | CX13: 2 | CZ13: 2 | DA13: 2 | DB13: 2 | DC13: 2 | DE13: 2 | DF13: 2 | DG13: 2 | DH13: 2 | DL13: 2
A14: QTY | BS14: =BS13*42 -> 84 | BT14: =BT13*42 -> 84 | BU14: =BU13*42 -> 84 | BV14: =BV13*42 -> 84 | BW14: =BW13*42 -> 84 | BX14: =BX13*42 -> 84 | BY14: =BY13*42 -> 42 | BZ14: =BZ13*42 -> 0 | ... GT14: =GT13*42 -> 0
A15: T530D687M2R5ATE0067280 | Y15: 2 | Z15: 2 | AA15: 2 | AG15: 2 | AH15: 2 | AI15: 2 | AJ15: 4 | AK15: 4 | AL15: 4 | AM15: 2 | AN15: 1 | AX15: 2 | AY15: 2 | AZ15: 2 | BA15: 2 | BB15: 2 | BC15: 2 | BD15: 2 | BE15: 2 | BF15: 3 | BG15: 2 | BH15: 2 | BN15: 2 | BO15: 2 | CF15: 2 | CG15: 2 | CH15: 2 | CI15: 2 | CJ15: 4 | CK15: 4 | CL15: 4 | CM15: 4 | CN15: 2 | CO15: 2 | DK15: 2 | EM15: 1 | EN15: 2 | EO15: 2 | EP15: 2 | ER15: 1
A16: QTY | BS16: =BS15*42 -> 0 | BT16: =BT15*42 -> 0 | BU16: =BU15*42 -> 0 | BV16: =BV15*42 -> 0 | BW16: =BW15*42 -> 0 | BX16: =BX15*42 -> 0 | BY16: =BY15*42 -> 0 | BZ16: =BZ15*42 -> 0 | ... CE16: =CE15*42 -> 0 | CF16: =A2=CF15*42 -> FALSE | CG16: =CG15*42 -> 84 | CH16: =CH15*42 -> 84 | CI16: =CI15*42 -> 84 | CJ16: =CJ15*42 -> 168 | CK16: =CK15*42 -> 168 | CL16: =CL15*42 -> 168 | CM16: =CM15*42 -> 168 | CN16: =CN15*42 -> 84 | ... GT16: =GT15*42 -> 0
A17: T530D687M2R5ATE010 | EM17: 1
A18: QTY | EM18: =EM17*42 -> 42 | EN18: =EN17*42 -> 0 | EO18: =EO17*42 -> 0 | EP18: =EP17*42 -> 0 | EQ18: =EQ17*42 -> 0 | ER18: =ER17*42 -> 0 | ES18: =ES17*42 -> 0 | ET18: =ET17*42 -> 0 | ... GT18: =GT17*42 -> 0
A19: T530D687M2R5 | B19: =B13*42 -> 252 | C19: =C13*42 -> 210 | D19: =D13*42 -> 0 | E19: =E13*42 -> 0 | F19: =F13*42 -> 0 | G19: =G13*42 -> 336 | H19: =H13*42 -> 210 | I19: =I13*42 -> 252 | ... X19: =X13*42 -> 42 | Y19: =Y13*42+Y15*42 -> 126 | Z19: =Z13*42+Z15*42 -> 168 | AA19: =AA13*42+AA15*42 -> 168 | AB19: =AB13*42+AB15*42 -> 126 | AC19: =AC13*42+AC15*42 -> 126 | AD19: =AD13*42+AD15*42 -> 168 | AE19: =AE13*42+AE15*42 -> 168 | AG19: =AG13*42+AG15*42 -> 84 | AH19: =AH13*42+AH15*42 -> 84 | AI19: =AI13*42+AI15*42 -> 84 | AJ19: =AJ13*42+AJ15*42 -> 168 | AK19: =AK13*42+AK15*42 -> 168 | AL19: =AL13*42+AL15*42 -> 168 | AM19: =AM13*42+AM15*42 -> 84 | AN19: =AN13*42+AN15*42 -> 84 | ... BR19: =BR13*42+BR15*42 -> 84 | BS19: =SUM(BS14,BS16) -> 84 | BT19: =SUM(BT14,BT16) -> 84 | BU19: =SUM(BU14,BU16) -> 84 | BV19: =SUM(BV14,BV16) -> 84 | BW19: =SUM(BW14,BW16) -> 84 | BX19: =SUM(BX14,BX16) -> 84 | BY19: =SUM(BY14,BY16) -> 42 | BZ19: =SUM(BZ14,BZ16) -> 0 | ... EL19: =SUM(EL14,EL16) -> 0 | EM19: =SUM(EM14,EM16,EM18) -> 84 | EN19: =SUM(EN14,EN16,EN18) -> 84 | EO19: =SUM(EO14,EO16,EO18) -> 84 | EP19: =SUM(EP14,EP16,EP18) -> 84 | EQ19: =SUM(EQ14,EQ16,EQ18) -> 0 | ER19: =SUM(ER14,ER16,ER18) -> 42 | ES19: =SUM(ES14,ES16,ES18) -> 0 | ET19: =SUM(ET14,ET16,ET18) -> 0 | ... GT19: =SUM(GT14,GT16,GT18) -> 0
A20: T530D477M004ATE010 | D20: 4 | E20: 4 | F20: 4 | H20: 1 | J20: 2 | K20: 2 | L20: 2 | M20: 2 | N20: 4 | O20: 4 | P20: 4 | Q20: 4 | R20: 4 | S20: 4 | T20: 4 | U20: 4 | V20: 2 | W20: 4 | X20: 4 | AL20: 2 | AM20: 4 | AN20: 2 | AO20: 2 | AP20: 4 | AQ20: 2 | AR20: 3 | AS20: 4 | AT20: 4 | AU20: 4 | AV20: 4 | BI20: 2 | BJ20: 2 | BK20: 2 | BL20: 2 | BM20: 2 | BN20: 2 | BW20: 2 | BY20: 3 | BZ20: 4 | CA20: 4 | CB20: 3 | CC20: 4 | CD20: 2 | CE20: 2 | CN20: 1 | CY20: 2 | DD20: 2 | DI20: 2 | DJ20: 2 | EU20: 2
A21: QTY | BS21: =BS20*42 -> 0 | BT21: =BT20*42 -> 0 | BU21: =BU20*42 -> 0 | BV21: =BV20*42 -> 0 | BW21: =BW20*42 -> 84 | BX21: =BX20*42 -> 0 | BY21: =BY20*42 -> 126 | BZ21: =BZ20*42 -> 168 | ... GT21: =GT20*42 -> 0
A22: T530D687M003ATE010
A23: QTY | CR23: =CR22*42 -> 0 | CS23: =CS22*42 -> 0 | CT23: =CT22*42 -> 0 | CU23: =CU22*42 -> 0 | CV23: =CV22*42 -> 0 | CW23: =CW22*42 -> 0 | CX23: =CX22*42 -> 0 | CY23: =CY22*42 -> 0 | ... GT23: =GT22*42 -> 0
A24: T530D337M006ATE010 | R24: 0 | S24: 11/30 之前需要11批 | V24: 2 | W24: 12/4 22 批 | BX24: 2 | CO24: 2 | CP24: 2 | CQ24: 2 | EQ24: 2 | ES24: 2 | ET24: 2
A25: QTY | D25: =SUM(D20:D24) -> 4 | E25: =SUM(E20:E24) -> 4 | F25: =SUM(F20:F24) -> 4 | G25: =SUM(G20:G24) -> 0 | H25: =SUM(H20:H24) -> 1 | I25: =SUM(I20:I24) -> 0 | J25: =SUM(J20:J24) -> 2 | K25: =SUM(K20:K24) -> 2 | ... AE25: =SUM(AE20:AE24) -> 0 | BG25: 2 | BH25: 2 | BS25: =BS24*42 -> 0 | BT25: =BT24*42 -> 0 | BU25: =BU24*42 -> 0 | BV25: =BV24*42 -> 0 | BW25: =BW24*42 -> 0 | BX25: =BX24*42 -> 84 | BY25: =BY24*42 -> 0 | BZ25: =BZ24*42 -> 0 | ... GT25: =GT24*42 -> 0
A26: Non-687 | D26: =D25*42 -> 168 | E26: =E25*42 -> 168 | F26: =F25*42 -> 168 | G26: =G25*42 -> 0 | H26: =H25*42 -> 42 | I26: =I25*42 -> 0 | J26: =J25*42 -> 84 | K26: =K25*42 -> 84 | ... AE26: =AE25*42 -> 0 | AG26: =AG25*42 -> 0 | AH26: =AH25*42 -> 0 | AI26: =AI25*42 -> 0 | AJ26: =AJ25*42 -> 0 | AK26: =AK25*42 -> 0 | AL26: {=SUM(AL20:AL25*42)} -> 84 | AM26: {=SUM(AM20:AM25*42)} -> 168 | AN26: {=SUM(AN20:AN25*42)} -> 84 | AO26: {=SUM(AO20:AO25*42)} -> 84 | AP26: {=SUM(AP20:AP25*42)} -> 168 | AQ26: {=SUM(AQ20:AQ25*42)} -> 84 | AR26: {=SUM(AR20:AR25*42)} -> 126 | AS26: {=SUM(AS20:AS25*42)} -> 168 | ... BR26: {=SUM(BR20:BR25*42)} -> 0 | BS26: =SUM(BS21,BS25) -> 0 | BT26: =SUM(BT21,BT25) -> 0 | BU26: =SUM(BU21,BU25) -> 0 | BV26: =SUM(BV21,BV25) -> 0 | BW26: =SUM(BW21,BW25) -> 84 | BX26: =SUM(BX21,BX25) -> 84 | BY26: =SUM(BY21,BY25) -> 126 | BZ26: =SUM(BZ21,BZ25) -> 168 | ... GT26: =SUM(GT21,GT25) -> 0
A27: Total | D27: =SUM(D19:D26) -> 176 | E27: =SUM(E19:E26) -> 176 | F27: =SUM(F19:F26) -> 176 | G27: =SUM(G19:G26) -> 336 | H27: =SUM(H19:H26) -> 254 | I27: =SUM(I19:I26) -> 252 | J27: =SUM(J19:J26) -> 256 | K27: =SUM(K19:K26) -> 256 | ... AE27: =SUM(AE19:AE26) -> 168 | AG27: =SUM(AG19:AG26) -> 84 | AH27: =SUM(AH19:AH26) -> 84 | AI27: =SUM(AI19:AI26) -> 84 | AJ27: =SUM(AJ19:AJ26) -> 168 | AK27: =SUM(AK19:AK26) -> 168 | AL27: =SUM(AL19:AL26) -> 254 | AM27: =SUM(AM19:AM26) -> 256 | AN27: =SUM(AN19:AN26) -> 170 | ... BR27: =SUM(BR19:BR26) -> 84 | BS27: =SUM(BS19,BS26) -> 84 | BT27: =SUM(BT19,BT26) -> 84 | BU27: =SUM(BU19,BU26) -> 84 | BV27: =SUM(BV19,BV26) -> 84 | BW27: =SUM(BW19,BW26) -> 168 | BX27: =SUM(BX19,BX26) -> 168 | BY27: =SUM(BY19,BY26) -> 168 | BZ27: =SUM(BZ19,BZ26) -> 168 | ... GT27: =SUM(GT19,GT26) -> 0
AZ29: =AZ13*42 -> 84 | BA29: =BA13*42 -> 84 | BB29: =BB13*42 -> 168 | BC29: =BC13*42 -> 168 | BD29: =BD13*42 -> 168 | BE29: =BE13*42 -> 168 | BF29: =BF13*42 -> 126 | BG29: =BG13*42 -> 84 | ... BR29: =BR13*42 -> 84
AZ30: =AZ15*42 -> 84 | BA30: =BA15*42 -> 84 | BB30: =BB15*42 -> 84 | BC30: =BC15*42 -> 84 | BD30: =BD15*42 -> 84 | BE30: =BE15*42 -> 84 | BF30: =BF15*42 -> 126 | BG30: =BG15*42 -> 84 | ... BR30: =BR15*42 -> 0
AZ31: =AZ20*42 -> 0 | BA31: =BA20*42 -> 0 | BB31: =BB20*42 -> 0 | BC31: =BC20*42 -> 0 | BD31: =BD20*42 -> 0 | BE31: =BE20*42 -> 0 | BF31: =BF20*42 -> 0 | BG31: =BG20*42 -> 0 | ... BR31: =BR20*42 -> 0

Sheet D
A1: D | B1: 45983 | C1: 45984 | D1: 45985 | E1: 45986 | F1: 45987 | G1: 45988 | H1: 45989 | I1: 45990 | J1: 45991 | K1: 45992 | L1: 45993 | M1: 45994 | N1: 45995 | O1: 45996 | P1: 45997 | Q1: 45998 | R1: 45999 | S1: 46000 | T1: 46001 | U1: 46002 | V1: 46003 | W1: 46004 | X1: 46005 | Y1: 46006 | Z1: 46007 | AA1: 46008 | AB1: 46009 | AC1: 46010 | AD1: 46011 | AE1: 46012 | AG1: 46018 | AH1: 46019 | AI1: 46020 | AJ1: 46021 | AK1: 46022 | AL1: 46023 | AM1: 46024 | AN1: 46025 | AO1: 46026 | AP1: 46027 | AQ1: 46028 | AR1: 46029 | AS1: 46030 | AT1: 46031 | AU1: 46032 | AV1: 46033 | AW1: 46034 | AX1: 46035 | AY1: 46036 | AZ1: 46037 | BA1: 46038 | BB1: 46039 | BC1: 46040 | BD1: 46041 | BE1: 46042 | BF1: 46043 | BG1: 46044 | BH1: 46045 | BI1: 46046 | BJ1: 46047 | BK1: 46048 | BL1: 46049 | BM1: 46050 | BN1: 46051 | BO1: 46052 | BP1: 46053 | BQ1: 46054 | BR1: 46055 | BS1: 46056 | BT1: 46057 | BU1: 46058 | BV1: 46059 | BW1: 46060 | BX1: 46061 | BY1: 46062 | BZ1: 46063 | CA1: 46064 | CB1: 46065 | CC1: 46066 | CD1: 46067 | CE1: 46068 | CF1: 46069 | CG1: 46070 | CH1: 46071 | CI1: 46072 | CJ1: 46073 | CK1: 46074 | CL1: 46075 | CM1: 46076 | CN1: 46077 | CO1: 46078 | CP1: 46079 | CQ1: 46080 | CR1: 46081 | CS1: 46082 | CT1: 46083 | CU1: 46084 | CV1: 46085 | CW1: 46086 | CX1: 46087 | CY1: 46088 | CZ1: 46089 | DA1: 46090 | DB1: 46091 | DC1: 46092 | DD1: 46093 | DE1: 46094 | DF1: 46095 | DG1: 46096 | DH1: 46097 | DI1: 46098 | DJ1: 46099 | DK1: 46100 | DL1: 46101 | DM1: 46102 | DN1: 46103 | DO1: 46104 | DP1: 46105 | DQ1: 46106 | DR1: 46107 | DS1: 46108 | DT1: 46109 | DU1: 46110 | DV1: 46111 | DW1: 46112 | DX1: 46113 | DY1: 46114 | DZ1: 46115 | EA1: 46116 | EB1: 46117 | EC1: 46118 | ED1: 46119 | EE1: 46120 | EF1: 46121 | EG1: 46122 | EH1: 46123 | EI1: 46124 | EJ1: 46125 | EK1: 46126 | EL1: 46127 | EM1: 46128 | EN1: 46129 | EO1: 46130 | EP1: 46131 | EQ1: 46132 | ER1: 46133 | ES1: 46134 | ET1: 46135 | EU1: 46136 | EV1: 46137 | EW1: 46138 | EX1: 46139 | EY1: 46140 | EZ1: 46141 | FA1: 46142 | FB1: 46143 | FC1: 46144 | FD1: 46145 | FE1: 46146 | FF1: 46147 | FG1: 46148 | FH1: 46149 | FI1: 46150 | FJ1: 46151 | FK1: 46152 | FL1: 46153 | FM1: 46154 | FN1: 46155 | FO1: 46156 | FP1: 46157 | FQ1: 46158 | FR1: 46159 | FS1: 46160 | FT1: 46161 | FU1: 46162 | FV1: 46163 | FW1: 46164 | FX1: 46165 | FY1: 46166 | FZ1: 46167 | GA1: 46168 | GB1: 46169 | GC1: 46170 | GD1: 46171 | GE1: 46172 | GF1: 46173 | GG1: 46174 | GH1: 46175 | GI1: 46176 | GJ1: 46177 | GK1: 46178 | GL1: 46179 | GM1: 46180 | GN1: 46181 | GO1: 46182 | GP1: 46183 | GQ1: 46184 | GR1: 46185 | GS1: 46186 | GT1: 46187 | GU1: 46188 | GV1: 46189 | GW1: 46190 | GX1: 46191 | GY1: 46192 | GZ1: 46193 | HA1: 46194 | HB1: 46195 | HC1: 46196 | HD1: 46197 | HE1: 46198 | HF1: 46199 | HG1: 46200 | HH1: 46201 | HI1: 46202 | HJ1: 46203 | HK1: 46204 | HL1: 46205 | HM1: 46206 | HN1: 46207 | HO1: 46208 | HP1: 46209 | HQ1: 46210 | HR1: 46211 | HS1: 46212 | HT1: 46213 | HU1: 46214 | HV1: 46215 | HW1: 46216 | HX1: 46217 | HY1: 46218 | HZ1: 46219 | IA1: 46220 | IB1: 46221 | IC1: 46222
A2: 2.0V | C2: =4*45 -> 180 | D2: =45*3 -> 135
A4: T521D106M050ATE0907654 | B4: 5 | C4: 5 | D4: 5 | E4: 6 | F4: 6 | G4: 6 | H4: 6 | I4: 7 | J4: 7 | K4: 7 | L4: 7 | M4: 7 | N4: 7 | O4: 7 | P4: 9 | Q4: 9 | R4: 8 | S4: 8 | T4: 8 | U4: 5 | V4: 3 | W4: 15 | X4: 15 | Y4: 15 | Z4: 9 | AA4: 9 | AB4: 9 | AC4: 9 | AD4: 3 | AE4: 3 | AG4: 4 | AH4: 4 | AI4: 4 | AJ4: 4 | AK4: 4 | AL4: 2 | AM4: 2 | AN4: 2 | AO4: 2 | AP4: 2 | AQ4: 7 | AR4: 7 | AS4: 8 | AT4: 8 | AU4: 5 | AV4: 5 | AW4: 5 | AX4: 7 | AY4: 6 | AZ4: 6 | BA4: 6 | BB4: 7 | BC4: 7 | BD4: 7 | BE4: 7 | BF4: 7 | BG4: 7 | BH4: 7 | BI4: 5 | BJ4: 5 | BK4: 5 | BL4: 6 | BM4: 6 | BN4: 11 | BO4: 13 | BP4: 19 | BQ4: 19 | BR4: 19 | BS4: 10 | BT4: 8 | BU4: 7 | BV4: 7 | BW4: 4 | BX4: 4 | CB4: 3 | CC4: 3 | CD4: 4 | CE4: 4 | CF4: 4 | CG4: 4 | CH4: 4 | CI4: 4 | CJ4: 4 | CK4: 4 | CL4: 4 | CM4: 4 | CN4: 4 | CO4: 4 | CP4: 4 | CQ4: 4 | CR4: 4 | CS4: 4 | CT4: 4 | CU4: 4 | CV4: 4 | CW4: 4 | CX4: 4 | CY4: 4 | CZ4: 4 | DA4: 4 | DB4: 4 | DC4: 4 | DD4: 4 | DE4: 4 | DF4: 3 | DG4: 3 | DH4: 3 | DI4: 3 | DJ4: 3 | DK4: 3 | DL4: 3 | DT4: 2 | DU4: 2 | DV4: 2 | DW4: 2 | DX4: 2 | DY4: 4 | DZ4: 4 | ED4: 2 | EE4: 2 | EF4: 2 | EG4: 2 | EV4: 2 | EW4: 2 | EX4: 2 | EY4: 2 | EZ4: 2 | FA4: 2 | FB4: 2 | FC4: 2 | FD4: 2 | FE4: 2 | FF4: 2 | FG4: 2 | FH4: 2 | FI4: 2 | FJ4: 4 | FK4: 4 | FL4: 4 | FM4: 4 | FN4: 4 | FO4: 4 | FP4: 4 | FQ4: 3 | FR4: 3 | FS4: 3 | FT4: 3 | FU4: 3 | FV4: 3 | FW4: 3 | FX4: 3 | FY4: 3 | FZ4: 3 | GA4: 3 | GB4: 3 | GC4: 3 | GD4: 3 | GE4: 2 | GF4: 2 | GG4: 2 | GH4: 2 | GI4: 2 | GJ4: 2 | GK4: 2 | GN4: 3 | GO4: 3 | GP4: 3 | GQ4: 3 | GR4: 3 | GS4: 2 | GT4: 2 | GU4: 2 | GV4: 2 | GW4: 2 | GX4: 3 | GY4: 3 | GZ4: 4 | HA4: 4 | HB4: 4 | HC4: 4 | HD4: 4 | HE4: 3 | HF4: 3 | HG4: 4 | HH4: 4 | HI4: 4 | HJ4: 4 | HK4: 4 | HL4: 4 | HM4: 4 | HN4: 4 | HO4: 4 | HP4: 4 | HQ4: 4 | HR4: 4 | HS4: 4 | HT4: 4 | HU4: 4 | HV4: 4 | HW4: 3 | HX4: 3 | HY4: 3 | HZ4: 3 | IA4: 3 | IB4: 3 | IC4: 3
A5: QTY | B5: =16380*B4/1000 -> 81.9 | C5: =16380*C4/1000 -> 81.9 | D5: =16380*D4/1000 -> 81.9 | E5: =16380*E4/1000 -> 98.28 | F5: =16380*F4/1000 -> 98.28 | G5: =16380*G4/1000 -> 98.28 | H5: =16380*H4/1000 -> 98.28 | I5: 114.66 | J5: 114.66 | K5: 114.66 | L5: 114.66 | M5: 114.66 | N5: 114.66 | O5: 114.66 | P5: =16380*P4/1000 -> 147.42 | Q5: =16380*Q4/1000 -> 147.42 | R5: =16380*R4/1000 -> 131.04 | S5: =16380*S4/1000 -> 131.04 | T5: =16380*T4/1000 -> 131.04 | U5: =16380*U4/1000 -> 81.9 | V5: =16380*V4/1000 -> 49.14 | W5: =16380*W4/1000 -> 245.7 | ... AE5: =16380*AE4/1000 -> 49.14 | AG5: =16380*AG4/1000 -> 65.52 | AH5: =16380*AH4/1000 -> 65.52 | AI5: =16380*AI4/1000 -> 65.52 | AJ5: =16380*AJ4/1000 -> 65.52 | AK5: =16380*AK4/1000 -> 65.52 | AL5: =16380*AL4/1000 -> 32.76 | AM5: =16380*AM4/1000 -> 32.76 | AN5: =16380*AN4/1000 -> 32.76 | ... IC5: =16380*IC4/1000 -> 49.14
A6: T521D107M025ATE040 | S6: 4 | U6: 1 | V6: 1 | W6: 2 | X6: 2 | Y6: 2 | Z6: 2 | AA6: 2 | AB6: 2 | AC6: 2 | AD6: 2 | AE6: 2 | AG6: 2 | AH6: 2 | AI6: 2 | AJ6: 2 | AK6: 2 | AL6: 4 | AM6: 3 | AN6: 3 | AO6: 3 | AP6: 3 | BP6: 2 | BQ6: 2 | BR6: 2 | BS6: 2 | BT6: 2 | BU6: 2 | BV6: 2 | BW6: 10 | BX6: 10 | BY6: 10 | BZ6: 10 | CA6: 10 | CB6: 7 | CC6: 7 | CD6: 7 | CE6: 7 | CY6: 3 | CZ6: 3 | DA6: 3 | DB6: 5 | DC6: 4 | DD6: 4 | DE6: 4 | DF6: 8 | DG6: 8 | DH6: 8 | DI6: 8 | DJ6: 8 | DK6: 8 | DL6: 8 | DM6: 6 | DN6: 6 | DO6: 6 | DP6: 6 | DQ6: 6 | DR6: 6 | DS6: 6 | DT6: 8 | DU6: 8 | DV6: 8 | DW6: 8 | DX6: 8 | DY6: 8 | DZ6: 8 | ED6: 8 | EE6: 8 | EF6: 8 | EG6: 8 | EO6: 9 | EP6: 9 | EQ6: 9 | ER6: 9 | ES6: 9 | ET6: 9 | EU6: 9 | EV6: 14 | EW6: 14 | EX6: 14 | EY6: 14 | EZ6: 14 | FA6: 14 | FB6: 14 | FC6: 14 | FD6: 14 | FE6: 15 | FF6: 16 | FG6: 17 | FH6: 18 | FI6: 19 | FJ6: 5 | FK6: 5 | FL6: 5 | FM6: 5 | FN6: 5 | FO6: 5 | FP6: 5 | FQ6: 5 | FR6: 5 | FS6: 5 | FT6: 5 | FU6: 5 | FV6: 5 | FW6: 5 | FX6: 3 | FY6: 3 | FZ6: 3 | GA6: 3 | GB6: 3 | GC6: 3 | GD6: 3 | GE6: 3 | GF6: 3 | GG6: 3 | GH6: 3 | GI6: 3 | GJ6: 3 | GK6: 3 | GL6: 4 | GM6: 4 | GN6: 4 | GO6: 3 | GP6: 1 | GS6: 2 | GT6: 2 | GU6: 2 | GV6: 2 | GW6: 2 | GX6: 2 | GY6: 2 | GZ6: 2 | HA6: 2 | HB6: 2 | HC6: 2 | HD6: 2 | HE6: 2 | HF6: 1 | HG6: 1 | HP6: 3 | HQ6: 4 | HR6: 3 | HS6: 2 | HT6: 2 | HU6: 2 | HV6: 2 | HW6: 2 | HX6: 2 | HY6: 2 | HZ6: 2 | IA6: 2 | IB6: 2 | IC6: 2
A7: QTY | BP7: =BP6*28.8 -> 57.6 | BQ7: =BQ6*28.8 -> 57.6 | BR7: =BR6*28.8 -> 57.6 | BS7: =BS6*28.8 -> 57.6 | BT7: =BT6*28.8 -> 57.6 | BU7: =BU6*28.8 -> 57.6 | BV7: =BV6*28.8 -> 57.6 | BW7: =BW6*28.8 -> 288 | ... IC7: =IC6*28.8 -> 57.6
A8: T521D107M025ATE050 | U8: 2 | V8: 2 | AU8: 1 | AV8: 1 | AW8: 1 | AX8: 1 | AY8: 1 | AZ8: 1 | CY8: 1 | CZ8: 1 | DM8: 1 | EQ8: 1 | ER8: 1 | FK8: 1 | FL8: 1 | FM8: 2 | FN8: 2 | FO8: 2 | FP8: 1 | HH8: 2 | HI8: 2 | HJ8: 2 | HK8: 2 | HL8: 2 | HM8: 2
A9: QTY | BN9: =BN8*28.8 -> 0 | BO9: =BO8*28.8 -> 0 | BP9: =BP8*28.8 -> 0 | BQ9: =BQ8*28.8 -> 0 | BR9: =BR8*28.8 -> 0 | BS9: =BS8*28.8 -> 0 | BT9: =BT8*28.8 -> 0 | BU9: =BU8*28.8 -> 0 | ... IC9: =IC8*28.8 -> 0
A10: T521D107M025ATE060 | P10: 2 | U10: 1 | V10: 1 | AL10: 2 | AU10: 3 | AV10: 3 | AW10: 3 | AX10: 3 | AY10: 4 | AZ10: 4 | BA10: 3 | BN10: 5 | BO10: 5 | BP10: 3 | BQ10: 3 | BR10: 3 | BS10: 4 | BT10: 4 | BU10: 3 | BV10: 3 | BW10: 3 | BX10: 2 | CY10: 2 | CZ10: 2 | DA10: 2 | DB10: 7 | DC10: 7 | DD10: 7 | DE10: 7 | DF10: 2 | DG10: 2 | DH10: 2 | DI10: 2 | DJ10: 2 | DK10: 2 | DL10: 2 | DM10: 2 | DN10: 3 | EH10: 1 | EI10: 1 | ES10: 1
A11: QTY | BN11: =BN10*28.8 -> 144 | BO11: =BO10*28.8 -> 144 | BP11: =BP10*28.8 -> 86.4 | BQ11: =BQ10*28.8 -> 86.4 | BR11: =BR10*28.8 -> 86.4 | BS11: =BS10*28.8 -> 115.2 | BT11: =BT10*28.8 -> 115.2 | BU11: =BU10*28.8 -> 86.4 | ... IC11: =IC10*28.8 -> 0
A12: T521D107M025ATE0407280 | B12: 25 | C12: 25 | D12: 25 | E12: 25 | F12: 25 | G12: 25 | H12: 25 | I12: 17 | J12: 17 | K12: 17 | L12: 17 | M12: 17 | N12: 17 | O12: 17 | P12: 11 | Q12: 13 | R12: 14 | S12: 11 | T12: 14 | U12: 11 | V12: 13 | W12: 8 | X12: 17 | Y12: 17 | Z12: 17 | AA12: 17 | AB12: 17 | AC12: 17 | AD12: 28 | AE12: 28 | AG12: 26 | AH12: 26 | AI12: 28 | AJ12: 28 | AK12: 28 | AL12: 27 | AM12: 30 | AN12: 31 | AO12: 31 | AP12: 32 | AQ12: 31 | AR12: 31 | AS12: 26 | AT12: 26 | AU12: 26 | AV12: 26 | AW12: 26 | AX12: 26 | AY12: 26 | AZ12: 26 | BA12: 26 | BB12: 31 | BC12: 31 | BD12: 31 | BE12: 31 | BF12: 31 | BG12: 29 | BH12: 29 | BI12: 29 | BJ12: 29 | BK12: 28 | BL12: 28 | BM12: 28 | BN12: 20 | BO12: 19 | BP12: 19 | BQ12: 19 | BR12: 19 | BS12: 25 | BT12: 26 | BU12: 27 | BV12: 28 | BW12: 21 | BX12: 22 | BY12: 24 | BZ12: 24 | CA12: 25 | CB12: 20 | CC12: 20 | CD12: 20 | CE12: 20 | CF12: 27 | CG12: 27 | CH12: 27 | CI12: 27 | CJ12: 27 | CK12: 27 | CL12: 27 | CM12: 27 | CN12: 27 | CO12: 20 | CP12: 20 | CQ12: 20 | CR12: 22 | CS12: 22 | CT12: 22 | CU12: 22 | CV12: 22 | CW12: 20 | CX12: 22 | CY12: 19 | CZ12: 19 | DA12: 20 | DB12: 15 | DC12: 8 | DD12: 8 | DE12: 8 | DF12: 9 | DG12: 9 | DH12: 9 | DI12: 9 | DJ12: 9 | DK12: 11 | DL12: 11 | DM12: 14 | DN12: 14 | DO12: 17 | DP12: 17 | DQ12: 17 | DR12: 18 | DS12: 18 | DT12: 20 | DU12: 20 | DV12: 20 | DW12: 20 | DX12: 20 | DY12: 19 | DZ12: 19 | ED12: 20 | EE12: 20 | EF12: 20 | EG12: 20 | EH12: 28 | EI12: 28 | EJ12: 29 | EK12: 29 | EL12: 29 | EM12: 28 | EN12: 28 | EO12: 18 | EP12: 18 | EQ12: 17 | ER12: 17 | ES12: 17 | ET12: 18 | EU12: 18 | EV12: 13 | EW12: 13 | EX12: 12 | EY12: 11 | EZ12: 11 | FA12: 11 | FB12: 11 | FC12: 10 | FD12: 10 | FE12: 11 | FF12: 12 | FG12: 13 | FH12: 14 | FI12: 15 | FJ12: 21 | FK12: 20 | FL12: 20 | FM12: 19 | FN12: 19 | FO12: 19 | FP12: 20 | FQ12: 20 | FR12: 20 | FS12: 15 | FT12: 15 | FU12: 15 | FV12: 16 | FW12: 16 | FX12: 17 | FY12: 17 | FZ12: 17 | GA12: 17 | GB12: 17 | GC12: 17 | GD12: 17 | GE12: 18 | GF12: 18 | GG12: 18 | GH12: 18 | GI12: 18 | GJ12: 18 | GK12: 18 | GL12: 17 | GM12: 17 | GN12: 7 | GO12: 9 | GP12: 11 | GQ12: 11 | GR12: 11 | GS12: 13 | GT12: 13 | GU12: 13 | GV12: 14 | GW12: 14 | GX12: 14 | GY12: 14 | GZ12: 22 | HA12: 22 | HB12: 22 | HC12: 25 | HD12: 25 | HE12: 25 | HF12: 25 | HG12: 20 | HH12: 20 | HI12: 20 | HJ12: 26 | HK12: 26 | HL12: 26 | HM12: 26 | HN12: 26 | HO12: 26 | HP12: 23 | HQ12: 13 | HR12: 14 | HS12: 15 | HT12: 15 | HU12: 15 | HV12: 15 | HW12: 15 | HX12: 15 | HY12: 15 | HZ12: 15 | IA12: 15 | IB12: 15 | IC12: 14
A13: QTY | B13: =([4]Summary!D32-D!B5)/28.8 -> 23.545139 | C13: =([4]Summary!E32-D!C5)/28.8 -> 23.545139 | D13: =([4]Summary!F32-D!D5)/28.8 -> 24.586806 | E13: =([4]Summary!G32-D!E5)/28.8 -> 25.059722 | F13: =([4]Summary!H32-D!F5)/28.8 -> 25.059722 | I13: 16.855556 | J13: 16.855556 | K13: 16.855556 | L13: 16.855556 | M13: 16.855556 | N13: 16.855556 | O13: 16.855556 | P13: =([5]Summary!D35-D!P32-D!P5)/28.8 -> 12.94375 | Q13: =([5]Summary!E35-D!Q32-D!Q5)/28.8 -> 12.94375 | R13: =([5]Summary!F35-D!R32-D!R5)/28.8 -> 13.5125 | S13: =([5]Summary!G35-D!S32-D!S5)/28.8 -> 14.66875 | T13: =([5]Summary!H35-D!T32-D!T5)/28.8 -> 13.5125 | U13: =([5]Summary!I35-D!U32-D!U5)/28.8 -> 15.21875 | V13: =([5]Summary!J35-D!V32-D!V5)/28.8 -> 16.35625 | W13: =([6]Summary!D37-D!W32-D!W5)/28.8 -> 9.0694444 | X13: =([6]Summary!E37-D!X32-D!X5)/28.8 -> 18.552083 | Y13: =([6]Summary!F37-D!Y32-D!Y5)/28.8 -> 18.552083 | Z13: =([6]Summary!G37-D!Z32-D!Z5)/28.8 -> 18.492361 | AA13: =([6]Summary!H37-D!AA32-D!AA5)/28.8 -> 18.492361 | AB13: =([6]Summary!I37-D!AB32-D!AB5)/28.8 -> 18.492361 | AC13: =([6]Summary!J37-D!AC32-D!AC5)/28.8 -> 18.492361 | AD13: =([7]Sheet1!D33-D!AD32-D!AD5-AD21)/28.8 -> 29.547222 | AE13: =([7]Sheet1!E33-D!AE32-D!AE5-AE21)/28.8 -> 29.547222 | BN13: =BN12*28.8 -> 576 | BO13: =BO12*28.8 -> 547.2 | BP13: =BP12*28.8 -> 547.2 | BQ13: =BQ12*28.8 -> 547.2 | BR13: =BR12*28.8 -> 547.2 | BS13: =BS12*28.8 -> 720 | BT13: =BT12*28.8 -> 748.8 | BU13: =BU12*28.8 -> 777.6 | ... IC13: =IC12*28.8 -> 403.2
A14: Total D107 | P14: =SUM(P5,#REF!) -> #REF! | Q14: =SUM(Q5,#REF!) -> #REF! | R14: =SUM(R5,#REF!) -> #REF! | S14: =SUM(S5,#REF!) -> #REF! | T14: =SUM(T5,#REF!) -> #REF! | U14: =SUM(U5,#REF!) -> #REF! | V14: =SUM(V5,#REF!) -> #REF! | W14: =SUM(W5,#REF!) -> #REF! | ... AE14: =SUM(AE5,#REF!) -> #REF! | AG14: =SUM(AG5,#REF!) -> #REF! | AH14: =SUM(AH5,#REF!) -> #REF! | AI14: =SUM(AI5,#REF!) -> #REF! | AJ14: =SUM(AJ5,#REF!) -> #REF! | AK14: =SUM(AK5,#REF!) -> #REF! | AL14: =SUM(AL5,#REF!) -> #REF! | AM14: =SUM(AM5,#REF!) -> #REF! | AN14: =SUM(AN5,#REF!) -> #REF! | ... BH14: =SUM(BH5,#REF!) -> #REF! | BI14: =SUM(BI5,#REF!)-20 -> #REF! | BJ14: =SUM(BJ5,#REF!)-30 -> #REF! | BK14: =SUM(BK5,#REF!) -> #REF! | BL14: =SUM(BL5,#REF!) -> #REF! | BM14: =SUM(BM5,#REF!) -> #REF! | BN14: =SUM(BN5,BN7,BN9,BN11,BN13) -> 900.18 | BO14: =SUM(BO5,BO7,BO9,BO11,BO13) -> 904.14 | BP14: =SUM(BP5,BP7,BP9,BP11,BP13) -> 1002.42 | BQ14: =SUM(BQ5,BQ7,BQ9,BQ11,BQ13) -> 1002.42 | BR14: =SUM(BR5,BR7,BR9,BR11,BR13) -> 1002.42 | BS14: =SUM(BS5,BS7,BS9,BS11,BS13) -> 1056.6 | BT14: =SUM(BT5,BT7,BT9,BT11,BT13) -> 1052.64 | BU14: =SUM(BU5,BU7,BU9,BU11,BU13) -> 1036.26 | ... IC14: =SUM(IC5,IC7,IC9,IC11,IC13) -> 509.94
A15: T598D337M006AT4143 | AD15: 1 | AE15: 1 | AF15: convert to 080,多发一些 | AG15: 1 | AH15: 1 | AI15: 1 | AJ15: 1 | AK15: 1 | AL15: 2 | AM15: 2 | AN15: 1 | AO15: 1 | AP15: 1 | AQ15: 1 | AR15: 1 | AS15: 1 | AT15: 1 | AU15: 1 | AV15: 1 | AW15: 1 | AX15: 1 | AY15: 1 | AZ15: 1 | BA15: 2 | BI15: 1 | BJ15: 1 | BK15: 1 | BL15: 1 | BO15: 1 | BP15: 1 | BQ15: 1 | CB15: 1 | CC15: 1 | CO15: 1 | CP15: 1 | CQ15: 1 | CY15: 2 | CZ15: 2 | DA15: 1 | DB15: 1 | DC15: 1 | DT15: 1 | DU15: 1 | DV15: 1 | DW15: 1 | DX15: 1 | DY15: 1 | DZ15: 1 | ED15: 1 | EE15: 1 | EF15: 1 | EG15: 1 | EH15: 1 | EI15: 1 | EO15: 1 | EP15: 1 | EQ15: 1 | ER15: 1 | ES15: 1 | ET15: 2 | EU15: 2 | EX15: 1 | EY15: 1 | EZ15: 1 | FA15: 1 | FB15: 1 | FJ15: 2 | FK15: 2 | FL15: 1 | FM15: 2 | FN15: 2 | FO15: 2 | FP15: 2 | FQ15: 2 | FR15: 1 | FX15: 1 | FY15: 1 | FZ15: 1 | GN15: 1 | GO15: 1 | GP15: 1 | GQ15: 2 | GR15: 1 | GS15: 2 | GT15: 1 | GU15: 1 | GV15: 1 | GW15: 1 | GX15: 1 | GY15: 1 | HA15: 1 | HB15: 1 | HC15: 1 | HD15: 1 | HG15: 1 | HH15: 1 | HI15: 1 | HW15: 4 | HX15: 5 | HY15: 6 | HZ15: 7 | IA15: 8 | IB15: 9 | IC15: 10
A16: QTY | BN16: =BN15*20 -> 0 | BO16: =BO15*20 -> 20 | BP16: =BP15*20 -> 20 | BQ16: =BQ15*20 -> 20 | BR16: =BR15*20 -> 0 | BS16: =BS15*20 -> 0 | BT16: =BT15*20 -> 0 | BU16: =BU15*20 -> 0 | ... IC16: =IC15*20 -> 200
A17: T598D337M006AT41437280 | AD17: 1 | AE17: 1 | AU17: 1 | AV17: 1 | AW17: 1 | AX17: 1 | AY17: 1 | AZ17: 1 | BA17: 2 | BB17: 1 | BC17: 1 | BD17: 1 | BE17: 1 | BF17: 1 | BG17: 2 | BH17: 2 | BK17: 1 | BL17: 1 | BM17: 1 | BO17: 1 | BP17: 1 | BQ17: 1 | BR17: 1 | BS17: 1 | BT17: 1 | BU17: 1 | BV17: 1 | BW17: 1 | BX17: 1 | BY17: 1 | BZ17: 1 | CO17: 1 | CP17: 1 | CQ17: 1 | CW17: 1 | CX17: 1 | CY17: 1 | CZ17: 1 | DA17: 1 | DB17: 1 | DC17: 1 | DD17: 1 | DE17: 1 | DF17: 1 | DG17: 1 | DH17: 1 | DI17: 1 | DJ17: 1 | DM17: 1 | DN17: 1 | DO17: 1 | DP17: 1 | DQ17: 1 | DT17: 1 | DU17: 1 | DV17: 1 | DW17: 1 | EJ17: 1 | EK17: 1 | EO17: 1 | EP17: 1 | EQ17: 1 | ER17: 1 | ES17: 1 | EX17: 1 | EY17: 1 | EZ17: 1 | FA17: 1 | FB17: 1 | FL17: 1 | GX17: 4 | GY17: 4 | GZ17: 2 | HA17: 1 | HB17: 1 | HC17: 1 | HG17: 1 | HH17: 1 | HI17: 1 | HQ17: 1 | HR17: 1 | HS17: 1 | HT17: 1
A18: QTY | BN18: =BN17*20 -> 0 | BO18: =BO17*20 -> 20 | BP18: =BP17*20 -> 20 | BQ18: =BQ17*20 -> 20 | BR18: =BR17*20 -> 20 | BS18: =BS17*20 -> 20 | BT18: =BT17*20 -> 20 | BU18: =BU17*20 -> 20 | ... IC18: =IC17*20 -> 0
A19: T598D337M006ATE025 | AD19: 1 | AE19: 1 | AG19: 2 | AH19: 2 | AI19: 1 | AJ19: 1 | AK19: 1 | AL19: 1 | AM19: 1 | AN19: 1 | AO19: 1 | AP19: 1 | AQ19: 1 | AR19: 1 | AS19: 1 | AT19: 1 | AU19: 1 | AV19: 1 | AW19: 1 | AX19: 1 | AZ19: 1 | BA19: 1 | BB19: 2 | BC19: 2 | BD19: 2 | BE19: 2 | BF19: 2 | BG19: 4 | BH19: 4 | BI19: 6 | BJ19: 6 | BK19: 6 | BL19: 6 | BM19: 6 | BN19: 6 | BO19: 6 | BP19: 1 | BQ19: 1 | BR19: 2 | BS19: 1 | BT19: 0 | BU19: 2 | BV19: 2 | BW19: 1 | BX19: 1 | BY19: 1 | BZ19: 1 | CO19: 1 | CP19: 1 | CQ19: 1 | CR19: 1 | CS19: 1 | CT19: 1 | CU19: 1 | CV19: 1 | DF19: 1 | DG19: 1 | DH19: 1 | DI19: 1 | DJ19: 1 | DX19: 1 | DY19: 1 | DZ19: 1 | ED19: 1 | EE19: 1 | EF19: 1 | EG19: 1 | EH19: 2 | EI19: 2 | EJ19: 2 | EK19: 2 | EL19: 3 | EM19: 4 | EN19: 2 | EO19: 2 | EP19: 2 | EQ19: 2 | ER19: 2 | ES19: 2 | ET19: 2 | EU19: 2 | EV19: 1 | EW19: 1 | EX19: 1 | EY19: 1 | EZ19: 1 | FA19: 1 | FQ19: 1 | FR19: 2 | GA19: 1 | GB19: 1 | GC19: 1 | GD19: 1 | GE19: 1 | GF19: 1 | GG19: 1 | GH19: 1 | GI19: 1 | GJ19: 1 | GK19: 1 | GN19: 1 | GO19: 1 | GP19: 1 | GQ19: 1 | GR19: 2 | GS19: 1 | GT19: 1 | GU19: 1 | GV19: 1 | GW19: 1 | GX19: 1 | GY19: 1 | GZ19: 1 | HG19: 1 | HH19: 1 | HI19: 1 | HJ19: 1 | HK19: 1 | HL19: 1 | HM19: 1 | HN19: 3 | HO19: 3 | HP19: 3 | HQ19: 4 | HR19: 4 | HS19: 4 | HT19: 4 | HU19: 3
A20: QTY | BN20: =BN19*20 -> 120 | BO20: =BO19*20 -> 120 | BP20: =BP19*20 -> 20 | BQ20: =BQ19*20 -> 20 | BR20: =BR19*20 -> 40 | BS20: =BS19*20 -> 20 | BT20: =BT19*20 -> 0 | BU20: =BU19*20 -> 40 | ... IC20: =IC19*20 -> 0
